Workbook

Sheet Instructivo
A1: Plantilla de Formulación del Plan de Acción Anual (PAA) 2027 — Escuela Tecnológica Instituto Técnico Central (ETITC)
A2: Oficina Asesora de Planeación y Desarrollo Institucional (OAPDI) · Versión 7 · Instrumento para las áreas funcionales · Libro protegido: solo se diligencian las celdas amarillas.
A4: 1. Propósito
A5: Este libro es el instrumento con el que cada dependencia y área funcional de la ETITC formula sus acciones para la vigencia 2027. La OAPDI entrega la ruta: las metas del Plan de Desarrollo Institucional (PDI) 2025-2032 que corresponden a cada área, lo que la institución espera alcanzar en 2027, las acciones que propone la OAPDI y los compromisos pendientes de 2026. Cada área responde con las acciones, productos, fechas, indicadores y evidencias con los que contribuirá a esas metas. La propuesta completa de la OAPDI, con los cambios frente a 2026, está en el libro 'Plan de acción 2027'.
A7: 2. Marco de referencia
A8: La formulación se rige por la Ley 152 de 1994 (Ley Orgánica del Plan de Desarrollo), el Modelo Integrado de Planeación y Gestión (MIPG), la estructura orgánica del Decreto 902 de 2013 y los grupos internos de trabajo de la Resolución 215 de 2022, el Mapa de Procesos GDC-DI-01 versión 9 (13 de junio de 2024), el Sistema Nacional de Acreditación (Acuerdos del Consejo Nacional de Educación Superior —CESU— 02 de 2020 y 01 de 2025) y la Guía Metodológica para la Evaluación de Impacto de la ETITC.
A10: 3. Arquitectura del PDI
A11: El PDI 2025-2032 se organiza en 6 ejes estratégicos, 24 líneas de acción y 45 metas estratégicas con horizonte 2032. Cada meta se identifica con un código de cuatro niveles (eje.línea.objetivo.meta), por ejemplo 1.1.1.1. Para 2027 se retoma la codificación del PDI: el diagnóstico de la OAPDI encontró que en 2026 varias metas cambiaron de código, de enunciado o de cifra, y esta plantilla las devuelve a su forma original.
A13: 4. Hojas del libro
A14: Buscador_Formulacion: el área selecciona su nombre en la lista desplegable (celda amarilla C4) y consulta sus metas, la meta institucional 2027, el aporte esperado (con las acciones que propone la OAPDI), los productos 2026 pendientes, los indicadores de impacto sugeridos, la hoja donde debe formular y sus compromisos 2026; en la parte inferior registra acciones adicionales. Eje1 a Eje6: una hoja por eje estratégico; cada fila es una meta asignada a un área y en ella el área formula su acción principal (columnas amarillas Q a AE). Compromisos_2026: hitos, compromisos vinculantes y tareas pendientes de los proyectos estructurantes (Convenio Zipazgo, Informe al Congreso 2025, Requerimiento MEN PIC/PG/PFB, Plan de Acción 2026) y del Acta CIGD 6-2026 sobre gestión energética; el área registra su decisión en las columnas amarillas. Las tablas de soporte (metas, áreas e indicadores) están ocultas y protegidas.
A16: 5. Cómo diligenciar
A17: Paso 1. Vaya a Buscador_Formulacion y seleccione su área en la celda amarilla C4. Paso 2. Revise las metas asignadas, el aporte esperado para 2027 y las acciones propuestas por la OAPDI, los productos 2026 pendientes y los compromisos que le corresponden (a la derecha); registre su decisión sobre cada compromiso en la hoja Compromisos_2026. Paso 3. Abra la hoja del eje que indica la columna 'Formular en la hoja', filtre por su área (columna J) y diligencie las columnas amarillas de cada fila. Paso 4. Si una meta requiere más de una acción, o si su área quiere contribuir a una meta que no tiene asignada, regístrela en la sección 'Acciones adicionales' del buscador, eligiendo el área y la meta en las listas. Paso 5. Verifique que la columna 'Alerta de consistencia' diga OK en todas sus filas y envíe el archivo a la OAPDI.
... A28: 9. Ejemplo de fila diligenciada (solo ilustrativo; no corresponde a una acción real)
A29: Hoja / fila | B29: Eje1_Formacion, fila de la meta 1.2.1.1 asignada a la Facultad de Sistemas (A26)
A30: Nombre de la acción | B30: Radicar en SACES el documento maestro de un programa nuevo de pregrado
A31: Producto esperado | B31: Constancia de radicación del documento maestro en SACES
A32: Fecha de inicio / fin | B32: 01/02/2027 — 30/06/2027
A33: Responsable | B33: sistemas@itc.edu.co
A34: Indicador de seguimiento / meta / unidad | B34: Documentos maestros radicados / 1 / documento
A35: Dimensión / indicador de impacto | B35: Valor Público / IMP-13 · Proporción de programas académicos pertinentes (alineados con necesidades y vocación del territorio)
A36: ¿Retoma compromiso 2026? | B36: Sí — continúa el documento maestro iniciado en 2026
A37: Evidencia verificable | B37: Radicado SACES y acta del Consejo Académico

Sheet Compromisos_2026
A1: Compromisos pendientes 2026 de los proyectos estructurantes para retomar o cerrar en el PAA 2027
A3: Id | B3: Proyecto estructurante | C3: Tipo | D3: Compromiso o tarea | E3: Responsable según la fuente | F3: Id área (propuesta) | G3: Área funcional | H3: Dependencia | I3: Meta PDI vinculada (propuesta) | J3: Eje | K3: Estado según la fuente | L3: Periodo 2027 | M3: Evidencia esperada | N3: Soporte normativo o documental | O3: Archivo fuente | P3: Decisión del área | Q3: Id asignación o fila donde se formula | R3: Observaciones | S3: Aux. | U3: Decisiones
A4: CP-001 | B4: Convenio ETITC-MinTIC / CIA Zipazgo | C4: Hito pendiente | D4: Suscribir el convenio interadministrativo ETITC-MinTIC (eventualmente tripartito con el municipio de Zipaquirá). | E4: Rectoría; MinTIC | F4: A01 | G4: =IFERROR(INDEX(Dependencias!$H$5:$H$51,MATCH(F4,Dependencias!$E$5:$E$51,0)),"") -> Despacho de Rectoría | H4: =IFERROR(INDEX(Dependencias!$F$5:$F$51,MATCH(F4,Dependencias!$E$5:$E$51,0))&" · "&INDEX(Dependencias!$G$5:$G$51,MATCH(F4,Dependencias!$E$5:$E$51,0)),"") -> 100 · Rectoría | I4: 5.3.1.1 | J4: =LEFT(I4,1) -> 5 | K4: En trámite; sin respuesta de MinTIC documentada | L4: Sugerido: (I semestre de 2027) | M4: Convenio suscrito | N4: Oficio 21/07/2026 | O4: Insumo Hoja de Ruta ETITC 2027 Convenio ETITC-MinTIC CIA Zipazgo.docx | S4: =IF(F4=LEFT(Buscador_Formulacion!$C$4,3),COUNTIF($F$4:F4,LEFT(Buscador_Formulacion!$C$4,3)),"") | U4: Se retoma en 2027
A5: CP-002 | B5: Convenio ETITC-MinTIC / CIA Zipazgo | C5: Hito pendiente | D5: Legalizar el convenio (perfeccionamiento, aprobaciones y designación de supervisión). | E5: Secretaría General; Rectoría | F5: A11 | G5: =IFERROR(INDEX(Dependencias!$H$5:$H$51,MATCH(F5,Dependencias!$E$5:$E$51,0)),"") -> Despacho de Secretaría General | H5: =IFERROR(INDEX(Dependencias!$F$5:$F$51,MATCH(F5,Dependencias!$E$5:$E$51,0))&" · "&INDEX(Dependencias!$G$5:$G$51,MATCH(F5,Dependencias!$E$5:$E$51,0)),"") -> 110 · Secretaría General | I5: 5.3.1.1 | J5: =LEFT(I5,1) -> 5 | K5: Sin iniciar: depende de la suscripción del convenio | L5: Posterior a la suscripción | M5: Actas de perfeccionamiento y designación de supervisor | N5: n.d. | O5: Insumo Hoja de Ruta ETITC 2027 Convenio ETITC-MinTIC CIA Zipazgo.docx | S5: =IF(F5=LEFT(Buscador_Formulacion!$C$4,3),COUNTIF($F$4:F5,LEFT(Buscador_Formulacion!$C$4,3)),"") | U5: Se cierra en 2026
A6: CP-003 | B6: Convenio ETITC-MinTIC / CIA Zipazgo | C6: Hito pendiente | D6: Iniciar la operación académica del Centro de IA Zipazgo una vez MinTIC entregue la obra y la dotación. | E6: MinTIC (obra y dotación); ETITC (operación) | F6: A15 | G6: =IFERROR(INDEX(Dependencias!$H$5:$H$51,MATCH(F6,Dependencias!$E$5:$E$51,0)),"") -> Despacho de la Vicerrectoría Académica | H6: =IFERROR(INDEX(Dependencias!$F$5:$F$51,MATCH(F6,Dependencias!$E$5:$E$51,0))&" · "&INDEX(Dependencias!$G$5:$G$51,MATCH(F6,Dependencias!$E$5:$E$51,0)),"") -> 120 · Vicerrectoría Académica | I6: 5.3.1.1 | J6: =LEFT(I6,1) -> 5 | K6: Pendiente; infraestructura en construcción al 31/03/2026 | L6: Sugerido: (2027-2, sujeto a la entrega de la obra por MinTIC) | M6: Acta de inicio de operación | N6: MEN 2026-EE-116789; Acuerdo 010/2025 | O6: Insumo Hoja de Ruta ETITC 2027 Convenio ETITC-MinTIC CIA Zipazgo.docx | S6: =IF(F6=LEFT(Buscador_Formulacion!$C$4,3),COUNTIF($F$4:F6,LEFT(Buscador_Formulacion!$C$4,3)),"") | U6: Se reasigna a otra área
A7: CP-004 | B7: Convenio ETITC-MinTIC / CIA Zipazgo | C7: Hito pendiente | D7: Definir la ruta de permanencia de la oferta en Zipaquirá antes del cierre de la ventana de lugares transitorios (admite nuevas cohortes por 2 años consecutivos). | E7: Vicerrectoría Académica | F7: A15 | G7: =IFERROR(INDEX(Dependencias!$H$5:$H$51,MATCH(F7,Dependencias!$E$5:$E$51,0)),"") -> Despacho de la Vicerrectoría Académica | H7: =IFERROR(INDEX(Dependencias!$F$5:$F$51,MATCH(F7,Dependencias!$E$5:$E$51,0))&" · "&INDEX(Dependencias!$G$5:$G$51,MATCH(F7,Dependencias!$E$5:$E$51,0)),"") -> 120 · Vicerrectoría Académica | I7: 1.1.1.1 | J7: =LEFT(I7,1) -> 1 | K7: Vigente desde las resoluciones del 16/04/2026; inicio del conteo por verificar | L7: 2027 | M7: Decisión documentada y trámite ante el MEN | N7: Res. 010369, 010371, 010377, 010378, 010379 y 010417 de 2026 | O7: Insumo Hoja de Ruta ETITC 2027 Convenio ETITC-MinTIC CIA Zipazgo.docx | S7: =IF(F7=LEFT(Buscador_Formulacion!$C$4,3),COUNTIF($F$4:F7,LEFT(Buscador_Formulacion!$C$4,3)),"") | U7: No aplica (justificar)
A8: CP-005 | B8: Convenio ETITC-MinTIC / CIA Zipazgo | C8: Compromiso vinculante | D8: Mantener designado un Coordinador del Convenio Marco de nivel directivo. | E8: Vicerrectoría Académica | F8: A15 | G8: =IFERROR(INDEX(Dependencias!$H$5:$H$51,MATCH(F8,Dependencias!$E$5:$E$51,0)),"") -> Despacho de la Vicerrectoría Académica | H8: =IFERROR(INDEX(Dependencias!$F$5:$F$51,MATCH(F8,Dependencias!$E$5:$E$51,0))&" · "&INDEX(Dependencias!$G$5:$G$51,MATCH(F8,Dependencias!$E$5:$E$51,0)),"") -> 120 · Vicerrectoría Académica | I8: 5.3.1.1 | J8: =LEFT(I8,1) -> 5 | K8: Vigente | L8: 2027 | M8: Acto de designación | N8: Convenio Marco 27/03/2025, cláusula 6, num. 7 | O8: Insumo Hoja de Ruta ETITC 2027 Convenio ETITC-MinTIC CIA Zipazgo.docx | S8: =IF(F8=LEFT(Buscador_Formulacion!$C$4,3),COUNTIF($F$4:F8,LEFT(Buscador_Formulacion!$C$4,3)),"")
A9: CP-006 | B9: Convenio ETITC-MinTIC / CIA Zipazgo | C9: Compromiso vinculante | D9: Presentar la programación académica semestral o anual del convenio. | E9: Vicerrectoría Académica; Decanaturas | F9: A15 | G9: =IFERROR(INDEX(Dependencias!$H$5:$H$51,MATCH(F9,Dependencias!$E$5:$E$51,0)),"") -> Despacho de la Vicerrectoría Académica | H9: =IFERROR(INDEX(Dependencias!$F$5:$F$51,MATCH(F9,Dependencias!$E$5:$E$51,0))&" · "&INDEX(Dependencias!$G$5:$G$51,MATCH(F9,Dependencias!$E$5:$E$51,0)),"") -> 120 · Vicerrectoría Académica | I9: 1.1.1.1 | J9: =LEFT(I9,1) -> 1 | K9: Vigente | L9: Cada periodo 2027 | M9: Documento de programación | N9: Convenio Marco, cláusula 6, num. 8 | O9: Insumo Hoja de Ruta ETITC 2027 Convenio ETITC-MinTIC CIA Zipazgo.docx | S9: =IF(F9=LEFT(Buscador_Formulacion!$C$4,3),COUNTIF($F$4:F9,LEFT(Buscador_Formulacion!$C$4,3)),"")
A10: CP-007 | B10: Convenio ETITC-MinTIC / CIA Zipazgo | C10: Compromiso vinculante | D10: Presentar el plan anual de trabajo 2027 del convenio. | E10: Vicerrectoría Académica | F10: A15 | G10: =IFERROR(INDEX(Dependencias!$H$5:$H$51,MATCH(F10,Dependencias!$E$5:$E$51,0)),"") -> Despacho de la Vicerrectoría Académica | H10: =IFERROR(INDEX(Dependencias!$F$5:$F$51,MATCH(F10,Dependencias!$E$5:$E$51,0))&" · "&INDEX(Dependencias!$G$5:$G$51,MATCH(F10,Dependencias!$E$5:$E$51,0)),"") -> 120 · Vicerrectoría Académica | I10: 5.3.1.1 | J10: =LEFT(I10,1) -> 5 | K10: Vigente | L10: Anual | M10: Plan de trabajo 2027 | N10: Convenio Marco, cláusula 6, num. 9 | O10: Insumo Hoja de Ruta ETITC 2027 Convenio ETITC-MinTIC CIA Zipazgo.docx | S10: =IF(F10=LEFT(Buscador_Formulacion!$C$4,3),COUNTIF($F$4:F10,LEFT(Buscador_Formulacion!$C$4,3)),"")
A11: CP-008 | B11: Convenio ETITC-MinTIC / CIA Zipazgo | C11: Compromiso vinculante | D11: Ejercer la Secretaría Técnica del Comité de Operación y Articulación. | E11: Vicerrectoría Académica | F11: A15 | G11: =IFERROR(INDEX(Dependencias!$H$5:$H$51,MATCH(F11,Dependencias!$E$5:$E$51,0)),"") -> Despacho de la Vicerrectoría Académica | H11: =IFERROR(INDEX(Dependencias!$F$5:$F$51,MATCH(F11,Dependencias!$E$5:$E$51,0))&" · "&INDEX(Dependencias!$G$5:$G$51,MATCH(F11,Dependencias!$E$5:$E$51,0)),"") -> 120 · Vicerrectoría Académica | I11: 5.3.1.1 | J11: =LEFT(I11,1) -> 5 | K11: Vigente; frecuencia por verificar | L11: Periódico | M11: Actas del comité | N11: Convenio Marco, cláusulas 9 y 10 | O11: Insumo Hoja de Ruta ETITC 2027 Convenio ETITC-MinTIC CIA Zipazgo.docx | S11: =IF(F11=LEFT(Buscador_Formulacion!$C$4,3),COUNTIF($F$4:F11,LEFT(Buscador_Formulacion!$C$4,3)),"")
A12: CP-009 | B12: Convenio ETITC-MinTIC / CIA Zipazgo | C12: Compromiso vinculante | D12: Aplicar la admisión especial y las rutas con homologación de créditos para estudiantes del convenio. | E12: Admisiones; Registro | F12: A29 | G12: =IFERROR(INDEX(Dependencias!$H$5:$H$51,MATCH(F12,Dependencias!$E$5:$E$51,0)),"") -> GIT Registro, Control y Admisiones | H12: =IFERROR(INDEX(Dependencias!$F$5:$F$51,MATCH(F12,Dependencias!$E$5:$E$51,0))&" · "&INDEX(Dependencias!$G$5:$G$51,MATCH(F12,Dependencias!$E$5:$E$51,0)),"") -> 126 · GIT Registro y Control | I12: 1.1.1.1 | J12: =LEFT(I12,1) -> 1 | K12: Vigente | L12: 2027-1 y 2027-2 | M12: Estudiantes admitidos y homologaciones | N12: Convenio Marco, cláusula 6, nums. 10 y 11 | O12: Insumo Hoja de Ruta ETITC 2027 Convenio ETITC-MinTIC CIA Zipazgo.docx | S12: =IF(F12=LEFT(Buscador_Formulacion!$C$4,3),COUNTIF($F$4:F12,LEFT(Buscador_Formulacion!$C$4,3)),"")
A13: CP-010 | B13: Convenio ETITC-MinTIC / CIA Zipazgo | C13: Compromiso vinculante | D13: Reportar en SNIES a los estudiantes del convenio. | E13: Registro y Control Académico; OAPDI | F13: A29 | G13: =IFERROR(INDEX(Dependencias!$H$5:$H$51,MATCH(F13,Dependencias!$E$5:$E$51,0)),"") -> GIT Registro, Control y Admisiones | H13: =IFERROR(INDEX(Dependencias!$F$5:$F$51,MATCH(F13,Dependencias!$E$5:$E$51,0))&" · "&INDEX(Dependencias!$G$5:$G$51,MATCH(F13,Dependencias!$E$5:$E$51,0)),"") -> 126 · GIT Registro y Control | I13: 1.1.1.1 | J13: =LEFT(I13,1) -> 1 | K13: Vigente | L13: Según calendario SNIES | M13: Reporte SNIES | N13: Convenio Marco, cláusula 6, num. 12 | O13: Insumo Hoja de Ruta ETITC 2027 Convenio ETITC-MinTIC CIA Zipazgo.docx | S13: =IF(F13=LEFT(Buscador_Formulacion!$C$4,3),COUNTIF($F$4:F13,LEFT(Buscador_Formulacion!$C$4,3)),"")
A14: CP-011 | B14: Convenio ETITC-MinTIC / CIA Zipazgo | C14: Compromiso institucional | D14: Obtener y cargar el Plan de Acción de la Facultad de IA y Zipazgo aprobado (debió presentarse en 3 meses desde el 16/05/2025; es anexo del oficio del 10/03/2026 y no está en la carpeta). | E14: Rectoría; OAPDI | F14: A05 | G14: =IFERROR(INDEX(Dependencias!$H$5:$H$51,MATCH(F14,Dependencias!$E$5:$E$51,0)),"") -> Planeación y Plan de Acción | H14: =IFERROR(INDEX(Dependencias!$F$5:$F$51,MATCH(F14,Dependencias!$E$5:$E$51,0))&" · "&INDEX(Dependencias!$G$5:$G$51,MATCH(F14,Dependencias!$E$5:$E$51,0)),"") -> 101 · Oficina Asesora de Planeación y Desarrollo Institucional | I14: 1.2.1.1 | J14: =LEFT(I14,1) -> 1 | K14: Aprobado por el Consejo Directivo según el oficio del 10/03/2026; el documento no está en la carpeta de trabajo | L14: Antes de cerrar la formulación 2027 | M14: Plan aprobado | N14: Acuerdo 010/2025, art. 2 | O14: Insumo Hoja de Ruta ETITC 2027 Convenio ETITC-MinTIC CIA Zipazgo.docx | S14: =IF(F14=LEFT(Buscador_Formulacion!$C$4,3),COUNTIF($F$4:F14,LEFT(Buscador_Formulacion!$C$4,3)),"")
A15: CP-012 | B15: Convenio ETITC-MinTIC / CIA Zipazgo | C15: Compromiso institucional | D15: Priorizar la sostenibilidad del Centro con recursos propios y gestionar convenios de financiación. | E15: Rectoría; Vicerrectoría Administrativa y Financiera | F15: A30 | G15: =IFERROR(INDEX(Dependencias!$H$5:$H$51,MATCH(F15,Dependencias!$E$5:$E$51,0)),"") -> Despacho de la Vicerrectoría Administrativa y Financiera | H15: =IFERROR(INDEX(Dependencias!$F$5:$F$51,MATCH(F15,Dependencias!$E$5:$E$51,0))&" · "&INDEX(Dependencias!$G$5:$G$51,MATCH(F15,Dependencias!$E$5:$E$51,0)),"") -> 130 · Vicerrectoría Administrativa y Financiera | I15: 5.3.1.1 | J15: =LEFT(I15,1) -> 5 | K15: Sin montos documentados | L15: 2027 | M15: Certificación presupuestal | N15: Acuerdo 010/2025, art. 3 | O15: Insumo Hoja de Ruta ETITC 2027 Convenio ETITC-MinTIC CIA Zipazgo.docx | S15: =IF(F15=LEFT(Buscador_Formulacion!$C$4,3),COUNTIF($F$4:F15,LEFT(Buscador_Formulacion!$C$4,3)),"")
A16: CP-013 | B16: Convenio ETITC-MinTIC / CIA Zipazgo | C16: Compromiso institucional | D16: Diseñar en 2027 cuatro programas: Tecnología en Análisis y Modelado de Datos con IA, Técnico Profesional en Ciencia de Datos Aplicada a la IA, Especialización en Gestión de Proyectos de IA y Maestría en Ciencia de Datos. | E16: Facultad de IA; Autoevaluación | F16: A46 | G16: =IFERROR(INDEX(Dependencias!$H$5:$H$51,MATCH(F16,Dependencias!$E$5:$E$51,0)),"") -> Facultad de Inteligencia Artificial (Acuerdo 010 de 2025) | H16: =IFERROR(INDEX(Dependencias!$F$5:$F$51,MATCH(F16,Dependencias!$E$5:$E$51,0))&" · "&INDEX(Dependencias!$G$5:$G$51,MATCH(F16,Dependencias!$E$5:$E$51,0)),"") -> 123 · Facultades | I16: 1.2.1.1 | J16: =LEFT(I16,1) -> 1 | K16: Proyectado | L16: 2027 | M16: Planes de estudio y acuerdos | N16: Oficio 10/03/2026, sección III | O16: Insumo Hoja de Ruta ETITC 2027 Convenio ETITC-MinTIC CIA Zipazgo.docx | S16: =IF(F16=LEFT(Buscador_Formulacion!$C$4,3),COUNTIF($F$4:F16,LEFT(Buscador_Formulacion!$C$4,3)),"")
A17: CP-014 | B17: Convenio ETITC-MinTIC / CIA Zipazgo | C17: Compromiso institucional | D17: Obtener registro calificado de Ingeniería en IA, Ingeniería Robótica con IA y Especialización en Soluciones de IA. | E17: Vicerrectoría Académica; Autoevaluación | F17: A15 | G17: =IFERROR(INDEX(Dependencias!$H$5:$H$51,MATCH(F17,Dependencias!$E$5:$E$51,0)),"") -> Despacho de la Vicerrectoría Académica | H17: =IFERROR(INDEX(Dependencias!$F$5:$F$51,MATCH(F17,Dependencias!$E$5:$E$51,0))&" · "&INDEX(Dependencias!$G$5:$G$51,MATCH(F17,Dependencias!$E$5:$E$51,0)),"") -> 120 · Vicerrectoría Académica | I17: 1.2.1.1 | J17: =LEFT(I17,1) -> 1 | K17: Ing. en IA radicada el 09/03/2026; las otras dos sin radicación documentada | L17: 2027 | M17: Radicados y resoluciones del MEN | N17: Acuerdos 04, 07 y 08 de 2026 | O17: Insumo Hoja de Ruta ETITC 2027 Convenio ETITC-MinTIC CIA Zipazgo.docx | S17: =IF(F17=LEFT(Buscador_Formulacion!$C$4,3),COUNTIF($F$4:F17,LEFT(Buscador_Formulacion!$C$4,3)),"")
A18: CP-015 | B18: Convenio ETITC-MinTIC / CIA Zipazgo | C18: Compromiso institucional | D18: Ofertar y matricular en Zipaquirá bajo lugares transitorios (por ejemplo, 60 estudiantes por periodo en Ingeniería de Sistemas). | E18: Vicerrectoría Académica | F18: A15 | G18: =IFERROR(INDEX(Dependencias!$H$5:$H$51,MATCH(F18,Dependencias!$E$5:$E$51,0)),"") -> Despacho de la Vicerrectoría Académica | H18: =IFERROR(INDEX(Dependencias!$F$5:$F$51,MATCH(F18,Dependencias!$E$5:$E$51,0))&" · "&INDEX(Dependencias!$G$5:$G$51,MATCH(F18,Dependencias!$E$5:$E$51,0)),"") -> 120 · Vicerrectoría Académica | I18: 1.1.1.1 | J18: =LEFT(I18,1) -> 1 | K18: Vigente | L18: Dentro de la ventana de 2 años | M18: Matrícula por lugar de desarrollo en SNIES | N18: Res. 010417 de 2026 | O18: Insumo Hoja de Ruta ETITC 2027 Convenio ETITC-MinTIC CIA Zipazgo.docx | S18: =IF(F18=LEFT(Buscador_Formulacion!$C$4,3),COUNTIF($F$4:F18,LEFT(Buscador_Formulacion!$C$4,3)),"")
A19: CP-016 | B19: Convenio ETITC-MinTIC / CIA Zipazgo | C19: Alerta a resolver | D19: Tramitar la modificación del lugar de desarrollo de los programas de IA si el Centro será su sede (los Acuerdos 04, 07 y 08 fijan Bogotá). | E19: Vicerrectoría Académica; Autoevaluación | F19: A08 | G19: =IFERROR(INDEX(Dependencias!$H$5:$H$51,MATCH(F19,Dependencias!$E$5:$E$51,0)),"") -> Aseguramiento de la Calidad, MIPG y Registros Calificados | H19: =IFERROR(INDEX(Dependencias!$F$5:$F$51,MATCH(F19,Dependencias!$E$5:$E$51,0))&" · "&INDEX(Dependencias!$G$5:$G$51,MATCH(F19,Dependencias!$E$5:$E$51,0)),"") -> 101 · Oficina Asesora de Planeación y Desarrollo Institucional | I19: 1.2.1.1 | J19: =LEFT(I19,1) -> 1 | K19: Sin trámite | L19: 2027 | M19: Solicitud de modificación ante el MEN | N19: Alerta 2 del insumo | O19: Insumo Hoja de Ruta ETITC 2027 Convenio ETITC-MinTIC CIA Zipazgo.docx | S19: =IF(F19=LEFT(Buscador_Formulacion!$C$4,3),COUNTIF($F$4:F19,LEFT(Buscador_Formulacion!$C$4,3)),"")
... A77: CP-074 | B77: Acta CIGD 6-2026 (07-10-2026) — Gestión energética | C77: Compromiso vinculante | D77: Reportar cada año a la UPME los resultados de la gestión energética (línea base, medidas y ahorro) en el Sistema Único de Usuarios. | E77: Gestión Ambiental; Gestor Energético | F77: A10 | G77: =IFERROR(INDEX(Dependencias!$H$5:$H$51,MATCH(F77,Dependencias!$E$5:$E$51,0)),"") -> Gestión Ambiental | H77: =IFERROR(INDEX(Dependencias!$F$5:$F$51,MATCH(F77,Dependencias!$E$5:$E$51,0))&" · "&INDEX(Dependencias!$G$5:$G$51,MATCH(F77,Dependencias!$E$5:$E$51,0)),"") -> 101 · Oficina Asesora de Planeación y Desarrollo Institucional | I77: 6.1.1.2 | J77: =LEFT(I77,1) -> 6 | K77: Incumplido a la fecha según el acta | L77: Sugerido: (primer reporte completo en 2027) | M77: Reporte radicado en el SUU | N77: Ley 2294 de 2023, art. 237; Circular UPME 000089 de 2025 | O77: Acta_de_Reunion_CIGD_6_2026_-_Borrador2_1.docx (punto 5 y numeral 4.2) | S77: =IF(F77=LEFT(Buscador_Formulacion!$C$4,3),COUNTIF($F$4:F77,LEFT(Buscador_Formulacion!$C$4,3)),"")

Sheet Buscador_Formulacion
A1: Buscador por área funcional y formulación de acciones adicionales 2027
A2: 1) Seleccione su área en la celda amarilla: la tabla muestra las metas que la OAPDI le asignó y lo que debe aportar en 2027. 2) Formule esas acciones en la hoja del eje indicada. 3) Si necesita acciones adicionales, regístrelas en la sección inferior.
B4: Área funcional: | C4: A27 · IBTI (124) | G4: Dependencia: | H4: =IFERROR(INDEX(Dependencias!$F$5:$F$51,MATCH(LEFT($C$4,3),Dependencias!$E$5:$E$51,0))&" · "&INDEX(Dependencias!$G$5:$G$51,MATCH(LEFT($C$4,3),Dependencias!$E$5:$E$51,0)),"") -> 124 · Instituto de Bachillerato Técnico Industrial (IBTI)
B5: Metas asignadas: | C5: =COUNTIF(Base_OAPDI!$I$5:$I$187,LEFT($C$4,3)) -> 2 | G5: Proceso: | H5: =IFERROR(INDEX(Dependencias!$I$5:$I$51,MATCH(LEFT($C$4,3),Dependencias!$E$5:$E$51,0)),"") -> Docencia IBTI
B6: Compromisos 2026: | C6: =COUNTIF(Compromisos_2026!$F$4:$F$77,LEFT($C$4,3)) -> 0
A7: N.° | B7: Id asignación | C7: Eje | D7: Código meta | E7: Meta estratégica (PDI) | F7: Meta institucional 2027 | G7: Aporte esperado del área 2027 | H7: Productos 2026 | I7: Pendientes 2026 | J7: Indicadores de impacto sugeridos | K7: Formular en la hoja | L7: Compromisos de proyectos | N7: N.° | O7: Id | P7: Proyecto estructurante | Q7: Compromiso pendiente 2026 | R7: Meta PDI | S7: Decisión del área
A8: 1 | B8: =IFERROR(INDEX(Base_OAPDI!$A$5:$A$187,MATCH($A8,Base_OAPDI!$U$5:$U$187,0)),"") -> E1-022 | C8: =IFERROR(INDEX(Base_OAPDI!$C$5:$C$187,MATCH($A8,Base_OAPDI!$U$5:$U$187,0)),"") -> Formación y pedagogía de calidad | D8: =IFERROR(INDEX(Base_OAPDI!$B$5:$B$187,MATCH($A8,Base_OAPDI!$U$5:$U$187,0)),"") -> 1.1.1.2 | E8: =IFERROR(INDEX(Base_OAPDI!$E$5:$E$187,MATCH($A8,Base_OAPDI!$U$5:$U$187,0)),"") -> Lograr que el 30% de los estudiantes del IBTI pasen a la educación superior de la ETITC. | F8: =IFERROR(INDEX(Base_OAPDI!$H$5:$H$187,MATCH($A8,Base_OAPDI!$U$5:$U$187,0)),"") -> 40 estudiantes | G8: =IFERROR(INDEX(Base_OAPDI!$R$5:$R$187,MATCH($A8,Base_OAPDI!$U$5:$U$187,0)),"") -> Acciones propuestas por la OAPDI (valídelas y formúlelas en esta fila o en Acciones adicionales): A27-008 Implementar la ruta de admisión y tránsito IBTI → educación superior. Cerrar o reprogramar 1 producto(s) 2026 pendiente(s) de esta meta. | H8: =IFERROR(INDEX(Base_OAPDI!$N$5:$N$187,MATCH($A8,Base_OAPDI!$U$5:$U$187,0)),"") -> 3 | I8: =IFERROR(INDEX(Base_OAPDI!$P$5:$P$187,MATCH($A8,Base_OAPDI!$U$5:$U$187,0)),"") -> 1 | J8: =IFERROR(INDEX(Base_OAPDI!$S$5:$S$187,MATCH($A8,Base_OAPDI!$U$5:$U$187,0)),"") -> IMP-12; IMP-06 | K8: =IFERROR(INDEX(Base_OAPDI!$T$5:$T$187,MATCH($A8,Base_OAPDI!$U$5:$U$187,0)),"") -> Eje1_Formacion | L8: =IFERROR(INDEX(Base_OAPDI!$Q$5:$Q$187,MATCH($A8,Base_OAPDI!$U$5:$U$187,0)),"") -> 0 | N8: 1 | O8: =IFERROR(INDEX(Compromisos_2026!$A$4:$A$77,MATCH($N8,Compromisos_2026!$S$4:$S$77,0))&"","") | P8: =IFERROR(INDEX(Compromisos_2026!$B$4:$B$77,MATCH($N8,Compromisos_2026!$S$4:$S$77,0))&"","") | Q8: =IFERROR(INDEX(Compromisos_2026!$D$4:$D$77,MATCH($N8,Compromisos_2026!$S$4:$S$77,0))&"","") | R8: =IFERROR(INDEX(Compromisos_2026!$I$4:$I$77,MATCH($N8,Compromisos_2026!$S$4:$S$77,0))&"","") | S8: =IFERROR(INDEX(Compromisos_2026!$P$4:$P$77,MATCH($N8,Compromisos_2026!$S$4:$S$77,0))&"","")
A9: 2 | B9: =IFERROR(INDEX(Base_OAPDI!$A$5:$A$187,MATCH($A9,Base_OAPDI!$U$5:$U$187,0)),"") -> E4-028 | C9: =IFERROR(INDEX(Base_OAPDI!$C$5:$C$187,MATCH($A9,Base_OAPDI!$U$5:$U$187,0)),"") -> Transformación institucional | D9: =IFERROR(INDEX(Base_OAPDI!$B$5:$B$187,MATCH($A9,Base_OAPDI!$U$5:$U$187,0)),"") -> 4.2.1.3 | E9: =IFERROR(INDEX(Base_OAPDI!$E$5:$E$187,MATCH($A9,Base_OAPDI!$U$5:$U$187,0)),"") -> Consolidar el IBTI como unidad autónoma y adscrita a la Institución con un programa de tránsito inmediato a la educación superior. | F9: =IFERROR(INDEX(Base_OAPDI!$H$5:$H$187,MATCH($A9,Base_OAPDI!$U$5:$U$187,0)),"") -> Currículos del IBTI y de los programas técnicos profesionales alineados; solicitud de adscripción ante el MEN | G9: =IFERROR(INDEX(Base_OAPDI!$R$5:$R$187,MATCH($A9,Base_OAPDI!$U$5:$U$187,0)),"") -> Acciones propuestas por la OAPDI (valídelas y formúlelas en esta fila o en Acciones adicionales): A27-098 Alinear los currículos del IBTI y de los programas técnicos profesionales. | H9: =IFERROR(INDEX(Base_OAPDI!$N$5:$N$187,MATCH($A9,Base_OAPDI!$U$5:$U$187,0)),"") -> 0 | I9: =IFERROR(INDEX(Base_OAPDI!$P$5:$P$187,MATCH($A9,Base_OAPDI!$U$5:$U$187,0)),"") -> 0 | J9: =IFERROR(INDEX(Base_OAPDI!$S$5:$S$187,MATCH($A9,Base_OAPDI!$U$5:$U$187,0)),"") -> IMP-12; IMP-06 | K9: =IFERROR(INDEX(Base_OAPDI!$T$5:$T$187,MATCH($A9,Base_OAPDI!$U$5:$U$187,0)),"") -> Eje4_Transformacion | L9: =IFERROR(INDEX(Base_OAPDI!$Q$5:$Q$187,MATCH($A9,Base_OAPDI!$U$5:$U$187,0)),"") -> 0 | N9: 2 | O9: =IFERROR(INDEX(Compromisos_2026!$A$4:$A$77,MATCH($N9,Compromisos_2026!$S$4:$S$77,0))&"","") | P9: =IFERROR(INDEX(Compromisos_2026!$B$4:$B$77,MATCH($N9,Compromisos_2026!$S$4:$S$77,0))&"","") | Q9: =IFERROR(INDEX(Compromisos_2026!$D$4:$D$77,MATCH($N9,Compromisos_2026!$S$4:$S$77,0))&"","") | R9: =IFERROR(INDEX(Compromisos_2026!$I$4:$I$77,MATCH($N9,Compromisos_2026!$S$4:$S$77,0))&"","") | S9: =IFERROR(INDEX(Compromisos_2026!$P$4:$P$77,MATCH($N9,Compromisos_2026!$S$4:$S$77,0))&"","")
A10: 3 | B10: =IFERROR(INDEX(Base_OAPDI!$A$5:$A$187,MATCH($A10,Base_OAPDI!$U$5:$U$187,0)),"") | C10: =IFERROR(INDEX(Base_OAPDI!$C$5:$C$187,MATCH($A10,Base_OAPDI!$U$5:$U$187,0)),"") | D10: =IFERROR(INDEX(Base_OAPDI!$B$5:$B$187,MATCH($A10,Base_OAPDI!$U$5:$U$187,0)),"") | E10: =IFERROR(INDEX(Base_OAPDI!$E$5:$E$187,MATCH($A10,Base_OAPDI!$U$5:$U$187,0)),"") | F10: =IFERROR(INDEX(Base_OAPDI!$H$5:$H$187,MATCH($A10,Base_OAPDI!$U$5:$U$187,0)),"") | G10: =IFERROR(INDEX(Base_OAPDI!$R$5:$R$187,MATCH($A10,Base_OAPDI!$U$5:$U$187,0)),"") | H10: =IFERROR(INDEX(Base_OAPDI!$N$5:$N$187,MATCH($A10,Base_OAPDI!$U$5:$U$187,0)),"") | I10: =IFERROR(INDEX(Base_OAPDI!$P$5:$P$187,MATCH($A10,Base_OAPDI!$U$5:$U$187,0)),"") | J10: =IFERROR(INDEX(Base_OAPDI!$S$5:$S$187,MATCH($A10,Base_OAPDI!$U$5:$U$187,0)),"") | K10: =IFERROR(INDEX(Base_OAPDI!$T$5:$T$187,MATCH($A10,Base_OAPDI!$U$5:$U$187,0)),"") | L10: =IFERROR(INDEX(Base_OAPDI!$Q$5:$Q$187,MATCH($A10,Base_OAPDI!$U$5:$U$187,0)),"") | N10: 3 | O10: =IFERROR(INDEX(Compromisos_2026!$A$4:$A$77,MATCH($N10,Compromisos_2026!$S$4:$S$77,0))&"","") | P10: =IFERROR(INDEX(Compromisos_2026!$B$4:$B$77,MATCH($N10,Compromisos_2026!$S$4:$S$77,0))&"","") | Q10: =IFERROR(INDEX(Compromisos_2026!$D$4:$D$77,MATCH($N10,Compromisos_2026!$S$4:$S$77,0))&"","") | R10: =IFERROR(INDEX(Compromisos_2026!$I$4:$I$77,MATCH($N10,Compromisos_2026!$S$4:$S$77,0))&"","") | S10: =IFERROR(INDEX(Compromisos_2026!$P$4:$P$77,MATCH($N10,Compromisos_2026!$S$4:$S$77,0))&"","")
A11: 4 | B11: =IFERROR(INDEX(Base_OAPDI!$A$5:$A$187,MATCH($A11,Base_OAPDI!$U$5:$U$187,0)),"") | C11: =IFERROR(INDEX(Base_OAPDI!$C$5:$C$187,MATCH($A11,Base_OAPDI!$U$5:$U$187,0)),"") | D11: =IFERROR(INDEX(Base_OAPDI!$B$5:$B$187,MATCH($A11,Base_OAPDI!$U$5:$U$187,0)),"") | E11: =IFERROR(INDEX(Base_OAPDI!$E$5:$E$187,MATCH($A11,Base_OAPDI!$U$5:$U$187,0)),"") | F11: =IFERROR(INDEX(Base_OAPDI!$H$5:$H$187,MATCH($A11,Base_OAPDI!$U$5:$U$187,0)),"") | G11: =IFERROR(INDEX(Base_OAPDI!$R$5:$R$187,MATCH($A11,Base_OAPDI!$U$5:$U$187,0)),"") | H11: =IFERROR(INDEX(Base_OAPDI!$N$5:$N$187,MATCH($A11,Base_OAPDI!$U$5:$U$187,0)),"") | I11: =IFERROR(INDEX(Base_OAPDI!$P$5:$P$187,MATCH($A11,Base_OAPDI!$U$5:$U$187,0)),"") | J11: =IFERROR(INDEX(Base_OAPDI!$S$5:$S$187,MATCH($A11,Base_OAPDI!$U$5:$U$187,0)),"") | K11: =IFERROR(INDEX(Base_OAPDI!$T$5:$T$187,MATCH($A11,Base_OAPDI!$U$5:$U$187,0)),"") | L11: =IFERROR(INDEX(Base_OAPDI!$Q$5:$Q$187,MATCH($A11,Base_OAPDI!$U$5:$U$187,0)),"") | N11: 4 | O11: =IFERROR(INDEX(Compromisos_2026!$A$4:$A$77,MATCH($N11,Compromisos_2026!$S$4:$S$77,0))&"","") | P11: =IFERROR(INDEX(Compromisos_2026!$B$4:$B$77,MATCH($N11,Compromisos_2026!$S$4:$S$77,0))&"","") | Q11: =IFERROR(INDEX(Compromisos_2026!$D$4:$D$77,MATCH($N11,Compromisos_2026!$S$4:$S$77,0))&"","") | R11: =IFERROR(INDEX(Compromisos_2026!$I$4:$I$77,MATCH($N11,Compromisos_2026!$S$4:$S$77,0))&"","") | S11: =IFERROR(INDEX(Compromisos_2026!$P$4:$P$77,MATCH($N11,Compromisos_2026!$S$4:$S$77,0))&"","")
A12: 5 | B12: =IFERROR(INDEX(Base_OAPDI!$A$5:$A$187,MATCH($A12,Base_OAPDI!$U$5:$U$187,0)),"") | C12: =IFERROR(INDEX(Base_OAPDI!$C$5:$C$187,MATCH($A12,Base_OAPDI!$U$5:$U$187,0)),"") | D12: =IFERROR(INDEX(Base_OAPDI!$B$5:$B$187,MATCH($A12,Base_OAPDI!$U$5:$U$187,0)),"") | E12: =IFERROR(INDEX(Base_OAPDI!$E$5:$E$187,MATCH($A12,Base_OAPDI!$U$5:$U$187,0)),"") | F12: =IFERROR(INDEX(Base_OAPDI!$H$5:$H$187,MATCH($A12,Base_OAPDI!$U$5:$U$187,0)),"") | G12: =IFERROR(INDEX(Base_OAPDI!$R$5:$R$187,MATCH($A12,Base_OAPDI!$U$5:$U$187,0)),"") | H12: =IFERROR(INDEX(Base_OAPDI!$N$5:$N$187,MATCH($A12,Base_OAPDI!$U$5:$U$187,0)),"") | I12: =IFERROR(INDEX(Base_OAPDI!$P$5:$P$187,MATCH($A12,Base_OAPDI!$U$5:$U$187,0)),"") | J12: =IFERROR(INDEX(Base_OAPDI!$S$5:$S$187,MATCH($A12,Base_OAPDI!$U$5:$U$187,0)),"") | K12: =IFERROR(INDEX(Base_OAPDI!$T$5:$T$187,MATCH($A12,Base_OAPDI!$U$5:$U$187,0)),"") | L12: =IFERROR(INDEX(Base_OAPDI!$Q$5:$Q$187,MATCH($A12,Base_OAPDI!$U$5:$U$187,0)),"") | N12: 5 | O12: =IFERROR(INDEX(Compromisos_2026!$A$4:$A$77,MATCH($N12,Compromisos_2026!$S$4:$S$77,0))&"","") | P12: =IFERROR(INDEX(Compromisos_2026!$B$4:$B$77,MATCH($N12,Compromisos_2026!$S$4:$S$77,0))&"","") | Q12: =IFERROR(INDEX(Compromisos_2026!$D$4:$D$77,MATCH($N12,Compromisos_2026!$S$4:$S$77,0))&"","") | R12: =IFERROR(INDEX(Compromisos_2026!$I$4:$I$77,MATCH($N12,Compromisos_2026!$S$4:$S$77,0))&"","") | S12: =IFERROR(INDEX(Compromisos_2026!$P$4:$P$77,MATCH($N12,Compromisos_2026!$S$4:$S$77,0))&"","")
A13: 6 | B13: =IFERROR(INDEX(Base_OAPDI!$A$5:$A$187,MATCH($A13,Base_OAPDI!$U$5:$U$187,0)),"") | C13: =IFERROR(INDEX(Base_OAPDI!$C$5:$C$187,MATCH($A13,Base_OAPDI!$U$5:$U$187,0)),"") | D13: =IFERROR(INDEX(Base_OAPDI!$B$5:$B$187,MATCH($A13,Base_OAPDI!$U$5:$U$187,0)),"") | E13: =IFERROR(INDEX(Base_OAPDI!$E$5:$E$187,MATCH($A13,Base_OAPDI!$U$5:$U$187,0)),"") | F13: =IFERROR(INDEX(Base_OAPDI!$H$5:$H$187,MATCH($A13,Base_OAPDI!$U$5:$U$187,0)),"") | G13: =IFERROR(INDEX(Base_OAPDI!$R$5:$R$187,MATCH($A13,Base_OAPDI!$U$5:$U$187,0)),"") | H13: =IFERROR(INDEX(Base_OAPDI!$N$5:$N$187,MATCH($A13,Base_OAPDI!$U$5:$U$187,0)),"") | I13: =IFERROR(INDEX(Base_OAPDI!$P$5:$P$187,MATCH($A13,Base_OAPDI!$U$5:$U$187,0)),"") | J13: =IFERROR(INDEX(Base_OAPDI!$S$5:$S$187,MATCH($A13,Base_OAPDI!$U$5:$U$187,0)),"") | K13: =IFERROR(INDEX(Base_OAPDI!$T$5:$T$187,MATCH($A13,Base_OAPDI!$U$5:$U$187,0)),"") | L13: =IFERROR(INDEX(Base_OAPDI!$Q$5:$Q$187,MATCH($A13,Base_OAPDI!$U$5:$U$187,0)),"") | N13: 6 | O13: =IFERROR(INDEX(Compromisos_2026!$A$4:$A$77,MATCH($N13,Compromisos_2026!$S$4:$S$77,0))&"","") | P13: =IFERROR(INDEX(Compromisos_2026!$B$4:$B$77,MATCH($N13,Compromisos_2026!$S$4:$S$77,0))&"","") | Q13: =IFERROR(INDEX(Compromisos_2026!$D$4:$D$77,MATCH($N13,Compromisos_2026!$S$4:$S$77,0))&"","") | R13: =IFERROR(INDEX(Compromisos_2026!$I$4:$I$77,MATCH($N13,Compromisos_2026!$S$4:$S$77,0))&"","") | S13: =IFERROR(INDEX(Compromisos_2026!$P$4:$P$77,MATCH($N13,Compromisos_2026!$S$4:$S$77,0))&"","")
A14: 7 | B14: =IFERROR(INDEX(Base_OAPDI!$A$5:$A$187,MATCH($A14,Base_OAPDI!$U$5:$U$187,0)),"") | C14: =IFERROR(INDEX(Base_OAPDI!$C$5:$C$187,MATCH($A14,Base_OAPDI!$U$5:$U$187,0)),"") | D14: =IFERROR(INDEX(Base_OAPDI!$B$5:$B$187,MATCH($A14,Base_OAPDI!$U$5:$U$187,0)),"") | E14: =IFERROR(INDEX(Base_OAPDI!$E$5:$E$187,MATCH($A14,Base_OAPDI!$U$5:$U$187,0)),"") | F14: =IFERROR(INDEX(Base_OAPDI!$H$5:$H$187,MATCH($A14,Base_OAPDI!$U$5:$U$187,0)),"") | G14: =IFERROR(INDEX(Base_OAPDI!$R$5:$R$187,MATCH($A14,Base_OAPDI!$U$5:$U$187,0)),"") | H14: =IFERROR(INDEX(Base_OAPDI!$N$5:$N$187,MATCH($A14,Base_OAPDI!$U$5:$U$187,0)),"") | I14: =IFERROR(INDEX(Base_OAPDI!$P$5:$P$187,MATCH($A14,Base_OAPDI!$U$5:$U$187,0)),"") | J14: =IFERROR(INDEX(Base_OAPDI!$S$5:$S$187,MATCH($A14,Base_OAPDI!$U$5:$U$187,0)),"") | K14: =IFERROR(INDEX(Base_OAPDI!$T$5:$T$187,MATCH($A14,Base_OAPDI!$U$5:$U$187,0)),"") | L14: =IFERROR(INDEX(Base_OAPDI!$Q$5:$Q$187,MATCH($A14,Base_OAPDI!$U$5:$U$187,0)),"") | N14: 7 | O14: =IFERROR(INDEX(Compromisos_2026!$A$4:$A$77,MATCH($N14,Compromisos_2026!$S$4:$S$77,0))&"","") | P14: =IFERROR(INDEX(Compromisos_2026!$B$4:$B$77,MATCH($N14,Compromisos_2026!$S$4:$S$77,0))&"","") | Q14: =IFERROR(INDEX(Compromisos_2026!$D$4:$D$77,MATCH($N14,Compromisos_2026!$S$4:$S$77,0))&"","") | R14: =IFERROR(INDEX(Compromisos_2026!$I$4:$I$77,MATCH($N14,Compromisos_2026!$S$4:$S$77,0))&"","") | S14: =IFERROR(INDEX(Compromisos_2026!$P$4:$P$77,MATCH($N14,Compromisos_2026!$S$4:$S$77,0))&"","")
A15: 8 | B15: =IFERROR(INDEX(Base_OAPDI!$A$5:$A$187,MATCH($A15,Base_OAPDI!$U$5:$U$187,0)),"") | C15: =IFERROR(INDEX(Base_OAPDI!$C$5:$C$187,MATCH($A15,Base_OAPDI!$U$5:$U$187,0)),"") | D15: =IFERROR(INDEX(Base_OAPDI!$B$5:$B$187,MATCH($A15,Base_OAPDI!$U$5:$U$187,0)),"") | E15: =IFERROR(INDEX(Base_OAPDI!$E$5:$E$187,MATCH($A15,Base_OAPDI!$U$5:$U$187,0)),"") | F15: =IFERROR(INDEX(Base_OAPDI!$H$5:$H$187,MATCH($A15,Base_OAPDI!$U$5:$U$187,0)),"") | G15: =IFERROR(INDEX(Base_OAPDI!$R$5:$R$187,MATCH($A15,Base_OAPDI!$U$5:$U$187,0)),"") | H15: =IFERROR(INDEX(Base_OAPDI!$N$5:$N$187,MATCH($A15,Base_OAPDI!$U$5:$U$187,0)),"") | I15: =IFERROR(INDEX(Base_OAPDI!$P$5:$P$187,MATCH($A15,Base_OAPDI!$U$5:$U$187,0)),"") | J15: =IFERROR(INDEX(Base_OAPDI!$S$5:$S$187,MATCH($A15,Base_OAPDI!$U$5:$U$187,0)),"") | K15: =IFERROR(INDEX(Base_OAPDI!$T$5:$T$187,MATCH($A15,Base_OAPDI!$U$5:$U$187,0)),"") | L15: =IFERROR(INDEX(Base_OAPDI!$Q$5:$Q$187,MATCH($A15,Base_OAPDI!$U$5:$U$187,0)),"") | N15: 8 | O15: =IFERROR(INDEX(Compromisos_2026!$A$4:$A$77,MATCH($N15,Compromisos_2026!$S$4:$S$77,0))&"","") | P15: =IFERROR(INDEX(Compromisos_2026!$B$4:$B$77,MATCH($N15,Compromisos_2026!$S$4:$S$77,0))&"","") | Q15: =IFERROR(INDEX(Compromisos_2026!$D$4:$D$77,MATCH($N15,Compromisos_2026!$S$4:$S$77,0))&"","") | R15: =IFERROR(INDEX(Compromisos_2026!$I$4:$I$77,MATCH($N15,Compromisos_2026!$S$4:$S$77,0))&"","") | S15: =IFERROR(INDEX(Compromisos_2026!$P$4:$P$77,MATCH($N15,Compromisos_2026!$S$4:$S$77,0))&"","")
A16: 9 | B16: =IFERROR(INDEX(Base_OAPDI!$A$5:$A$187,MATCH($A16,Base_OAPDI!$U$5:$U$187,0)),"") | C16: =IFERROR(INDEX(Base_OAPDI!$C$5:$C$187,MATCH($A16,Base_OAPDI!$U$5:$U$187,0)),"") | D16: =IFERROR(INDEX(Base_OAPDI!$B$5:$B$187,MATCH($A16,Base_OAPDI!$U$5:$U$187,0)),"") | E16: =IFERROR(INDEX(Base_OAPDI!$E$5:$E$187,MATCH($A16,Base_OAPDI!$U$5:$U$187,0)),"") | F16: =IFERROR(INDEX(Base_OAPDI!$H$5:$H$187,MATCH($A16,Base_OAPDI!$U$5:$U$187,0)),"") | G16: =IFERROR(INDEX(Base_OAPDI!$R$5:$R$187,MATCH($A16,Base_OAPDI!$U$5:$U$187,0)),"") | H16: =IFERROR(INDEX(Base_OAPDI!$N$5:$N$187,MATCH($A16,Base_OAPDI!$U$5:$U$187,0)),"") | I16: =IFERROR(INDEX(Base_OAPDI!$P$5:$P$187,MATCH($A16,Base_OAPDI!$U$5:$U$187,0)),"") | J16: =IFERROR(INDEX(Base_OAPDI!$S$5:$S$187,MATCH($A16,Base_OAPDI!$U$5:$U$187,0)),"") | K16: =IFERROR(INDEX(Base_OAPDI!$T$5:$T$187,MATCH($A16,Base_OAPDI!$U$5:$U$187,0)),"") | L16: =IFERROR(INDEX(Base_OAPDI!$Q$5:$Q$187,MATCH($A16,Base_OAPDI!$U$5:$U$187,0)),"") | N16: 9 | O16: =IFERROR(INDEX(Compromisos_2026!$A$4:$A$77,MATCH($N16,Compromisos_2026!$S$4:$S$77,0))&"","") | P16: =IFERROR(INDEX(Compromisos_2026!$B$4:$B$77,MATCH($N16,Compromisos_2026!$S$4:$S$77,0))&"","") | Q16: =IFERROR(INDEX(Compromisos_2026!$D$4:$D$77,MATCH($N16,Compromisos_2026!$S$4:$S$77,0))&"","") | R16: =IFERROR(INDEX(Compromisos_2026!$I$4:$I$77,MATCH($N16,Compromisos_2026!$S$4:$S$77,0))&"","") | S16: =IFERROR(INDEX(Compromisos_2026!$P$4:$P$77,MATCH($N16,Compromisos_2026!$S$4:$S$77,0))&"","")
A17: 10 | B17: =IFERROR(INDEX(Base_OAPDI!$A$5:$A$187,MATCH($A17,Base_OAPDI!$U$5:$U$187,0)),"") | C17: =IFERROR(INDEX(Base_OAPDI!$C$5:$C$187,MATCH($A17,Base_OAPDI!$U$5:$U$187,0)),"") | D17: =IFERROR(INDEX(Base_OAPDI!$B$5:$B$187,MATCH($A17,Base_OAPDI!$U$5:$U$187,0)),"") | E17: =IFERROR(INDEX(Base_OAPDI!$E$5:$E$187,MATCH($A17,Base_OAPDI!$U$5:$U$187,0)),"") | F17: =IFERROR(INDEX(Base_OAPDI!$H$5:$H$187,MATCH($A17,Base_OAPDI!$U$5:$U$187,0)),"") | G17: =IFERROR(INDEX(Base_OAPDI!$R$5:$R$187,MATCH($A17,Base_OAPDI!$U$5:$U$187,0)),"") | H17: =IFERROR(INDEX(Base_OAPDI!$N$5:$N$187,MATCH($A17,Base_OAPDI!$U$5:$U$187,0)),"") | I17: =IFERROR(INDEX(Base_OAPDI!$P$5:$P$187,MATCH($A17,Base_OAPDI!$U$5:$U$187,0)),"") | J17: =IFERROR(INDEX(Base_OAPDI!$S$5:$S$187,MATCH($A17,Base_OAPDI!$U$5:$U$187,0)),"") | K17: =IFERROR(INDEX(Base_OAPDI!$T$5:$T$187,MATCH($A17,Base_OAPDI!$U$5:$U$187,0)),"") | L17: =IFERROR(INDEX(Base_OAPDI!$Q$5:$Q$187,MATCH($A17,Base_OAPDI!$U$5:$U$187,0)),"") | N17: 10 | O17: =IFERROR(INDEX(Compromisos_2026!$A$4:$A$77,MATCH($N17,Compromisos_2026!$S$4:$S$77,0))&"","") | P17: =IFERROR(INDEX(Compromisos_2026!$B$4:$B$77,MATCH($N17,Compromisos_2026!$S$4:$S$77,0))&"","") | Q17: =IFERROR(INDEX(Compromisos_2026!$D$4:$D$77,MATCH($N17,Compromisos_2026!$S$4:$S$77,0))&"","") | R17: =IFERROR(INDEX(Compromisos_2026!$I$4:$I$77,MATCH($N17,Compromisos_2026!$S$4:$S$77,0))&"","") | S17: =IFERROR(INDEX(Compromisos_2026!$P$4:$P$77,MATCH($N17,Compromisos_2026!$S$4:$S$77,0))&"","")
A18: 11 | B18: =IFERROR(INDEX(Base_OAPDI!$A$5:$A$187,MATCH($A18,Base_OAPDI!$U$5:$U$187,0)),"") | C18: =IFERROR(INDEX(Base_OAPDI!$C$5:$C$187,MATCH($A18,Base_OAPDI!$U$5:$U$187,0)),"") | D18: =IFERROR(INDEX(Base_OAPDI!$B$5:$B$187,MATCH($A18,Base_OAPDI!$U$5:$U$187,0)),"") | E18: =IFERROR(INDEX(Base_OAPDI!$E$5:$E$187,MATCH($A18,Base_OAPDI!$U$5:$U$187,0)),"") | F18: =IFERROR(INDEX(Base_OAPDI!$H$5:$H$187,MATCH($A18,Base_OAPDI!$U$5:$U$187,0)),"") | G18: =IFERROR(INDEX(Base_OAPDI!$R$5:$R$187,MATCH($A18,Base_OAPDI!$U$5:$U$187,0)),"") | H18: =IFERROR(INDEX(Base_OAPDI!$N$5:$N$187,MATCH($A18,Base_OAPDI!$U$5:$U$187,0)),"") | I18: =IFERROR(INDEX(Base_OAPDI!$P$5:$P$187,MATCH($A18,Base_OAPDI!$U$5:$U$187,0)),"") | J18: =IFERROR(INDEX(Base_OAPDI!$S$5:$S$187,MATCH($A18,Base_OAPDI!$U$5:$U$187,0)),"") | K18: =IFERROR(INDEX(Base_OAPDI!$T$5:$T$187,MATCH($A18,Base_OAPDI!$U$5:$U$187,0)),"") | L18: =IFERROR(INDEX(Base_OAPDI!$Q$5:$Q$187,MATCH($A18,Base_OAPDI!$U$5:$U$187,0)),"") | N18: 11 | O18: =IFERROR(INDEX(Compromisos_2026!$A$4:$A$77,MATCH($N18,Compromisos_2026!$S$4:$S$77,0))&"","") | P18: =IFERROR(INDEX(Compromisos_2026!$B$4:$B$77,MATCH($N18,Compromisos_2026!$S$4:$S$77,0))&"","") | Q18: =IFERROR(INDEX(Compromisos_2026!$D$4:$D$77,MATCH($N18,Compromisos_2026!$S$4:$S$77,0))&"","") | R18: =IFERROR(INDEX(Compromisos_2026!$I$4:$I$77,MATCH($N18,Compromisos_2026!$S$4:$S$77,0))&"","") | S18: =IFERROR(INDEX(Compromisos_2026!$P$4:$P$77,MATCH($N18,Compromisos_2026!$S$4:$S$77,0))&"","")
A19: 12 | B19: =IFERROR(INDEX(Base_OAPDI!$A$5:$A$187,MATCH($A19,Base_OAPDI!$U$5:$U$187,0)),"") | C19: =IFERROR(INDEX(Base_OAPDI!$C$5:$C$187,MATCH($A19,Base_OAPDI!$U$5:$U$187,0)),"") | D19: =IFERROR(INDEX(Base_OAPDI!$B$5:$B$187,MATCH($A19,Base_OAPDI!$U$5:$U$187,0)),"") | E19: =IFERROR(INDEX(Base_OAPDI!$E$5:$E$187,MATCH($A19,Base_OAPDI!$U$5:$U$187,0)),"") | F19: =IFERROR(INDEX(Base_OAPDI!$H$5:$H$187,MATCH($A19,Base_OAPDI!$U$5:$U$187,0)),"") | G19: =IFERROR(INDEX(Base_OAPDI!$R$5:$R$187,MATCH($A19,Base_OAPDI!$U$5:$U$187,0)),"") | H19: =IFERROR(INDEX(Base_OAPDI!$N$5:$N$187,MATCH($A19,Base_OAPDI!$U$5:$U$187,0)),"") | I19: =IFERROR(INDEX(Base_OAPDI!$P$5:$P$187,MATCH($A19,Base_OAPDI!$U$5:$U$187,0)),"") | J19: =IFERROR(INDEX(Base_OAPDI!$S$5:$S$187,MATCH($A19,Base_OAPDI!$U$5:$U$187,0)),"") | K19: =IFERROR(INDEX(Base_OAPDI!$T$5:$T$187,MATCH($A19,Base_OAPDI!$U$5:$U$187,0)),"") | L19: =IFERROR(INDEX(Base_OAPDI!$Q$5:$Q$187,MATCH($A19,Base_OAPDI!$U$5:$U$187,0)),"") | N19: 12 | O19: =IFERROR(INDEX(Compromisos_2026!$A$4:$A$77,MATCH($N19,Compromisos_2026!$S$4:$S$77,0))&"","") | P19: =IFERROR(INDEX(Compromisos_2026!$B$4:$B$77,MATCH($N19,Compromisos_2026!$S$4:$S$77,0))&"","") | Q19: =IFERROR(INDEX(Compromisos_2026!$D$4:$D$77,MATCH($N19,Compromisos_2026!$S$4:$S$77,0))&"","") | R19: =IFERROR(INDEX(Compromisos_2026!$I$4:$I$77,MATCH($N19,Compromisos_2026!$S$4:$S$77,0))&"","") | S19: =IFERROR(INDEX(Compromisos_2026!$P$4:$P$77,MATCH($N19,Compromisos_2026!$S$4:$S$77,0))&"","")
... A32: 25 | B32: =IFERROR(INDEX(Base_OAPDI!$A$5:$A$187,MATCH($A32,Base_OAPDI!$U$5:$U$187,0)),"") | C32: =IFERROR(INDEX(Base_OAPDI!$C$5:$C$187,MATCH($A32,Base_OAPDI!$U$5:$U$187,0)),"") | D32: =IFERROR(INDEX(Base_OAPDI!$B$5:$B$187,MATCH($A32,Base_OAPDI!$U$5:$U$187,0)),"") | E32: =IFERROR(INDEX(Base_OAPDI!$E$5:$E$187,MATCH($A32,Base_OAPDI!$U$5:$U$187,0)),"") | F32: =IFERROR(INDEX(Base_OAPDI!$H$5:$H$187,MATCH($A32,Base_OAPDI!$U$5:$U$187,0)),"") | G32: =IFERROR(INDEX(Base_OAPDI!$R$5:$R$187,MATCH($A32,Base_OAPDI!$U$5:$U$187,0)),"") | H32: =IFERROR(INDEX(Base_OAPDI!$N$5:$N$187,MATCH($A32,Base_OAPDI!$U$5:$U$187,0)),"") | I32: =IFERROR(INDEX(Base_OAPDI!$P$5:$P$187,MATCH($A32,Base_OAPDI!$U$5:$U$187,0)),"") | J32: =IFERROR(INDEX(Base_OAPDI!$S$5:$S$187,MATCH($A32,Base_OAPDI!$U$5:$U$187,0)),"") | K32: =IFERROR(INDEX(Base_OAPDI!$T$5:$T$187,MATCH($A32,Base_OAPDI!$U$5:$U$187,0)),"") | L32: =IFERROR(INDEX(Base_OAPDI!$Q$5:$Q$187,MATCH($A32,Base_OAPDI!$U$5:$U$187,0)),"") | N32: 25 | O32: =IFERROR(INDEX(Compromisos_2026!$A$4:$A$77,MATCH($N32,Compromisos_2026!$S$4:$S$77,0))&"","") | P32: =IFERROR(INDEX(Compromisos_2026!$B$4:$B$77,MATCH($N32,Compromisos_2026!$S$4:$S$77,0))&"","") | Q32: =IFERROR(INDEX(Compromisos_2026!$D$4:$D$77,MATCH($N32,Compromisos_2026!$S$4:$S$77,0))&"","") | R32: =IFERROR(INDEX(Compromisos_2026!$I$4:$I$77,MATCH($N32,Compromisos_2026!$S$4:$S$77,0))&"","") | S32: =IFERROR(INDEX(Compromisos_2026!$P$4:$P$77,MATCH($N32,Compromisos_2026!$S$4:$S$77,0))&"","")
A33: 26 | B33: =IFERROR(INDEX(Base_OAPDI!$A$5:$A$187,MATCH($A33,Base_OAPDI!$U$5:$U$187,0)),"") | C33: =IFERROR(INDEX(Base_OAPDI!$C$5:$C$187,MATCH($A33,Base_OAPDI!$U$5:$U$187,0)),"") | D33: =IFERROR(INDEX(Base_OAPDI!$B$5:$B$187,MATCH($A33,Base_OAPDI!$U$5:$U$187,0)),"") | E33: =IFERROR(INDEX(Base_OAPDI!$E$5:$E$187,MATCH($A33,Base_OAPDI!$U$5:$U$187,0)),"") | F33: =IFERROR(INDEX(Base_OAPDI!$H$5:$H$187,MATCH($A33,Base_OAPDI!$U$5:$U$187,0)),"") | G33: =IFERROR(INDEX(Base_OAPDI!$R$5:$R$187,MATCH($A33,Base_OAPDI!$U$5:$U$187,0)),"") | H33: =IFERROR(INDEX(Base_OAPDI!$N$5:$N$187,MATCH($A33,Base_OAPDI!$U$5:$U$187,0)),"") | I33: =IFERROR(INDEX(Base_OAPDI!$P$5:$P$187,MATCH($A33,Base_OAPDI!$U$5:$U$187,0)),"") | J33: =IFERROR(INDEX(Base_OAPDI!$S$5:$S$187,MATCH($A33,Base_OAPDI!$U$5:$U$187,0)),"") | K33: =IFERROR(INDEX(Base_OAPDI!$T$5:$T$187,MATCH($A33,Base_OAPDI!$U$5:$U$187,0)),"") | L33: =IFERROR(INDEX(Base_OAPDI!$Q$5:$Q$187,MATCH($A33,Base_OAPDI!$U$5:$U$187,0)),"") | N33: La decisión sobre cada compromiso se registra en la hoja Compromisos_2026.
A34: 27 | B34: =IFERROR(INDEX(Base_OAPDI!$A$5:$A$187,MATCH($A34,Base_OAPDI!$U$5:$U$187,0)),"") | C34: =IFERROR(INDEX(Base_OAPDI!$C$5:$C$187,MATCH($A34,Base_OAPDI!$U$5:$U$187,0)),"") | D34: =IFERROR(INDEX(Base_OAPDI!$B$5:$B$187,MATCH($A34,Base_OAPDI!$U$5:$U$187,0)),"") | E34: =IFERROR(INDEX(Base_OAPDI!$E$5:$E$187,MATCH($A34,Base_OAPDI!$U$5:$U$187,0)),"") | F34: =IFERROR(INDEX(Base_OAPDI!$H$5:$H$187,MATCH($A34,Base_OAPDI!$U$5:$U$187,0)),"") | G34: =IFERROR(INDEX(Base_OAPDI!$R$5:$R$187,MATCH($A34,Base_OAPDI!$U$5:$U$187,0)),"") | H34: =IFERROR(INDEX(Base_OAPDI!$N$5:$N$187,MATCH($A34,Base_OAPDI!$U$5:$U$187,0)),"") | I34: =IFERROR(INDEX(Base_OAPDI!$P$5:$P$187,MATCH($A34,Base_OAPDI!$U$5:$U$187,0)),"") | J34: =IFERROR(INDEX(Base_OAPDI!$S$5:$S$187,MATCH($A34,Base_OAPDI!$U$5:$U$187,0)),"") | K34: =IFERROR(INDEX(Base_OAPDI!$T$5:$T$187,MATCH($A34,Base_OAPDI!$U$5:$U$187,0)),"") | L34: =IFERROR(INDEX(Base_OAPDI!$Q$5:$Q$187,MATCH($A34,Base_OAPDI!$U$5:$U$187,0)),"")
A35: 28 | B35: =IFERROR(INDEX(Base_OAPDI!$A$5:$A$187,MATCH($A35,Base_OAPDI!$U$5:$U$187,0)),"") | C35: =IFERROR(INDEX(Base_OAPDI!$C$5:$C$187,MATCH($A35,Base_OAPDI!$U$5:$U$187,0)),"") | D35: =IFERROR(INDEX(Base_OAPDI!$B$5:$B$187,MATCH($A35,Base_OAPDI!$U$5:$U$187,0)),"") | E35: =IFERROR(INDEX(Base_OAPDI!$E$5:$E$187,MATCH($A35,Base_OAPDI!$U$5:$U$187,0)),"") | F35: =IFERROR(INDEX(Base_OAPDI!$H$5:$H$187,MATCH($A35,Base_OAPDI!$U$5:$U$187,0)),"") | G35: =IFERROR(INDEX(Base_OAPDI!$R$5:$R$187,MATCH($A35,Base_OAPDI!$U$5:$U$187,0)),"") | H35: =IFERROR(INDEX(Base_OAPDI!$N$5:$N$187,MATCH($A35,Base_OAPDI!$U$5:$U$187,0)),"") | I35: =IFERROR(INDEX(Base_OAPDI!$P$5:$P$187,MATCH($A35,Base_OAPDI!$U$5:$U$187,0)),"") | J35: =IFERROR(INDEX(Base_OAPDI!$S$5:$S$187,MATCH($A35,Base_OAPDI!$U$5:$U$187,0)),"") | K35: =IFERROR(INDEX(Base_OAPDI!$T$5:$T$187,MATCH($A35,Base_OAPDI!$U$5:$U$187,0)),"") | L35: =IFERROR(INDEX(Base_OAPDI!$Q$5:$Q$187,MATCH($A35,Base_OAPDI!$U$5:$U$187,0)),"")
A36: 29 | B36: =IFERROR(INDEX(Base_OAPDI!$A$5:$A$187,MATCH($A36,Base_OAPDI!$U$5:$U$187,0)),"") | C36: =IFERROR(INDEX(Base_OAPDI!$C$5:$C$187,MATCH($A36,Base_OAPDI!$U$5:$U$187,0)),"") | D36: =IFERROR(INDEX(Base_OAPDI!$B$5:$B$187,MATCH($A36,Base_OAPDI!$U$5:$U$187,0)),"") | E36: =IFERROR(INDEX(Base_OAPDI!$E$5:$E$187,MATCH($A36,Base_OAPDI!$U$5:$U$187,0)),"") | F36: =IFERROR(INDEX(Base_OAPDI!$H$5:$H$187,MATCH($A36,Base_OAPDI!$U$5:$U$187,0)),"") | G36: =IFERROR(INDEX(Base_OAPDI!$R$5:$R$187,MATCH($A36,Base_OAPDI!$U$5:$U$187,0)),"") | H36: =IFERROR(INDEX(Base_OAPDI!$N$5:$N$187,MATCH($A36,Base_OAPDI!$U$5:$U$187,0)),"") | I36: =IFERROR(INDEX(Base_OAPDI!$P$5:$P$187,MATCH($A36,Base_OAPDI!$U$5:$U$187,0)),"") | J36: =IFERROR(INDEX(Base_OAPDI!$S$5:$S$187,MATCH($A36,Base_OAPDI!$U$5:$U$187,0)),"") | K36: =IFERROR(INDEX(Base_OAPDI!$T$5:$T$187,MATCH($A36,Base_OAPDI!$U$5:$U$187,0)),"") | L36: =IFERROR(INDEX(Base_OAPDI!$Q$5:$Q$187,MATCH($A36,Base_OAPDI!$U$5:$U$187,0)),"")
A37: 30 | B37: =IFERROR(INDEX(Base_OAPDI!$A$5:$A$187,MATCH($A37,Base_OAPDI!$U$5:$U$187,0)),"") | C37: =IFERROR(INDEX(Base_OAPDI!$C$5:$C$187,MATCH($A37,Base_OAPDI!$U$5:$U$187,0)),"") | D37: =IFERROR(INDEX(Base_OAPDI!$B$5:$B$187,MATCH($A37,Base_OAPDI!$U$5:$U$187,0)),"") | E37: =IFERROR(INDEX(Base_OAPDI!$E$5:$E$187,MATCH($A37,Base_OAPDI!$U$5:$U$187,0)),"") | F37: =IFERROR(INDEX(Base_OAPDI!$H$5:$H$187,MATCH($A37,Base_OAPDI!$U$5:$U$187,0)),"") | G37: =IFERROR(INDEX(Base_OAPDI!$R$5:$R$187,MATCH($A37,Base_OAPDI!$U$5:$U$187,0)),"") | H37: =IFERROR(INDEX(Base_OAPDI!$N$5:$N$187,MATCH($A37,Base_OAPDI!$U$5:$U$187,0)),"") | I37: =IFERROR(INDEX(Base_OAPDI!$P$5:$P$187,MATCH($A37,Base_OAPDI!$U$5:$U$187,0)),"") | J37: =IFERROR(INDEX(Base_OAPDI!$S$5:$S$187,MATCH($A37,Base_OAPDI!$U$5:$U$187,0)),"") | K37: =IFERROR(INDEX(Base_OAPDI!$T$5:$T$187,MATCH($A37,Base_OAPDI!$U$5:$U$187,0)),"") | L37: =IFERROR(INDEX(Base_OAPDI!$Q$5:$Q$187,MATCH($A37,Base_OAPDI!$U$5:$U$187,0)),"")
A38: 31 | B38: =IFERROR(INDEX(Base_OAPDI!$A$5:$A$187,MATCH($A38,Base_OAPDI!$U$5:$U$187,0)),"") | C38: =IFERROR(INDEX(Base_OAPDI!$C$5:$C$187,MATCH($A38,Base_OAPDI!$U$5:$U$187,0)),"") | D38: =IFERROR(INDEX(Base_OAPDI!$B$5:$B$187,MATCH($A38,Base_OAPDI!$U$5:$U$187,0)),"") | E38: =IFERROR(INDEX(Base_OAPDI!$E$5:$E$187,MATCH($A38,Base_OAPDI!$U$5:$U$187,0)),"") | F38: =IFERROR(INDEX(Base_OAPDI!$H$5:$H$187,MATCH($A38,Base_OAPDI!$U$5:$U$187,0)),"") | G38: =IFERROR(INDEX(Base_OAPDI!$R$5:$R$187,MATCH($A38,Base_OAPDI!$U$5:$U$187,0)),"") | H38: =IFERROR(INDEX(Base_OAPDI!$N$5:$N$187,MATCH($A38,Base_OAPDI!$U$5:$U$187,0)),"") | I38: =IFERROR(INDEX(Base_OAPDI!$P$5:$P$187,MATCH($A38,Base_OAPDI!$U$5:$U$187,0)),"") | J38: =IFERROR(INDEX(Base_OAPDI!$S$5:$S$187,MATCH($A38,Base_OAPDI!$U$5:$U$187,0)),"") | K38: =IFERROR(INDEX(Base_OAPDI!$T$5:$T$187,MATCH($A38,Base_OAPDI!$U$5:$U$187,0)),"") | L38: =IFERROR(INDEX(Base_OAPDI!$Q$5:$Q$187,MATCH($A38,Base_OAPDI!$U$5:$U$187,0)),"")
A39: 32 | B39: =IFERROR(INDEX(Base_OAPDI!$A$5:$A$187,MATCH($A39,Base_OAPDI!$U$5:$U$187,0)),"") | C39: =IFERROR(INDEX(Base_OAPDI!$C$5:$C$187,MATCH($A39,Base_OAPDI!$U$5:$U$187,0)),"") | D39: =IFERROR(INDEX(Base_OAPDI!$B$5:$B$187,MATCH($A39,Base_OAPDI!$U$5:$U$187,0)),"") | E39: =IFERROR(INDEX(Base_OAPDI!$E$5:$E$187,MATCH($A39,Base_OAPDI!$U$5:$U$187,0)),"") | F39: =IFERROR(INDEX(Base_OAPDI!$H$5:$H$187,MATCH($A39,Base_OAPDI!$U$5:$U$187,0)),"") | G39: =IFERROR(INDEX(Base_OAPDI!$R$5:$R$187,MATCH($A39,Base_OAPDI!$U$5:$U$187,0)),"") | H39: =IFERROR(INDEX(Base_OAPDI!$N$5:$N$187,MATCH($A39,Base_OAPDI!$U$5:$U$187,0)),"") | I39: =IFERROR(INDEX(Base_OAPDI!$P$5:$P$187,MATCH($A39,Base_OAPDI!$U$5:$U$187,0)),"") | J39: =IFERROR(INDEX(Base_OAPDI!$S$5:$S$187,MATCH($A39,Base_OAPDI!$U$5:$U$187,0)),"") | K39: =IFERROR(INDEX(Base_OAPDI!$T$5:$T$187,MATCH($A39,Base_OAPDI!$U$5:$U$187,0)),"") | L39: =IFERROR(INDEX(Base_OAPDI!$Q$5:$Q$187,MATCH($A39,Base_OAPDI!$U$5:$U$187,0)),"")
A40: 33 | B40: =IFERROR(INDEX(Base_OAPDI!$A$5:$A$187,MATCH($A40,Base_OAPDI!$U$5:$U$187,0)),"") | C40: =IFERROR(INDEX(Base_OAPDI!$C$5:$C$187,MATCH($A40,Base_OAPDI!$U$5:$U$187,0)),"") | D40: =IFERROR(INDEX(Base_OAPDI!$B$5:$B$187,MATCH($A40,Base_OAPDI!$U$5:$U$187,0)),"") | E40: =IFERROR(INDEX(Base_OAPDI!$E$5:$E$187,MATCH($A40,Base_OAPDI!$U$5:$U$187,0)),"") | F40: =IFERROR(INDEX(Base_OAPDI!$H$5:$H$187,MATCH($A40,Base_OAPDI!$U$5:$U$187,0)),"") | G40: =IFERROR(INDEX(Base_OAPDI!$R$5:$R$187,MATCH($A40,Base_OAPDI!$U$5:$U$187,0)),"") | H40: =IFERROR(INDEX(Base_OAPDI!$N$5:$N$187,MATCH($A40,Base_OAPDI!$U$5:$U$187,0)),"") | I40: =IFERROR(INDEX(Base_OAPDI!$P$5:$P$187,MATCH($A40,Base_OAPDI!$U$5:$U$187,0)),"") | J40: =IFERROR(INDEX(Base_OAPDI!$S$5:$S$187,MATCH($A40,Base_OAPDI!$U$5:$U$187,0)),"") | K40: =IFERROR(INDEX(Base_OAPDI!$T$5:$T$187,MATCH($A40,Base_OAPDI!$U$5:$U$187,0)),"") | L40: =IFERROR(INDEX(Base_OAPDI!$Q$5:$Q$187,MATCH($A40,Base_OAPDI!$U$5:$U$187,0)),"")
A41: 34 | B41: =IFERROR(INDEX(Base_OAPDI!$A$5:$A$187,MATCH($A41,Base_OAPDI!$U$5:$U$187,0)),"") | C41: =IFERROR(INDEX(Base_OAPDI!$C$5:$C$187,MATCH($A41,Base_OAPDI!$U$5:$U$187,0)),"") | D41: =IFERROR(INDEX(Base_OAPDI!$B$5:$B$187,MATCH($A41,Base_OAPDI!$U$5:$U$187,0)),"") | E41: =IFERROR(INDEX(Base_OAPDI!$E$5:$E$187,MATCH($A41,Base_OAPDI!$U$5:$U$187,0)),"") | F41: =IFERROR(INDEX(Base_OAPDI!$H$5:$H$187,MATCH($A41,Base_OAPDI!$U$5:$U$187,0)),"") | G41: =IFERROR(INDEX(Base_OAPDI!$R$5:$R$187,MATCH($A41,Base_OAPDI!$U$5:$U$187,0)),"") | H41: =IFERROR(INDEX(Base_OAPDI!$N$5:$N$187,MATCH($A41,Base_OAPDI!$U$5:$U$187,0)),"") | I41: =IFERROR(INDEX(Base_OAPDI!$P$5:$P$187,MATCH($A41,Base_OAPDI!$U$5:$U$187,0)),"") | J41: =IFERROR(INDEX(Base_OAPDI!$S$5:$S$187,MATCH($A41,Base_OAPDI!$U$5:$U$187,0)),"") | K41: =IFERROR(INDEX(Base_OAPDI!$T$5:$T$187,MATCH($A41,Base_OAPDI!$U$5:$U$187,0)),"") | L41: =IFERROR(INDEX(Base_OAPDI!$Q$5:$Q$187,MATCH($A41,Base_OAPDI!$U$5:$U$187,0)),"")
A42: 35 | B42: =IFERROR(INDEX(Base_OAPDI!$A$5:$A$187,MATCH($A42,Base_OAPDI!$U$5:$U$187,0)),"") | C42: =IFERROR(INDEX(Base_OAPDI!$C$5:$C$187,MATCH($A42,Base_OAPDI!$U$5:$U$187,0)),"") | D42: =IFERROR(INDEX(Base_OAPDI!$B$5:$B$187,MATCH($A42,Base_OAPDI!$U$5:$U$187,0)),"") | E42: =IFERROR(INDEX(Base_OAPDI!$E$5:$E$187,MATCH($A42,Base_OAPDI!$U$5:$U$187,0)),"") | F42: =IFERROR(INDEX(Base_OAPDI!$H$5:$H$187,MATCH($A42,Base_OAPDI!$U$5:$U$187,0)),"") | G42: =IFERROR(INDEX(Base_OAPDI!$R$5:$R$187,MATCH($A42,Base_OAPDI!$U$5:$U$187,0)),"") | H42: =IFERROR(INDEX(Base_OAPDI!$N$5:$N$187,MATCH($A42,Base_OAPDI!$U$5:$U$187,0)),"") | I42: =IFERROR(INDEX(Base_OAPDI!$P$5:$P$187,MATCH($A42,Base_OAPDI!$U$5:$U$187,0)),"") | J42: =IFERROR(INDEX(Base_OAPDI!$S$5:$S$187,MATCH($A42,Base_OAPDI!$U$5:$U$187,0)),"") | K42: =IFERROR(INDEX(Base_OAPDI!$T$5:$T$187,MATCH($A42,Base_OAPDI!$U$5:$U$187,0)),"") | L42: =IFERROR(INDEX(Base_OAPDI!$Q$5:$Q$187,MATCH($A42,Base_OAPDI!$U$5:$U$187,0)),"")
A43: 36 | B43: =IFERROR(INDEX(Base_OAPDI!$A$5:$A$187,MATCH($A43,Base_OAPDI!$U$5:$U$187,0)),"") | C43: =IFERROR(INDEX(Base_OAPDI!$C$5:$C$187,MATCH($A43,Base_OAPDI!$U$5:$U$187,0)),"") | D43: =IFERROR(INDEX(Base_OAPDI!$B$5:$B$187,MATCH($A43,Base_OAPDI!$U$5:$U$187,0)),"") | E43: =IFERROR(INDEX(Base_OAPDI!$E$5:$E$187,MATCH($A43,Base_OAPDI!$U$5:$U$187,0)),"") | F43: =IFERROR(INDEX(Base_OAPDI!$H$5:$H$187,MATCH($A43,Base_OAPDI!$U$5:$U$187,0)),"") | G43: =IFERROR(INDEX(Base_OAPDI!$R$5:$R$187,MATCH($A43,Base_OAPDI!$U$5:$U$187,0)),"") | H43: =IFERROR(INDEX(Base_OAPDI!$N$5:$N$187,MATCH($A43,Base_OAPDI!$U$5:$U$187,0)),"") | I43: =IFERROR(INDEX(Base_OAPDI!$P$5:$P$187,MATCH($A43,Base_OAPDI!$U$5:$U$187,0)),"") | J43: =IFERROR(INDEX(Base_OAPDI!$S$5:$S$187,MATCH($A43,Base_OAPDI!$U$5:$U$187,0)),"") | K43: =IFERROR(INDEX(Base_OAPDI!$T$5:$T$187,MATCH($A43,Base_OAPDI!$U$5:$U$187,0)),"") | L43: =IFERROR(INDEX(Base_OAPDI!$Q$5:$Q$187,MATCH($A43,Base_OAPDI!$U$5:$U$187,0)),"")
A44: 37 | B44: =IFERROR(INDEX(Base_OAPDI!$A$5:$A$187,MATCH($A44,Base_OAPDI!$U$5:$U$187,0)),"") | C44: =IFERROR(INDEX(Base_OAPDI!$C$5:$C$187,MATCH($A44,Base_OAPDI!$U$5:$U$187,0)),"") | D44: =IFERROR(INDEX(Base_OAPDI!$B$5:$B$187,MATCH($A44,Base_OAPDI!$U$5:$U$187,0)),"") | E44: =IFERROR(INDEX(Base_OAPDI!$E$5:$E$187,MATCH($A44,Base_OAPDI!$U$5:$U$187,0)),"") | F44: =IFERROR(INDEX(Base_OAPDI!$H$5:$H$187,MATCH($A44,Base_OAPDI!$U$5:$U$187,0)),"") | G44: =IFERROR(INDEX(Base_OAPDI!$R$5:$R$187,MATCH($A44,Base_OAPDI!$U$5:$U$187,0)),"") | H44: =IFERROR(INDEX(Base_OAPDI!$N$5:$N$187,MATCH($A44,Base_OAPDI!$U$5:$U$187,0)),"") | I44: =IFERROR(INDEX(Base_OAPDI!$P$5:$P$187,MATCH($A44,Base_OAPDI!$U$5:$U$187,0)),"") | J44: =IFERROR(INDEX(Base_OAPDI!$S$5:$S$187,MATCH($A44,Base_OAPDI!$U$5:$U$187,0)),"") | K44: =IFERROR(INDEX(Base_OAPDI!$T$5:$T$187,MATCH($A44,Base_OAPDI!$U$5:$U$187,0)),"") | L44: =IFERROR(INDEX(Base_OAPDI!$Q$5:$Q$187,MATCH($A44,Base_OAPDI!$U$5:$U$187,0)),"")
A45: 38 | B45: =IFERROR(INDEX(Base_OAPDI!$A$5:$A$187,MATCH($A45,Base_OAPDI!$U$5:$U$187,0)),"") | C45: =IFERROR(INDEX(Base_OAPDI!$C$5:$C$187,MATCH($A45,Base_OAPDI!$U$5:$U$187,0)),"") | D45: =IFERROR(INDEX(Base_OAPDI!$B$5:$B$187,MATCH($A45,Base_OAPDI!$U$5:$U$187,0)),"") | E45: =IFERROR(INDEX(Base_OAPDI!$E$5:$E$187,MATCH($A45,Base_OAPDI!$U$5:$U$187,0)),"") | F45: =IFERROR(INDEX(Base_OAPDI!$H$5:$H$187,MATCH($A45,Base_OAPDI!$U$5:$U$187,0)),"") | G45: =IFERROR(INDEX(Base_OAPDI!$R$5:$R$187,MATCH($A45,Base_OAPDI!$U$5:$U$187,0)),"") | H45: =IFERROR(INDEX(Base_OAPDI!$N$5:$N$187,MATCH($A45,Base_OAPDI!$U$5:$U$187,0)),"") | I45: =IFERROR(INDEX(Base_OAPDI!$P$5:$P$187,MATCH($A45,Base_OAPDI!$U$5:$U$187,0)),"") | J45: =IFERROR(INDEX(Base_OAPDI!$S$5:$S$187,MATCH($A45,Base_OAPDI!$U$5:$U$187,0)),"") | K45: =IFERROR(INDEX(Base_OAPDI!$T$5:$T$187,MATCH($A45,Base_OAPDI!$U$5:$U$187,0)),"") | L45: =IFERROR(INDEX(Base_OAPDI!$Q$5:$Q$187,MATCH($A45,Base_OAPDI!$U$5:$U$187,0)),"")
... A47: 40 | B47: =IFERROR(INDEX(Base_OAPDI!$A$5:$A$187,MATCH($A47,Base_OAPDI!$U$5:$U$187,0)),"") | C47: =IFERROR(INDEX(Base_OAPDI!$C$5:$C$187,MATCH($A47,Base_OAPDI!$U$5:$U$187,0)),"") | D47: =IFERROR(INDEX(Base_OAPDI!$B$5:$B$187,MATCH($A47,Base_OAPDI!$U$5:$U$187,0)),"") | E47: =IFERROR(INDEX(Base_OAPDI!$E$5:$E$187,MATCH($A47,Base_OAPDI!$U$5:$U$187,0)),"") | F47: =IFERROR(INDEX(Base_OAPDI!$H$5:$H$187,MATCH($A47,Base_OAPDI!$U$5:$U$187,0)),"") | G47: =IFERROR(INDEX(Base_OAPDI!$R$5:$R$187,MATCH($A47,Base_OAPDI!$U$5:$U$187,0)),"") | H47: =IFERROR(INDEX(Base_OAPDI!$N$5:$N$187,MATCH($A47,Base_OAPDI!$U$5:$U$187,0)),"") | I47: =IFERROR(INDEX(Base_OAPDI!$P$5:$P$187,MATCH($A47,Base_OAPDI!$U$5:$U$187,0)),"") | J47: =IFERROR(INDEX(Base_OAPDI!$S$5:$S$187,MATCH($A47,Base_OAPDI!$U$5:$U$187,0)),"") | K47: =IFERROR(INDEX(Base_OAPDI!$T$5:$T$187,MATCH($A47,Base_OAPDI!$U$5:$U$187,0)),"") | L47: =IFERROR(INDEX(Base_OAPDI!$Q$5:$Q$187,MATCH($A47,Base_OAPDI!$U$5:$U$187,0)),"")
A49: ACCIONES ADICIONALES DEL ÁREA (diligenciar)
A50: N.° | B50: Área funcional (lista) | C50: Código de meta PDI (lista) | D50: Eje | E50: Línea | F50: Meta estratégica (PDI) | G50: Origen de la acción | H50: Nombre de la acción | I50: Descripción de la acción | J50: Producto esperado | K50: Fecha de inicio (dd/mm/aaaa) | L50: Fecha de fin (dd/mm/aaaa) | M50: Responsable (correo institucional) | N50: Indicador de seguimiento | O50: Meta 2027 de la acción | P50: Unidad de medida | Q50: Dimensión de impacto | R50: Indicador de impacto (Guía Metodológica) | S50: Categoría de impacto (automática) | T50: ¿Retoma un compromiso pendiente 2026? | U50: Evidencia verificable | V50: Observaciones | W50: Alerta de consistencia
A51: 1 | D51: =IF(C51="","",INDEX(Catalogos!$C$5:$C$49,MATCH(LEFT(C51,7),Catalogos!$A$5:$A$49,0))) | E51: =IF(C51="","",INDEX(Catalogos!$D$5:$D$49,MATCH(LEFT(C51,7),Catalogos!$A$5:$A$49,0))&" "&INDEX(Catalogos!$E$5:$E$49,MATCH(LEFT(C51,7),Catalogos!$A$5:$A$49,0))) | F51: =IF(C51="","",INDEX(Catalogos!$F$5:$F$49,MATCH(LEFT(C51,7),Catalogos!$A$5:$A$49,0))) | S51: =IF(R51="","",INDEX(Catalogos!$Y$5:$Y$25,MATCH(R51,L_IMP,0))) | W51: =IF(H51="","Pendiente por formular",IF(OR(J51="",K51="",L51="",M51="",N51="",O51="",Q51="",R51="",B51="",C51="",G51=""),"Incompleta: faltan campos obligatorios",IF(OR(NOT(ISNUMBER(K51)),NOT(ISNUMBER(L51))),"Fecha inválida",IF(L51<K51,"La fecha de fin es anterior a la de inicio",IF(OR(YEAR(K51)<>2027,YEAR(L51)<>2027),"Fechas fuera de la vigencia 2027",IF(ISERROR(SEARCH("@itc.edu.co",M51)),"El responsable no tiene correo institucional",IF(ISERROR(SEARCH(Q51,INDEX(Catalogos!$Z$5:$Z$25,MATCH(R51,L_IMP,0)))),"La dimensión no corresponde al indicador de impacto","OK"))))))) -> Pendiente por formular
A52: 2 | D52: =IF(C52="","",INDEX(Catalogos!$C$5:$C$49,MATCH(LEFT(C52,7),Catalogos!$A$5:$A$49,0))) | E52: =IF(C52="","",INDEX(Catalogos!$D$5:$D$49,MATCH(LEFT(C52,7),Catalogos!$A$5:$A$49,0))&" "&INDEX(Catalogos!$E$5:$E$49,MATCH(LEFT(C52,7),Catalogos!$A$5:$A$49,0))) | F52: =IF(C52="","",INDEX(Catalogos!$F$5:$F$49,MATCH(LEFT(C52,7),Catalogos!$A$5:$A$49,0))) | S52: =IF(R52="","",INDEX(Catalogos!$Y$5:$Y$25,MATCH(R52,L_IMP,0))) | W52: =IF(H52="","Pendiente por formular",IF(OR(J52="",K52="",L52="",M52="",N52="",O52="",Q52="",R52="",B52="",C52="",G52=""),"Incompleta: faltan campos obligatorios",IF(OR(NOT(ISNUMBER(K52)),NOT(ISNUMBER(L52))),"Fecha inválida",IF(L52<K52,"La fecha de fin es anterior a la de inicio",IF(OR(YEAR(K52)<>2027,YEAR(L52)<>2027),"Fechas fuera de la vigencia 2027",IF(ISERROR(SEARCH("@itc.edu.co",M52)),"El responsable no tiene correo institucional",IF(ISERROR(SEARCH(Q52,INDEX(Catalogos!$Z$5:$Z$25,MATCH(R52,L_IMP,0)))),"La dimensión no corresponde al indicador de impacto","OK"))))))) -> Pendiente por formular
