Workbook
Name L_AREAS: Catalogos!$Q$5:$Q$51
Name L_ESTVF: Catalogos!$AF$5:$AF$8
Name L_FUENTE: Catalogos!$AC$5:$AC$12
Name L_GASTO: Catalogos!$AD$5:$AD$6
Name L_MESES: Catalogos!$Z$5:$Z$16
Name L_METAS: Catalogos!$I$5:$I$49
Name L_MOD: Catalogos!$AB$5:$AB$11
Name L_PRIOR: Catalogos!$AH$5:$AH$7
Name L_REG2026: '2026'!$A$5:$A$428
Name L_SINO: Catalogos!$AE$5:$AE$6
Name L_TIPO: Catalogos!$AG$5:$AG$15
Name L_UNIDAD: Catalogos!$AA$5:$AA$7
Name P_FECHA: Tablero_Consistencia!$B$9
Name P_SMMLV: Tablero_Consistencia!$B$8
Name P_TOPE_MENOR: Tablero_Consistencia!$B$6
Name P_TOPE_MINIMA: Tablero_Consistencia!$B$7

Sheet Instructivo
A1: Plan de Necesidades 2027 — Escuela Tecnológica Instituto Técnico Central (ETITC)
A2: Oficina Asesora de Planeación y Desarrollo Institucional (OAPDI) · Versión 1 · Complemento de la Plantilla de Formulación 2027 (versión 7) · Libro protegido: solo se diligencian las celdas amarillas.
A4: 1. Propósito
A5: Este libro es el instrumento con el que cada dependencia y área funcional de la ETITC registra los bienes, obras y servicios que necesita contratar en 2027 para ejecutar las acciones de su Plan de Acción. Es el complemento de la Plantilla de Formulación 2027: en la plantilla el área dice qué va a hacer (acción, producto, indicador); en este libro dice qué necesita adquirir para hacerlo. Cada necesidad se vincula a una acción del Plan de Acción 2027 y, por medio de ella, a una meta del Plan de Desarrollo Institucional (PDI) 2025-2032, de modo que ningún recurso se programe sin una meta que lo justifique. La OAPDI consolida el libro y lo entrega como insumo del Plan Anual de Adquisiciones que la ETITC publica en SECOP II. Convención de siglas: en este libro, como en la plantilla, la sigla PAA se reserva para el Plan de Acción Anual; el Plan Anual de Adquisiciones se escribe siempre completo para no confundirlos.
A7: 2. Marco normativo
A8: Ley 80 de 1993 (Estatuto General de Contratación de la Administración Pública) y Ley 1150 de 2007 (modalidades de selección, artículo 2). Ley 1474 de 2011, artículo 74: las entidades publican en su página web, a más tardar el 31 de enero de cada año, el plan de acción con los proyectos de inversión, el presupuesto y el plan general de compras. Decreto 1082 de 2015, artículos 2.2.1.1.1.4.1 a 2.2.1.1.1.4.4: el Plan Anual de Adquisiciones debe listar los bienes, obras y servicios que se pretende adquirir, identificados con el Clasificador de Bienes y Servicios (UNSPSC), con su valor estimado, la fuente de los recursos, la modalidad de selección y la fecha aproximada de inicio del proceso; se publica en la página web y en SECOP y se actualiza por lo menos una vez durante la vigencia. Guía para elaborar el Plan Anual de Adquisiciones de Colombia Compra Eficiente. Decreto 111 de 1996 (Estatuto Orgánico del Presupuesto): ninguna necesidad se contrata sin certificado de disponibilidad presupuestal. Ley 152 de 1994 y Modelo Integrado de Planeación y Gestión (MIPG): articulación entre planeación, presupuesto y contratación.
A10: 3. Del plan de necesidades al Plan Anual de Adquisiciones: la ruta
A11: Etapa 1 — El área formula sus acciones 2027 en la Plantilla de Formulación 2027.
A12: Etapa 2 — El área registra en la hoja "Formulación PDN 2027" cada bien, obra o servicio que requiere una de esas acciones, con su código UNSPSC, valor, fechas, modalidad estimada, fuente y responsable.
A13: Etapa 3 — La OAPDI revisa el Tablero_Consistencia: alineación con la meta y la acción, alertas, comparación con 2026 y acciones con presupuesto que no registran necesidades.
A14: Etapa 4 — La Vicerrectoría Administrativa y Financiera (presupuesto) confirma la fuente, el rubro o proyecto de inversión y la viabilidad de las vigencias futuras.
A15: Etapa 5 — El GIT de Contratación y Adquisiciones toma la hoja "Insumo_Plan_Adquisiciones", agrupa necesidades iguales, confirma la modalidad según los topes de la vigencia, asigna la unidad de contratación y convierte los textos a los códigos de la plantilla de cargue de SECOP II.
... A39: 6. Diccionario de campos de la hoja Formulación PDN 2027
A40: Columna | B40: Campo | C40: Qué registrar | D40: Obligatorio | E40: Uso en el Plan Anual de Adquisiciones (campo SECOP II)
A41: A | B41: N.° necesidad | C41: Automático (PN27-001, PN27-002…). Identifica la necesidad en toda la cadena: OAPDI, presupuesto y contratación. | D41: Automático | E41: Trazabilidad interna.
A42: B | B42: Área funcional que formula | C42: Seleccione su área de la lista (las mismas 47 áreas de la Plantilla de Formulación 2027). | D42: Sí | E42: Trazabilidad; define la unidad de contratación.
A43: C-D | B43: Dependencia y proceso | C43: Automáticos: dependencia del Decreto 902 de 2013 / Resolución 215 de 2022 y proceso del mapa GDC-DI-01 V9. | D43: Automático | E43: Trazabilidad interna.
A44: E | B44: Meta estratégica PDI | C44: Seleccione la meta (código eje.línea.objetivo.meta) a la que aporta la acción que requiere la necesidad. | D44: Sí | E44: Justificación estratégica de la adquisición.
A45: F-G | B45: Eje y línea | C45: Automáticos a partir de la meta. | D45: Automático | E45: Trazabilidad interna.
A46: H | B46: Acción del Plan de Acción 2027 | C46: Seleccione la acción A27-### de la lista (filtrada por la meta) o "PROPIA" si es una acción formulada por el área. | D46: Sí | E46: Vincula el gasto con la planeación (Ley 1474 de 2011, art. 74).
A47: I | B47: Nombre de la acción propia | C47: Solo si eligió PROPIA: el nombre de la acción tal como quedó en la Plantilla de Formulación 2027. | D47: Condicional | E47: Trazabilidad interna.
A48: J | B48: Tipo de necesidad | C48: Servicios profesionales, apoyo a la gestión, bienes, suministro, mantenimiento, obra, consultoría, interventoría, licencias, arrendamiento u otro. | D48: Sí | E48: Orienta la modalidad y la agrupación de procesos.
A49: K | B49: Justificación de la necesidad | C49: Qué problema resuelve y qué producto de la acción no podría lograrse sin ella. Sea concreto: es la base de los estudios previos. | D49: Sí | E49: Estudios previos.
A50: L | B50: Descripción del objeto contractual | C50: Qué se va a adquirir o contratar y para qué. Ejemplo: "Prestar servicios profesionales para…", "Adquirir equipos de cómputo para…". | D50: Sí | E50: Descripción.
A51: M | B51: Código UNSPSC principal | C51: Un solo código de 8 dígitos, como número, a nivel de clase (termina en 00) o de producto. Ver Guía UNSPSC. | D51: Sí | E51: Códigos UNSPSC.
... A66: AJ | B66: Alerta de consistencia | C66: Automática. Debe decir OK para que la necesidad pase al Insumo del Plan Anual de Adquisiciones. | D66: Automático | E66: Control de calidad.
A68: 7. Reglas de calidad
A69: Una necesidad por fila y un objeto por necesidad. Toda necesidad sirve a una acción del Plan de Acción 2027; si la acción no existe, primero se formula en la plantilla. El código UNSPSC se registra como número de 8 dígitos (clase o producto). Los valores se registran en pesos colombianos, sin puntos, signos ni texto, y el valor de la vigencia 2027 no supera el total. Si el contrato se paga en más de una vigencia, marque vigencias futuras y su estado. El mes de presentación de ofertas no es anterior al de inicio. El responsable se identifica con correo institucional @itc.edu.co, sin tildes ni espacios. No registre como necesidad algo que no se va a contratar (por ejemplo, actividades que el área ejecuta con su propio personal de planta).
A71: 8. Convenciones
A72: Gris: información automática o de la OAPDI (bloqueada). Amarillo: celdas habilitadas para diligenciar. Verde: control y anotaciones de la OAPDI. El marcador [PENDIENTE DE VERIFICAR] señala un dato que ningún documento fuente confirma y que debe validarse antes de usarlo. El libro está protegido; la hoja 2026 y la estructura del libro (crear, borrar u ocultar hojas) solo las puede desbloquear la OAPDI.
A74: 9. Ejemplo de fila diligenciada (solo ilustrativo; no corresponde a una necesidad aprobada)
A75: Área (B) | B75: A05 · Planeación y Plan de Acción (101)
A76: Meta PDI (E) | B76: 4.2.1.2 · Contar con un (1) sistema de información estratégico.
A77: Acción (H) | B77: A27-093 · Formalizar el cierre de la implementación del SIUE y su manual de uso
A78: Tipo / objeto (J, L) | B78: Prestación de servicios profesionales / Prestar servicios profesionales a la OAPDI para el mantenimiento y fortalecimiento del sistema de información estratégico y la analítica de datos institucional.
A79: UNSPSC (M) | B79: 80111600 (clase; verifique en el clasificador si existe un producto más preciso)
A80: Meses (O, P) / duración (Q, R) | B80: Enero / Enero — 11 Meses
A81: Modalidad / fuente / gasto (S, T, U) | B81: Contratación directa / Presupuesto General de la Nación – funcionamiento / Funcionamiento
A82: Valor total y 2027 (W, X) | B82: 60500000 y 60500000 (cifras ilustrativas tomadas de una necesidad similar de 2026)
A83: Vigencias futuras (Y, Z) | B83: No / No aplica
...

Sheet Guía UNSPSC
A1: Guía del Código Estándar de Productos y Servicios de las Naciones Unidas (UNSPSC)
A2: Cómo identificar el código de cada necesidad para que el Plan de Necesidades se convierta en el Plan Anual de Adquisiciones.
A4: 1. Qué es el UNSPSC y por qué es obligatorio
A5: El UNSPSC (United Nations Standard Products and Services Code, Código Estándar de Productos y Servicios de las Naciones Unidas) es un sistema de clasificación de cuatro niveles que asigna un código numérico de 8 dígitos a cada bien, obra o servicio. En Colombia se adoptó como el Clasificador de Bienes y Servicios que administra la Agencia Nacional de Contratación Pública – Colombia Compra Eficiente. El Decreto 1082 de 2015 (artículo 2.2.1.1.1.4.1) exige que cada adquisición del Plan Anual de Adquisiciones se identifique con este clasificador, y SECOP II no admite una adquisición sin código. El código tiene además tres efectos prácticos: (a) es el idioma común con los proveedores, porque los proponentes se inscriben en el Registro Único de Proponentes (RUP) con estos mismos códigos; (b) define qué proveedores reciben la alerta del proceso en SECOP II y quiénes pueden acreditar experiencia; y (c) permite a la ETITC agrupar compras iguales de varias áreas en un solo proceso. Un código mal elegido puede dejar por fuera a los proveedores idóneos o invalidar la verificación de experiencia.
A7: 2. Estructura del código: cuatro niveles, dos dígitos por nivel
A8: Nivel | B8: Dígitos que identifica | C8: Código de ejemplo | D8: Denominación de referencia del ejemplo | E8: ¿Sirve para SECOP II? | F8: Comentario
A9: 1. Segmento | B9: 2 primeros (80) | C9: 80000000 | D9: Servicios de gestión, servicios profesionales de empresa y servicios administrativos | E9: No | F9: Agrupa sectores completos; es demasiado general.
A10: 2. Familia | B10: 4 primeros (8011) | C10: 80110000 | D10: Servicios de recursos humanos | E10: No | F10: Sigue siendo general; SECOP II exige tercer o cuarto nivel.
A11: 3. Clase | B11: 6 primeros (801116) | C11: 80111600 | D11: Servicios de personal temporal | E11: Sí | F11: Termina en 00. Úsela cuando no exista un producto exacto o el objeto agrupe varios productos de la misma clase.
A12: 4. Producto | B12: 8 dígitos (80111601) | C12: 80111601 | D12: Asistencia de oficina o administrativa temporal | E12: Sí (preferible) | F12: Es el nivel más preciso; úselo siempre que exista.
A13: Nota: las denominaciones de esta guía son de referencia para explicar la estructura. La denominación oficial y vigente es la que muestra el clasificador de Colombia Compra Eficiente; verifíquela siempre allí antes de registrar el código.
A15: 3. Cómo encontrar el código correcto (paso a paso)
A16: Paso 1. Defina primero el objeto: qué se compra o contrata y para qué (columna L de la hoja de formulación). El código se escoge a partir del objeto, no al revés.
A17: Paso 2. Ingrese al Clasificador de Bienes y Servicios de Colombia Compra Eficiente: https://operaciones.colombiacompra.gov.co/clasificador-de-bienes-y-servicios (también puede usar el buscador de códigos del Registro Único de Proponentes en SECOP II).
A18: Paso 3. Busque por palabra clave del bien o servicio (por ejemplo: "mantenimiento", "licencia de software", "extintores") o navegue de lo general a lo particular: segmento → familia → clase → producto.
A19: Paso 4. Elija el producto (8 dígitos) que corresponda exactamente. Si el objeto agrupa varios productos de la misma clase, registre la clase (6 dígitos seguidos de 00).
A20: Paso 5. Registre en la columna M un solo código de 8 dígitos, como número, sin espacios, puntos ni texto. Si el objeto requiere códigos de otras clases (por ejemplo, suministro e instalación), regístrelos en la columna N separados por punto y coma (;).
A21: Paso 6. Verifique con el GIT de Contratación y Adquisiciones cuando dude entre dos códigos: el código debe ser coherente con los requisitos habilitantes que se pedirán en el RUP.
A22: Paso 7. Revise la columna "Alerta de consistencia": si dice "Código UNSPSC inválido" o "a nivel de segmento o familia", corrija antes de remitir.
A24: 4. Errores frecuentes encontrados en la formulación 2026 (hoja 2026)
A25: • De 424 registros 2026, 43 tienen el código vacío, escrito como texto o con varios códigos en la misma celda (por ejemplo, "39120000 39121700"); SECOP II solo lee un código por campo.
A26: • 20 registros usan códigos a nivel de segmento o familia (terminados en 0000, por ejemplo 41000000 o 60000000), que SECOP II no acepta como identificación de la adquisición.
... A31: 5. Segmentos usados por la ETITC en 2026 (orientación para buscar)
A32: Segmento | B32: N.° de códigos registrados en 2026 | D32: Denominación de referencia
A33: 11 | B33: 5 | D33: Material mineral, textil y vegetal y animal no comestible
A34: 12 | B34: 3 | D34: Material químico, incluidos bioquímicos y materiales de gas
A35: 13 | B35: 2 | D35: Materiales de resina, colofonia, caucho, espuma, película y elastómeros
A36: 14 | B36: 2 | D36: Materiales y productos de papel
A37: 20 | B37: 1 | D37: Maquinaria y accesorios de minería y perforación de pozos
A38: 22 | B38: 1 | D38: Maquinaria y accesorios para construcción y edificación
A39: 23 | B39: 17 | D39: Maquinaria y accesorios de manufactura y procesamiento industrial
A40: 24 | B40: 4 | D40: Maquinaria, accesorios y suministros para manejo, acondicionamiento y almacenamiento de materiales
A41: 25 | B41: 1 | D41: Vehículos comerciales, militares y particulares, accesorios y componentes
A42: 27 | B42: 6 | D42: Herramientas y maquinaria general
A43: 30 | B43: 6 | D43: Componentes y suministros para estructuras, edificación, construcción y obras civiles
A44: 31 | B44: 3 | D44: Componentes y suministros de manufactura
... A77: 95 | B77: 4 | D77: Terrenos, edificios, estructuras y vías
A79: 6. Códigos de 8 dígitos usados en 2026, con un ejemplo de objeto (consulta rápida; verifique siempre la denominación oficial)
A80: Código | B80: Nivel | C80: Veces en 2026 | D80: Ejemplo de objeto contractual 2026 | E80: N.° registro 2026 | F80: Área que lo registró (2026)
A81: 80111600 | B81: Clase | C81: 56 | D81: Prestar servicios profesionales para apoyar el diseño, implementación, conformación y seguimiento del Plan de Emergencias de la Escuela Tecnológica Instituto Técnico Central – ETITC y sus sedes, así como para realizar l… | E81: PN26-006 | F81: Talento humano - Seguridad y salud en el trabajo
...

Sheet Formulación PDN 2027
A1: Formulación del Plan de Necesidades 2027 — Escuela Tecnológica Instituto Técnico Central (ETITC)
A2: Una necesidad (bien, obra o servicio) por fila. Cada necesidad se vincula a una acción del Plan de Acción 2027 y, por ella, a una meta del PDI 2025-2032. Lo diligenciado aquí alimenta el Plan Anual de Adquisiciones.
A3: Gris: datos automáticos (no se editan). Amarillo: celdas que diligencia el área. Verde oscuro: control de la OAPDI. Diligencie en orden: área → meta → acción → necesidad. Consulte el Instructivo y la Guía UNSPSC.
A5: IDENTIFICACIÓN DEL ÁREA | E5: ALINEACIÓN CON EL PLAN DE ACCIÓN 2027 Y EL PDI | J5: LA NECESIDAD | M5: DATOS PARA EL PLAN ANUAL DE ADQUISICIONES (SECOP II) | AB5: RESPONSABLE | AF5: TRAZABILIDAD 2026 Y PRIORIDAD | AJ5: CONTROL
A6: N.° necesidad | B6: Área funcional que formula | C6: Dependencia (Decreto 902 de 2013) | D6: Proceso (mapa GDC-DI-01 V9) | E6: Meta estratégica PDI 2025-2032 | F6: Eje estratégico | G6: Línea de acción | H6: Acción del Plan de Acción 2027 a la que sirve la necesidad | I6: Nombre de la acción propia del área (solo si eligió PROPIA) | J6: Tipo de necesidad | K6: Justificación de la necesidad (qué problema resuelve y qué producto de la acción permite) | L6: Descripción del objeto contractual | M6: Código UNSPSC principal (8 dígitos) | N6: Códigos UNSPSC adicionales (separados por ;) | O6: Mes estimado de inicio del proceso de selección | P6: Mes estimado de presentación de ofertas | Q6: Duración del contrato (número) | R6: Unidad de duración | S6: Modalidad de selección | T6: Fuente de los recursos | U6: Tipo de gasto | V6: Rubro presupuestal o proyecto de inversión (BPIN) | W6: Valor total estimado ($, sin puntos) | X6: Valor estimado vigencia 2027 ($, sin puntos) | Y6: ¿Requiere vigencias futuras? | Z6: Estado de la solicitud de vigencias futuras | AA6: Sede o lugar de ejecución | AB6: Nombre del responsable (supervisor previsto) | AC6: Cargo del responsable | AD6: Teléfono / extensión | AE6: Correo institucional del responsable | AF6: ¿Continúa una necesidad 2026? | AG6: N.° de registro 2026 que continúa (hoja 2026) | AH6: Prioridad | AI6: Observaciones | AJ6: Alerta de consistencia | AK6: Aux. índice exportación
A7: ="PN27-"&TEXT(ROW()-6,"000") -> PN27-001 | C7: =IF(B7="","",IFERROR(INDEX(Catalogos!$R$5:$R$51,MATCH(B7,L_AREAS,0)),"")) | D7: =IF(B7="","",IFERROR(INDEX(Catalogos!$O$5:$O$51,MATCH(B7,L_AREAS,0)),"")) | F7: =IF(E7="","",IFERROR(INDEX(Catalogos!$C$5:$C$49,MATCH(E7,L_METAS,0)),"")) | G7: =IF(E7="","",IFERROR(INDEX(Catalogos!$E$5:$E$49,MATCH(E7,L_METAS,0)),"")) | AJ7: =IF(COUNTA(B7,E7,H7,I7,J7,K7,L7,M7,N7,O7,P7,Q7,R7,S7,T7,U7,V7,W7,X7,Y7,Z7,AA7,AB7,AC7,AD7,AE7,AF7,AG7,AH7,AI7)=0,"",IF(OR(B7="",E7="",H7="",J7="",K7="",L7="",M7="",O7="",P7="",Q7="",R7="",S7="",T7="",U7="",W7="",X7="",Y7="",AB7="",AC7="",AE7="",AF7=""),"Incompleta: faltan campos obligatorios",IF(AND(LEFT(H7,6)="PROPIA",I7=""),"Falta el nombre de la acción propia del área",IF(AND(LEFT(H7,3)="A27",IFERROR(INDEX(Catalogos!$T$5:$T$207,MATCH(H7,Catalogos!$U$5:$U$207,0)),"x")<>LEFT(E7,7)),"La acción no corresponde a la meta seleccionada",IF(OR(NOT(ISNUMBER(M7)),M7<10000000,M7>99999999),"Código UNSPSC inválido: registre 8 dígitos",IF(MOD(M7,10000)=0,"UNSPSC a nivel de segmento o familia: use clase o producto",IF(IFERROR(MATCH(P7,L_MESES,0)<MATCH(O7,L_MESES,0),TRUE()),"El mes de ofertas es anterior al de inicio del proceso",IF(OR(NOT(ISNUMBER(Q7)),Q7<=0),"Duración inválida",IF(OR(NOT(ISNUMBER(W7)),NOT(ISNUMBER(X7))),"Valor inválido: registre solo números",IF(OR(W7<=0,X7<=0),"Valor inválido: debe ser mayor que cero",IF(X7>W7,"El valor de la vigencia 2027 supera el valor total",IF(AND(X7<W7,Y7="No"),"El valor total supera el de 2027: requiere vigencias futuras",IF(AND(Y7="Sí",OR(Z7="",Z7="No aplica")),"Indique el estado de la solicitud de vigencias futuras",IF(IF(AND(S7="Mínima cuantía",ISNUMBER(P_TOPE_MINIMA)),W7>P_TOPE_MINIMA,FALSE()),"El valor supera el tope de mínima cuantía 2027",IF(IF(AND(S7="Selección abreviada de menor cuantía",ISNUMBER(P_TOPE_MENOR)),W7>P_TOPE_MENOR,FALSE()),"El valor supera el tope de menor cuantía 2027",IF(OR(ISERROR(SEARCH("@itc.edu.co",AE7)),SUMPRODUCT(--ISNUMBER(SEARCH({"á","é","í","ó","ú","ñ"," "},AE7)))>0),"El correo del responsable no es institucional válido",IF(AND(AF7="Sí",AG7=""),"Indique el N.° de registro 2026 que continúa","OK"))))))))))))))))) | AK7: =IF(AJ7="OK",COUNTIF($AJ$7:AJ7,"OK"),"")
A8: ="PN27-"&TEXT(ROW()-6,"000") -> PN27-002 | C8: =IF(B8="","",IFERROR(INDEX(Catalogos!$R$5:$R$51,MATCH(B8,L_AREAS,0)),"")) | D8: =IF(B8="","",IFERROR(INDEX(Catalogos!$O$5:$O$51,MATCH(B8,L_AREAS,0)),"")) | F8: =IF(E8="","",IFERROR(INDEX(Catalogos!$C$5:$C$49,MATCH(E8,L_METAS,0)),"")) | G8: =IF(E8="","",IFERROR(INDEX(Catalogos!$E$5:$E$49,MATCH(E8,L_METAS,0)),"")) | AJ8: =IF(COUNTA(B8,E8,H8,I8,J8,K8,L8,M8,N8,O8,P8,Q8,R8,S8,T8,U8,V8,W8,X8,Y8,Z8,AA8,AB8,AC8,AD8,AE8,AF8,AG8,AH8,AI8)=0,"",IF(OR(B8="",E8="",H8="",J8="",K8="",L8="",M8="",O8="",P8="",Q8="",R8="",S8="",T8="",U8="",W8="",X8="",Y8="",AB8="",AC8="",AE8="",AF8=""),"Incompleta: faltan campos obligatorios",IF(AND(LEFT(H8,6)="PROPIA",I8=""),"Falta el nombre de la acción propia del área",IF(AND(LEFT(H8,3)="A27",IFERROR(INDEX(Catalogos!$T$5:$T$207,MATCH(H8,Catalogos!$U$5:$U$207,0)),"x")<>LEFT(E8,7)),"La acción no corresponde a la meta seleccionada",IF(OR(NOT(ISNUMBER(M8)),M8<10000000,M8>99999999),"Código UNSPSC inválido: registre 8 dígitos",IF(MOD(M8,10000)=0,"UNSPSC a nivel de segmento o familia: use clase o producto",IF(IFERROR(MATCH(P8,L_MESES,0)<MATCH(O8,L_MESES,0),TRUE()),"El mes de ofertas es anterior al de inicio del proceso",IF(OR(NOT(ISNUMBER(Q8)),Q8<=0),"Duración inválida",IF(OR(NOT(ISNUMBER(W8)),NOT(ISNUMBER(X8))),"Valor inválido: registre solo números",IF(OR(W8<=0,X8<=0),"Valor inválido: debe ser mayor que cero",IF(X8>W8,"El valor de la vigencia 2027 supera el valor total",IF(AND(X8<W8,Y8="No"),"El valor total supera el de 2027: requiere vigencias futuras",IF(AND(Y8="Sí",OR(Z8="",Z8="No aplica")),"Indique el estado de la solicitud de vigencias futuras",IF(IF(AND(S8="Mínima cuantía",ISNUMBER(P_TOPE_MINIMA)),W8>P_TOPE_MINIMA,FALSE()),"El valor supera el tope de mínima cuantía 2027",IF(IF(AND(S8="Selección abreviada de menor cuantía",ISNUMBER(P_TOPE_MENOR)),W8>P_TOPE_MENOR,FALSE()),"El valor supera el tope de menor cuantía 2027",IF(OR(ISERROR(SEARCH("@itc.edu.co",AE8)),SUMPRODUCT(--ISNUMBER(SEARCH({"á","é","í","ó","ú","ñ"," "},AE8)))>0),"El correo del responsable no es institucional válido",IF(AND(AF8="Sí",AG8=""),"Indique el N.° de registro 2026 que continúa","OK"))))))))))))))))) | AK8: =IF(AJ8="OK",COUNTIF($AJ$7:AJ8,"OK"),"")
A9: ="PN27-"&TEXT(ROW()-6,"000") -> PN27-003 | C9: =IF(B9="","",IFERROR(INDEX(Catalogos!$R$5:$R$51,MATCH(B9,L_AREAS,0)),"")) | D9: =IF(B9="","",IFERROR(INDEX(Catalogos!$O$5:$O$51,MATCH(B9,L_AREAS,0)),"")) | F9: =IF(E9="","",IFERROR(INDEX(Catalogos!$C$5:$C$49,MATCH(E9,L_METAS,0)),"")) | G9: =IF(E9="","",IFERROR(INDEX(Catalogos!$E$5:$E$49,MATCH(E9,L_METAS,0)),"")) | AJ9: =IF(COUNTA(B9,E9,H9,I9,J9,K9,L9,M9,N9,O9,P9,Q9,R9,S9,T9,U9,V9,W9,X9,Y9,Z9,AA9,AB9,AC9,AD9,AE9,AF9,AG9,AH9,AI9)=0,"",IF(OR(B9="",E9="",H9="",J9="",K9="",L9="",M9="",O9="",P9="",Q9="",R9="",S9="",T9="",U9="",W9="",X9="",Y9="",AB9="",AC9="",AE9="",AF9=""),"Incompleta: faltan campos obligatorios",IF(AND(LEFT(H9,6)="PROPIA",I9=""),"Falta el nombre de la acción propia del área",IF(AND(LEFT(H9,3)="A27",IFERROR(INDEX(Catalogos!$T$5:$T$207,MATCH(H9,Catalogos!$U$5:$U$207,0)),"x")<>LEFT(E9,7)),"La acción no corresponde a la meta seleccionada",IF(OR(NOT(ISNUMBER(M9)),M9<10000000,M9>99999999),"Código UNSPSC inválido: registre 8 dígitos",IF(MOD(M9,10000)=0,"UNSPSC a nivel de segmento o familia: use clase o producto",IF(IFERROR(MATCH(P9,L_MESES,0)<MATCH(O9,L_MESES,0),TRUE()),"El mes de ofertas es anterior al de inicio del proceso",IF(OR(NOT(ISNUMBER(Q9)),Q9<=0),"Duración inválida",IF(OR(NOT(ISNUMBER(W9)),NOT(ISNUMBER(X9))),"Valor inválido: registre solo números",IF(OR(W9<=0,X9<=0),"Valor inválido: debe ser mayor que cero",IF(X9>W9,"El valor de la vigencia 2027 supera el valor total",IF(AND(X9<W9,Y9="No"),"El valor total supera el de 2027: requiere vigencias futuras",IF(AND(Y9="Sí",OR(Z9="",Z9="No aplica")),"Indique el estado de la solicitud de vigencias futuras",IF(IF(AND(S9="Mínima cuantía",ISNUMBER(P_TOPE_MINIMA)),W9>P_TOPE_MINIMA,FALSE()),"El valor supera el tope de mínima cuantía 2027",IF(IF(AND(S9="Selección abreviada de menor cuantía",ISNUMBER(P_TOPE_MENOR)),W9>P_TOPE_MENOR,FALSE()),"El valor supera el tope de menor cuantía 2027",IF(OR(ISERROR(SEARCH("@itc.edu.co",AE9)),SUMPRODUCT(--ISNUMBER(SEARCH({"á","é","í","ó","ú","ñ"," "},AE9)))>0),"El correo del responsable no es institucional válido",IF(AND(AF9="Sí",AG9=""),"Indique el N.° de registro 2026 que continúa","OK"))))))))))))))))) | AK9: =IF(AJ9="OK",COUNTIF($AJ$7:AJ9,"OK"),"")
A10: ="PN27-"&TEXT(ROW()-6,"000") -> PN27-004 | C10: =IF(B10="","",IFERROR(INDEX(Catalogos!$R$5:$R$51,MATCH(B10,L_AREAS,0)),"")) | D10: =IF(B10="","",IFERROR(INDEX(Catalogos!$O$5:$O$51,MATCH(B10,L_AREAS,0)),"")) | F10: =IF(E10="","",IFERROR(INDEX(Catalogos!$C$5:$C$49,MATCH(E10,L_METAS,0)),"")) | G10: =IF(E10="","",IFERROR(INDEX(Catalogos!$E$5:$E$49,MATCH(E10,L_METAS,0)),"")) | AJ10: =IF(COUNTA(B10,E10,H10,I10,J10,K10,L10,M10,N10,O10,P10,Q10,R10,S10,T10,U10,V10,W10,X10,Y10,Z10,AA10,AB10,AC10,AD10,AE10,AF10,AG10,AH10,AI10)=0,"",IF(OR(B10="",E10="",H10="",J10="",K10="",L10="",M10="",O10="",P10="",Q10="",R10="",S10="",T10="",U10="",W10="",X10="",Y10="",AB10="",AC10="",AE10="",AF10=""),"Incompleta: faltan campos obligatorios",IF(AND(LEFT(H10,6)="PROPIA",I10=""),"Falta el nombre de la acción propia del área",IF(AND(LEFT(H10,3)="A27",IFERROR(INDEX(Catalogos!$T$5:$T$207,MATCH(H10,Catalogos!$U$5:$U$207,0)),"x")<>LEFT(E10,7)),"La acción no corresponde a la meta seleccionada",IF(OR(NOT(ISNUMBER(M10)),M10<10000000,M10>99999999),"Código UNSPSC inválido: registre 8 dígitos",IF(MOD(M10,10000)=0,"UNSPSC a nivel de segmento o familia: use clase o producto",IF(IFERROR(MATCH(P10,L_MESES,0)<MATCH(O10,L_MESES,0),TRUE()),"El mes de ofertas es anterior al de inicio del proceso",IF(OR(NOT(ISNUMBER(Q10)),Q10<=0),"Duración inválida",IF(OR(NOT(ISNUMBER(W10)),NOT(ISNUMBER(X10))),"Valor inválido: registre solo números",IF(OR(W10<=0,X10<=0),"Valor inválido: debe ser mayor que cero",IF(X10>W10,"El valor de la vigencia 2027 supera el valor total",IF(AND(X10<W10,Y10="No"),"El valor total supera el de 2027: requiere vigencias futuras",IF(AND(Y10="Sí",OR(Z10="",Z10="No aplica")),"Indique el estado de la solicitud de vigencias futuras",IF(IF(AND(S10="Mínima cuantía",ISNUMBER(P_TOPE_MINIMA)),W10>P_TOPE_MINIMA,FALSE()),"El valor supera el tope de mínima cuantía 2027",IF(IF(AND(S10="Selección abreviada de menor cuantía",ISNUMBER(P_TOPE_MENOR)),W10>P_TOPE_MENOR,FALSE()),"El valor supera el tope de menor cuantía 2027",IF(OR(ISERROR(SEARCH("@itc.edu.co",AE10)),SUMPRODUCT(--ISNUMBER(SEARCH({"á","é","í","ó","ú","ñ"," "},AE10)))>0),"El correo del responsable no es institucional válido",IF(AND(AF10="Sí",AG10=""),"Indique el N.° de registro 2026 que continúa","OK"))))))))))))))))) | AK10: =IF(AJ10="OK",COUNTIF($AJ$7:AJ10,"OK"),"")
A11: ="PN27-"&TEXT(ROW()-6,"000") -> PN27-005 | C11: =IF(B11="","",IFERROR(INDEX(Catalogos!$R$5:$R$51,MATCH(B11,L_AREAS,0)),"")) | D11: =IF(B11="","",IFERROR(INDEX(Catalogos!$O$5:$O$51,MATCH(B11,L_AREAS,0)),"")) | F11: =IF(E11="","",IFERROR(INDEX(Catalogos!$C$5:$C$49,MATCH(E11,L_METAS,0)),"")) | G11: =IF(E11="","",IFERROR(INDEX(Catalogos!$E$5:$E$49,MATCH(E11,L_METAS,0)),"")) | AJ11: =IF(COUNTA(B11,E11,H11,I11,J11,K11,L11,M11,N11,O11,P11,Q11,R11,S11,T11,U11,V11,W11,X11,Y11,Z11,AA11,AB11,AC11,AD11,AE11,AF11,AG11,AH11,AI11)=0,"",IF(OR(B11="",E11="",H11="",J11="",K11="",L11="",M11="",O11="",P11="",Q11="",R11="",S11="",T11="",U11="",W11="",X11="",Y11="",AB11="",AC11="",AE11="",AF11=""),"Incompleta: faltan campos obligatorios",IF(AND(LEFT(H11,6)="PROPIA",I11=""),"Falta el nombre de la acción propia del área",IF(AND(LEFT(H11,3)="A27",IFERROR(INDEX(Catalogos!$T$5:$T$207,MATCH(H11,Catalogos!$U$5:$U$207,0)),"x")<>LEFT(E11,7)),"La acción no corresponde a la meta seleccionada",IF(OR(NOT(ISNUMBER(M11)),M11<10000000,M11>99999999),"Código UNSPSC inválido: registre 8 dígitos",IF(MOD(M11,10000)=0,"UNSPSC a nivel de segmento o familia: use clase o producto",IF(IFERROR(MATCH(P11,L_MESES,0)<MATCH(O11,L_MESES,0),TRUE()),"El mes de ofertas es anterior al de inicio del proceso",IF(OR(NOT(ISNUMBER(Q11)),Q11<=0),"Duración inválida",IF(OR(NOT(ISNUMBER(W11)),NOT(ISNUMBER(X11))),"Valor inválido: registre solo números",IF(OR(W11<=0,X11<=0),"Valor inválido: debe ser mayor que cero",IF(X11>W11,"El valor de la vigencia 2027 supera el valor total",IF(AND(X11<W11,Y11="No"),"El valor total supera el de 2027: requiere vigencias futuras",IF(AND(Y11="Sí",OR(Z11="",Z11="No aplica")),"Indique el estado de la solicitud de vigencias futuras",IF(IF(AND(S11="Mínima cuantía",ISNUMBER(P_TOPE_MINIMA)),W11>P_TOPE_MINIMA,FALSE()),"El valor supera el tope de mínima cuantía 2027",IF(IF(AND(S11="Selección abreviada de menor cuantía",ISNUMBER(P_TOPE_MENOR)),W11>P_TOPE_MENOR,FALSE()),"El valor supera el tope de menor cuantía 2027",IF(OR(ISERROR(SEARCH("@itc.edu.co",AE11)),SUMPRODUCT(--ISNUMBER(SEARCH({"á","é","í","ó","ú","ñ"," "},AE11)))>0),"El correo del responsable no es institucional válido",IF(AND(AF11="Sí",AG11=""),"Indique el N.° de registro 2026 que continúa","OK"))))))))))))))))) | AK11: =IF(AJ11="OK",COUNTIF($AJ$7:AJ11,"OK"),"")
A12: ="PN27-"&TEXT(ROW()-6,"000") -> PN27-006 | C12: =IF(B12="","",IFERROR(INDEX(Catalogos!$R$5:$R$51,MATCH(B12,L_AREAS,0)),"")) | D12: =IF(B12="","",IFERROR(INDEX(Catalogos!$O$5:$O$51,MATCH(B12,L_AREAS,0)),"")) | F12: =IF(E12="","",IFERROR(INDEX(Catalogos!$C$5:$C$49,MATCH(E12,L_METAS,0)),"")) | G12: =IF(E12="","",IFERROR(INDEX(Catalogos!$E$5:$E$49,MATCH(E12,L_METAS,0)),"")) | AJ12: =IF(COUNTA(B12,E12,H12,I12,J12,K12,L12,M12,N12,O12,P12,Q12,R12,S12,T12,U12,V12,W12,X12,Y12,Z12,AA12,AB12,AC12,AD12,AE12,AF12,AG12,AH12,AI12)=0,"",IF(OR(B12="",E12="",H12="",J12="",K12="",L12="",M12="",O12="",P12="",Q12="",R12="",S12="",T12="",U12="",W12="",X12="",Y12="",AB12="",AC12="",AE12="",AF12=""),"Incompleta: faltan campos obligatorios",IF(AND(LEFT(H12,6)="PROPIA",I12=""),"Falta el nombre de la acción propia del área",IF(AND(LEFT(H12,3)="A27",IFERROR(INDEX(Catalogos!$T$5:$T$207,MATCH(H12,Catalogos!$U$5:$U$207,0)),"x")<>LEFT(E12,7)),"La acción no corresponde a la meta seleccionada",IF(OR(NOT(ISNUMBER(M12)),M12<10000000,M12>99999999),"Código UNSPSC inválido: registre 8 dígitos",IF(MOD(M12,10000)=0,"UNSPSC a nivel de segmento o familia: use clase o producto",IF(IFERROR(MATCH(P12,L_MESES,0)<MATCH(O12,L_MESES,0),TRUE()),"El mes de ofertas es anterior al de inicio del proceso",IF(OR(NOT(ISNUMBER(Q12)),Q12<=0),"Duración inválida",IF(OR(NOT(ISNUMBER(W12)),NOT(ISNUMBER(X12))),"Valor inválido: registre solo números",IF(OR(W12<=0,X12<=0),"Valor inválido: debe ser mayor que cero",IF(X12>W12,"El valor de la vigencia 2027 supera el valor total",IF(AND(X12<W12,Y12="No"),"El valor total supera el de 2027: requiere vigencias futuras",IF(AND(Y12="Sí",OR(Z12="",Z12="No aplica")),"Indique el estado de la solicitud de vigencias futuras",IF(IF(AND(S12="Mínima cuantía",ISNUMBER(P_TOPE_MINIMA)),W12>P_TOPE_MINIMA,FALSE()),"El valor supera el tope de mínima cuantía 2027",IF(IF(AND(S12="Selección abreviada de menor cuantía",ISNUMBER(P_TOPE_MENOR)),W12>P_TOPE_MENOR,FALSE()),"El valor supera el tope de menor cuantía 2027",IF(OR(ISERROR(SEARCH("@itc.edu.co",AE12)),SUMPRODUCT(--ISNUMBER(SEARCH({"á","é","í","ó","ú","ñ"," "},AE12)))>0),"El correo del responsable no es institucional válido",IF(AND(AF12="Sí",AG12=""),"Indique el N.° de registro 2026 que continúa","OK"))))))))))))))))) | AK12: =IF(AJ12="OK",COUNTIF($AJ$7:AJ12,"OK"),"")
A13: ="PN27-"&TEXT(ROW()-6,"000") -> PN27-007 | C13: =IF(B13="","",IFERROR(INDEX(Catalogos!$R$5:$R$51,MATCH(B13,L_AREAS,0)),"")) | D13: =IF(B13="","",IFERROR(INDEX(Catalogos!$O$5:$O$51,MATCH(B13,L_AREAS,0)),"")) | F13: =IF(E13="","",IFERROR(INDEX(Catalogos!$C$5:$C$49,MATCH(E13,L_METAS,0)),"")) | G13: =IF(E13="","",IFERROR(INDEX(Catalogos!$E$5:$E$49,MATCH(E13,L_METAS,0)),"")) | AJ13: =IF(COUNTA(B13,E13,H13,I13,J13,K13,L13,M13,N13,O13,P13,Q13,R13,S13,T13,U13,V13,W13,X13,Y13,Z13,AA13,AB13,AC13,AD13,AE13,AF13,AG13,AH13,AI13)=0,"",IF(OR(B13="",E13="",H13="",J13="",K13="",L13="",M13="",O13="",P13="",Q13="",R13="",S13="",T13="",U13="",W13="",X13="",Y13="",AB13="",AC13="",AE13="",AF13=""),"Incompleta: faltan campos obligatorios",IF(AND(LEFT(H13,6)="PROPIA",I13=""),"Falta el nombre de la acción propia del área",IF(AND(LEFT(H13,3)="A27",IFERROR(INDEX(Catalogos!$T$5:$T$207,MATCH(H13,Catalogos!$U$5:$U$207,0)),"x")<>LEFT(E13,7)),"La acción no corresponde a la meta seleccionada",IF(OR(NOT(ISNUMBER(M13)),M13<10000000,M13>99999999),"Código UNSPSC inválido: registre 8 dígitos",IF(MOD(M13,10000)=0,"UNSPSC a nivel de segmento o familia: use clase o producto",IF(IFERROR(MATCH(P13,L_MESES,0)<MATCH(O13,L_MESES,0),TRUE()),"El mes de ofertas es anterior al de inicio del proceso",IF(OR(NOT(ISNUMBER(Q13)),Q13<=0),"Duración inválida",IF(OR(NOT(ISNUMBER(W13)),NOT(ISNUMBER(X13))),"Valor inválido: registre solo números",IF(OR(W13<=0,X13<=0),"Valor inválido: debe ser mayor que cero",IF(X13>W13,"El valor de la vigencia 2027 supera el valor total",IF(AND(X13<W13,Y13="No"),"El valor total supera el de 2027: requiere vigencias futuras",IF(AND(Y13="Sí",OR(Z13="",Z13="No aplica")),"Indique el estado de la solicitud de vigencias futuras",IF(IF(AND(S13="Mínima cuantía",ISNUMBER(P_TOPE_MINIMA)),W13>P_TOPE_MINIMA,FALSE()),"El valor supera el tope de mínima cuantía 2027",IF(IF(AND(S13="Selección abreviada de menor cuantía",ISNUMBER(P_TOPE_MENOR)),W13>P_TOPE_MENOR,FALSE()),"El valor supera el tope de menor cuantía 2027",IF(OR(ISERROR(SEARCH("@itc.edu.co",AE13)),SUMPRODUCT(--ISNUMBER(SEARCH({"á","é","í","ó","ú","ñ"," "},AE13)))>0),"El correo del responsable no es institucional válido",IF(AND(AF13="Sí",AG13=""),"Indique el N.° de registro 2026 que continúa","OK"))))))))))))))))) | AK13: =IF(AJ13="OK",COUNTIF($AJ$7:AJ13,"OK"),"")
A14: ="PN27-"&TEXT(ROW()-6,"000") -> PN27-008 | C14: =IF(B14="","",IFERROR(INDEX(Catalogos!$R$5:$R$51,MATCH(B14,L_AREAS,0)),"")) | D14: =IF(B14="","",IFERROR(INDEX(Catalogos!$O$5:$O$51,MATCH(B14,L_AREAS,0)),"")) | F14: =IF(E14="","",IFERROR(INDEX(Catalogos!$C$5:$C$49,MATCH(E14,L_METAS,0)),"")) | G14: =IF(E14="","",IFERROR(INDEX(Catalogos!$E$5:$E$49,MATCH(E14,L_METAS,0)),"")) | AJ14: =IF(COUNTA(B14,E14,H14,I14,J14,K14,L14,M14,N14,O14,P14,Q14,R14,S14,T14,U14,V14,W14,X14,Y14,Z14,AA14,AB14,AC14,AD14,AE14,AF14,AG14,AH14,AI14)=0,"",IF(OR(B14="",E14="",H14="",J14="",K14="",L14="",M14="",O14="",P14="",Q14="",R14="",S14="",T14="",U14="",W14="",X14="",Y14="",AB14="",AC14="",AE14="",AF14=""),"Incompleta: faltan campos obligatorios",IF(AND(LEFT(H14,6)="PROPIA",I14=""),"Falta el nombre de la acción propia del área",IF(AND(LEFT(H14,3)="A27",IFERROR(INDEX(Catalogos!$T$5:$T$207,MATCH(H14,Catalogos!$U$5:$U$207,0)),"x")<>LEFT(E14,7)),"La acción no corresponde a la meta seleccionada",IF(OR(NOT(ISNUMBER(M14)),M14<10000000,M14>99999999),"Código UNSPSC inválido: registre 8 dígitos",IF(MOD(M14,10000)=0,"UNSPSC a nivel de segmento o familia: use clase o producto",IF(IFERROR(MATCH(P14,L_MESES,0)<MATCH(O14,L_MESES,0),TRUE()),"El mes de ofertas es anterior al de inicio del proceso",IF(OR(NOT(ISNUMBER(Q14)),Q14<=0),"Duración inválida",IF(OR(NOT(ISNUMBER(W14)),NOT(ISNUMBER(X14))),"Valor inválido: registre solo números",IF(OR(W14<=0,X14<=0),"Valor inválido: debe ser mayor que cero",IF(X14>W14,"El valor de la vigencia 2027 supera el valor total",IF(AND(X14<W14,Y14="No"),"El valor total supera el de 2027: requiere vigencias futuras",IF(AND(Y14="Sí",OR(Z14="",Z14="No aplica")),"Indique el estado de la solicitud de vigencias futuras",IF(IF(AND(S14="Mínima cuantía",ISNUMBER(P_TOPE_MINIMA)),W14>P_TOPE_MINIMA,FALSE()),"El valor supera el tope de mínima cuantía 2027",IF(IF(AND(S14="Selección abreviada de menor cuantía",ISNUMBER(P_TOPE_MENOR)),W14>P_TOPE_MENOR,FALSE()),"El valor supera el tope de menor cuantía 2027",IF(OR(ISERROR(SEARCH("@itc.edu.co",AE14)),SUMPRODUCT(--ISNUMBER(SEARCH({"á","é","í","ó","ú","ñ"," "},AE14)))>0),"El correo del responsable no es institucional válido",IF(AND(AF14="Sí",AG14=""),"Indique el N.° de registro 2026 que continúa","OK"))))))))))))))))) | AK14: =IF(AJ14="OK",COUNTIF($AJ$7:AJ14,"OK"),"")
A15: ="PN27-"&TEXT(ROW()-6,"000") -> PN27-009 | C15: =IF(B15="","",IFERROR(INDEX(Catalogos!$R$5:$R$51,MATCH(B15,L_AREAS,0)),"")) | D15: =IF(B15="","",IFERROR(INDEX(Catalogos!$O$5:$O$51,MATCH(B15,L_AREAS,0)),"")) | F15: =IF(E15="","",IFERROR(INDEX(Catalogos!$C$5:$C$49,MATCH(E15,L_METAS,0)),"")) | G15: =IF(E15="","",IFERROR(INDEX(Catalogos!$E$5:$E$49,MATCH(E15,L_METAS,0)),"")) | AJ15: =IF(COUNTA(B15,E15,H15,I15,J15,K15,L15,M15,N15,O15,P15,Q15,R15,S15,T15,U15,V15,W15,X15,Y15,Z15,AA15,AB15,AC15,AD15,AE15,AF15,AG15,AH15,AI15)=0,"",IF(OR(B15="",E15="",H15="",J15="",K15="",L15="",M15="",O15="",P15="",Q15="",R15="",S15="",T15="",U15="",W15="",X15="",Y15="",AB15="",AC15="",AE15="",AF15=""),"Incompleta: faltan campos obligatorios",IF(AND(LEFT(H15,6)="PROPIA",I15=""),"Falta el nombre de la acción propia del área",IF(AND(LEFT(H15,3)="A27",IFERROR(INDEX(Catalogos!$T$5:$T$207,MATCH(H15,Catalogos!$U$5:$U$207,0)),"x")<>LEFT(E15,7)),"La acción no corresponde a la meta seleccionada",IF(OR(NOT(ISNUMBER(M15)),M15<10000000,M15>99999999),"Código UNSPSC inválido: registre 8 dígitos",IF(MOD(M15,10000)=0,"UNSPSC a nivel de segmento o familia: use clase o producto",IF(IFERROR(MATCH(P15,L_MESES,0)<MATCH(O15,L_MESES,0),TRUE()),"El mes de ofertas es anterior al de inicio del proceso",IF(OR(NOT(ISNUMBER(Q15)),Q15<=0),"Duración inválida",IF(OR(NOT(ISNUMBER(W15)),NOT(ISNUMBER(X15))),"Valor inválido: registre solo números",IF(OR(W15<=0,X15<=0),"Valor inválido: debe ser mayor que cero",IF(X15>W15,"El valor de la vigencia 2027 supera el valor total",IF(AND(X15<W15,Y15="No"),"El valor total supera el de 2027: requiere vigencias futuras",IF(AND(Y15="Sí",OR(Z15="",Z15="No aplica")),"Indique el estado de la solicitud de vigencias futuras",IF(IF(AND(S15="Mínima cuantía",ISNUMBER(P_TOPE_MINIMA)),W15>P_TOPE_MINIMA,FALSE()),"El valor supera el tope de mínima cuantía 2027",IF(IF(AND(S15="Selección abreviada de menor cuantía",ISNUMBER(P_TOPE_MENOR)),W15>P_TOPE_MENOR,FALSE()),"El valor supera el tope de menor cuantía 2027",IF(OR(ISERROR(SEARCH("@itc.edu.co",AE15)),SUMPRODUCT(--ISNUMBER(SEARCH({"á","é","í","ó","ú","ñ"," "},AE15)))>0),"El correo del responsable no es institucional válido",IF(AND(AF15="Sí",AG15=""),"Indique el N.° de registro 2026 que continúa","OK"))))))))))))))))) | AK15: =IF(AJ15="OK",COUNTIF($AJ$7:AJ15,"OK"),"")
A16: ="PN27-"&TEXT(ROW()-6,"000") -> PN27-010 | C16: =IF(B16="","",IFERROR(INDEX(Catalogos!$R$5:$R$51,MATCH(B16,L_AREAS,0)),"")) | D16: =IF(B16="","",IFERROR(INDEX(Catalogos!$O$5:$O$51,MATCH(B16,L_AREAS,0)),"")) | F16: =IF(E16="","",IFERROR(INDEX(Catalogos!$C$5:$C$49,MATCH(E16,L_METAS,0)),"")) | G16: =IF(E16="","",IFERROR(INDEX(Catalogos!$E$5:$E$49,MATCH(E16,L_METAS,0)),"")) | AJ16: =IF(COUNTA(B16,E16,H16,I16,J16,K16,L16,M16,N16,O16,P16,Q16,R16,S16,T16,U16,V16,W16,X16,Y16,Z16,AA16,AB16,AC16,AD16,AE16,AF16,AG16,AH16,AI16)=0,"",IF(OR(B16="",E16="",H16="",J16="",K16="",L16="",M16="",O16="",P16="",Q16="",R16="",S16="",T16="",U16="",W16="",X16="",Y16="",AB16="",AC16="",AE16="",AF16=""),"Incompleta: faltan campos obligatorios",IF(AND(LEFT(H16,6)="PROPIA",I16=""),"Falta el nombre de la acción propia del área",IF(AND(LEFT(H16,3)="A27",IFERROR(INDEX(Catalogos!$T$5:$T$207,MATCH(H16,Catalogos!$U$5:$U$207,0)),"x")<>LEFT(E16,7)),"La acción no corresponde a la meta seleccionada",IF(OR(NOT(ISNUMBER(M16)),M16<10000000,M16>99999999),"Código UNSPSC inválido: registre 8 dígitos",IF(MOD(M16,10000)=0,"UNSPSC a nivel de segmento o familia: use clase o producto",IF(IFERROR(MATCH(P16,L_MESES,0)<MATCH(O16,L_MESES,0),TRUE()),"El mes de ofertas es anterior al de inicio del proceso",IF(OR(NOT(ISNUMBER(Q16)),Q16<=0),"Duración inválida",IF(OR(NOT(ISNUMBER(W16)),NOT(ISNUMBER(X16))),"Valor inválido: registre solo números",IF(OR(W16<=0,X16<=0),"Valor inválido: debe ser mayor que cero",IF(X16>W16,"El valor de la vigencia 2027 supera el valor total",IF(AND(X16<W16,Y16="No"),"El valor total supera el de 2027: requiere vigencias futuras",IF(AND(Y16="Sí",OR(Z16="",Z16="No aplica")),"Indique el estado de la solicitud de vigencias futuras",IF(IF(AND(S16="Mínima cuantía",ISNUMBER(P_TOPE_MINIMA)),W16>P_TOPE_MINIMA,FALSE()),"El valor supera el tope de mínima cuantía 2027",IF(IF(AND(S16="Selección abreviada de menor cuantía",ISNUMBER(P_TOPE_MENOR)),W16>P_TOPE_MENOR,FALSE()),"El valor supera el tope de menor cuantía 2027",IF(OR(ISERROR(SEARCH("@itc.edu.co",AE16)),SUMPRODUCT(--ISNUMBER(SEARCH({"á","é","í","ó","ú","ñ"," "},AE16)))>0),"El correo del responsable no es institucional válido",IF(AND(AF16="Sí",AG16=""),"Indique el N.° de registro 2026 que continúa","OK"))))))))))))))))) | AK16: =IF(AJ16="OK",COUNTIF($AJ$7:AJ16,"OK"),"")
A17: ="PN27-"&TEXT(ROW()-6,"000") -> PN27-011 | C17: =IF(B17="","",IFERROR(INDEX(Catalogos!$R$5:$R$51,MATCH(B17,L_AREAS,0)),"")) | D17: =IF(B17="","",IFERROR(INDEX(Catalogos!$O$5:$O$51,MATCH(B17,L_AREAS,0)),"")) | F17: =IF(E17="","",IFERROR(INDEX(Catalogos!$C$5:$C$49,MATCH(E17,L_METAS,0)),"")) | G17: =IF(E17="","",IFERROR(INDEX(Catalogos!$E$5:$E$49,MATCH(E17,L_METAS,0)),"")) | AJ17: =IF(COUNTA(B17,E17,H17,I17,J17,K17,L17,M17,N17,O17,P17,Q17,R17,S17,T17,U17,V17,W17,X17,Y17,Z17,AA17,AB17,AC17,AD17,AE17,AF17,AG17,AH17,AI17)=0,"",IF(OR(B17="",E17="",H17="",J17="",K17="",L17="",M17="",O17="",P17="",Q17="",R17="",S17="",T17="",U17="",W17="",X17="",Y17="",AB17="",AC17="",AE17="",AF17=""),"Incompleta: faltan campos obligatorios",IF(AND(LEFT(H17,6)="PROPIA",I17=""),"Falta el nombre de la acción propia del área",IF(AND(LEFT(H17,3)="A27",IFERROR(INDEX(Catalogos!$T$5:$T$207,MATCH(H17,Catalogos!$U$5:$U$207,0)),"x")<>LEFT(E17,7)),"La acción no corresponde a la meta seleccionada",IF(OR(NOT(ISNUMBER(M17)),M17<10000000,M17>99999999),"Código UNSPSC inválido: registre 8 dígitos",IF(MOD(M17,10000)=0,"UNSPSC a nivel de segmento o familia: use clase o producto",IF(IFERROR(MATCH(P17,L_MESES,0)<MATCH(O17,L_MESES,0),TRUE()),"El mes de ofertas es anterior al de inicio del proceso",IF(OR(NOT(ISNUMBER(Q17)),Q17<=0),"Duración inválida",IF(OR(NOT(ISNUMBER(W17)),NOT(ISNUMBER(X17))),"Valor inválido: registre solo números",IF(OR(W17<=0,X17<=0),"Valor inválido: debe ser mayor que cero",IF(X17>W17,"El valor de la vigencia 2027 supera el valor total",IF(AND(X17<W17,Y17="No"),"El valor total supera el de 2027: requiere vigencias futuras",IF(AND(Y17="Sí",OR(Z17="",Z17="No aplica")),"Indique el estado de la solicitud de vigencias futuras",IF(IF(AND(S17="Mínima cuantía",ISNUMBER(P_TOPE_MINIMA)),W17>P_TOPE_MINIMA,FALSE()),"El valor supera el tope de mínima cuantía 2027",IF(IF(AND(S17="Selección abreviada de menor cuantía",ISNUMBER(P_TOPE_MENOR)),W17>P_TOPE_MENOR,FALSE()),"El valor supera el tope de menor cuantía 2027",IF(OR(ISERROR(SEARCH("@itc.edu.co",AE17)),SUMPRODUCT(--ISNUMBER(SEARCH({"á","é","í","ó","ú","ñ"," "},AE17)))>0),"El correo del responsable no es institucional válido",IF(AND(AF17="Sí",AG17=""),"Indique el N.° de registro 2026 que continúa","OK"))))))))))))))))) | AK17: =IF(AJ17="OK",COUNTIF($AJ$7:AJ17,"OK"),"")
A18: ="PN27-"&TEXT(ROW()-6,"000") -> PN27-012 | C18: =IF(B18="","",IFERROR(INDEX(Catalogos!$R$5:$R$51,MATCH(B18,L_AREAS,0)),"")) | D18: =IF(B18="","",IFERROR(INDEX(Catalogos!$O$5:$O$51,MATCH(B18,L_AREAS,0)),"")) | F18: =IF(E18="","",IFERROR(INDEX(Catalogos!$C$5:$C$49,MATCH(E18,L_METAS,0)),"")) | G18: =IF(E18="","",IFERROR(INDEX(Catalogos!$E$5:$E$49,MATCH(E18,L_METAS,0)),"")) | AJ18: =IF(COUNTA(B18,E18,H18,I18,J18,K18,L18,M18,N18,O18,P18,Q18,R18,S18,T18,U18,V18,W18,X18,Y18,Z18,AA18,AB18,AC18,AD18,AE18,AF18,AG18,AH18,AI18)=0,"",IF(OR(B18="",E18="",H18="",J18="",K18="",L18="",M18="",O18="",P18="",Q18="",R18="",S18="",T18="",U18="",W18="",X18="",Y18="",AB18="",AC18="",AE18="",AF18=""),"Incompleta: faltan campos obligatorios",IF(AND(LEFT(H18,6)="PROPIA",I18=""),"Falta el nombre de la acción propia del área",IF(AND(LEFT(H18,3)="A27",IFERROR(INDEX(Catalogos!$T$5:$T$207,MATCH(H18,Catalogos!$U$5:$U$207,0)),"x")<>LEFT(E18,7)),"La acción no corresponde a la meta seleccionada",IF(OR(NOT(ISNUMBER(M18)),M18<10000000,M18>99999999),"Código UNSPSC inválido: registre 8 dígitos",IF(MOD(M18,10000)=0,"UNSPSC a nivel de segmento o familia: use clase o producto",IF(IFERROR(MATCH(P18,L_MESES,0)<MATCH(O18,L_MESES,0),TRUE()),"El mes de ofertas es anterior al de inicio del proceso",IF(OR(NOT(ISNUMBER(Q18)),Q18<=0),"Duración inválida",IF(OR(NOT(ISNUMBER(W18)),NOT(ISNUMBER(X18))),"Valor inválido: registre solo números",IF(OR(W18<=0,X18<=0),"Valor inválido: debe ser mayor que cero",IF(X18>W18,"El valor de la vigencia 2027 supera el valor total",IF(AND(X18<W18,Y18="No"),"El valor total supera el de 2027: requiere vigencias futuras",IF(AND(Y18="Sí",OR(Z18="",Z18="No aplica")),"Indique el estado de la solicitud de vigencias futuras",IF(IF(AND(S18="Mínima cuantía",ISNUMBER(P_TOPE_MINIMA)),W18>P_TOPE_MINIMA,FALSE()),"El valor supera el tope de mínima cuantía 2027",IF(IF(AND(S18="Selección abreviada de menor cuantía",ISNUMBER(P_TOPE_MENOR)),W18>P_TOPE_MENOR,FALSE()),"El valor supera el tope de menor cuantía 2027",IF(OR(ISERROR(SEARCH("@itc.edu.co",AE18)),SUMPRODUCT(--ISNUMBER(SEARCH({"á","é","í","ó","ú","ñ"," "},AE18)))>0),"El correo del responsable no es institucional válido",IF(AND(AF18="Sí",AG18=""),"Indique el N.° de registro 2026 que continúa","OK"))))))))))))))))) | AK18: =IF(AJ18="OK",COUNTIF($AJ$7:AJ18,"OK"),"")
... A506: ="PN27-"&TEXT(ROW()-6,"000") -> PN27-500 | C506: =IF(B506="","",IFERROR(INDEX(Catalogos!$R$5:$R$51,MATCH(B506,L_AREAS,0)),"")) | D506: =IF(B506="","",IFERROR(INDEX(Catalogos!$O$5:$O$51,MATCH(B506,L_AREAS,0)),"")) | F506: =IF(E506="","",IFERROR(INDEX(Catalogos!$C$5:$C$49,MATCH(E506,L_METAS,0)),"")) | G506: =IF(E506="","",IFERROR(INDEX(Catalogos!$E$5:$E$49,MATCH(E506,L_METAS,0)),"")) | AJ506: =IF(COUNTA(B506,E506,H506,I506,J506,K506,L506,M506,N506,O506,P506,Q506,R506,S506,T506,U506,V506,W506,X506,Y506,Z506,AA506,AB506,AC506,AD506,AE506,AF506,AG506,AH506,AI506)=0,"",IF(OR(B506="",E506="",H506="",J506="",K506="",L506="",M506="",O506="",P506="",Q506="",R506="",S506="",T506="",U506="",W506="",X506="",Y506="",AB506="",AC506="",AE506="",AF506=""),"Incompleta: faltan campos obligatorios",IF(AND(LEFT(H506,6)="PROPIA",I506=""),"Falta el nombre de la acción propia del área",IF(AND(LEFT(H506,3)="A27",IFERROR(INDEX(Catalogos!$T$5:$T$207,MATCH(H506,Catalogos!$U$5:$U$207,0)),"x")<>LEFT(E506,7)),"La acción no corresponde a la meta seleccionada",IF(OR(NOT(ISNUMBER(M506)),M506<10000000,M506>99999999),"Código UNSPSC inválido: registre 8 dígitos",IF(MOD(M506,10000)=0,"UNSPSC a nivel de segmento o familia: use clase o producto",IF(IFERROR(MATCH(P506,L_MESES,0)<MATCH(O506,L_MESES,0),TRUE()),"El mes de ofertas es anterior al de inicio del proceso",IF(OR(NOT(ISNUMBER(Q506)),Q506<=0),"Duración inválida",IF(OR(NOT(ISNUMBER(W506)),NOT(ISNUMBER(X506))),"Valor inválido: registre solo números",IF(OR(W506<=0,X506<=0),"Valor inválido: debe ser mayor que cero",IF(X506>W506,"El valor de la vigencia 2027 supera el valor total",IF(AND(X506<W506,Y506="No"),"El valor total supera el de 2027: requiere vigencias futuras",IF(AND(Y506="Sí",OR(Z506="",Z506="No aplica")),"Indique el estado de la solicitud de vigencias futuras",IF(IF(AND(S506="Mínima cuantía",ISNUMBER(P_TOPE_MINIMA)),W506>P_TOPE_MINIMA,FALSE()),"El valor supera el tope de mínima cuantía 2027",IF(IF(AND(S506="Selección abreviada de menor cuantía",ISNUMBER(P_TOPE_MENOR)),W506>P_TOPE_MENOR,FALSE()),"El valor supera el tope de menor cuantía 2027",IF(OR(ISERROR(SEARCH("@itc.edu.co",AE506)),SUMPRODUCT(--ISNUMBER(SEARCH({"á","é","í","ó","ú","ñ"," "},AE506)))>0),"El correo del responsable no es institucional válido",IF(AND(AF506="Sí",AG506=""),"Indique el N.° de registro 2026 que continúa","OK"))))))))))))))))) | AK506: =IF(AJ506="OK",COUNTIF($AJ$7:AJ506,"OK"),"")

Sheet 2026
A1: Plan de Necesidades 2026 — registro histórico (solo consulta)
A2: Fuente: archivo "Plan_de_necesidades_PROTEGIDO_Modificado_2.xlsx", hoja "Plan de necesidades fin" (424 registros), que contiene íntegramente la versión "Plan_de_necesidades_PROTEGIDO.xlsx". Hoja protegida por la OAPDI: no se puede editar ni borrar; sí filtrar.
A3: Columnas B a K: información original de la formulación 2026, sin modificar. Columnas L a O (verde): anotaciones de la OAPDI para la consolidación 2027; las inferidas deben validarse.
A4: N.° registro 2026 | B4: CÓDIGO UNSPSC | C4: ENCARGADO | D4: DESCRIPCIÓN (OBJETO CONTRACTUAL) | E4: DURACIÓN DEL CONTRATO (NUMERO MESES) | F4: MODALIDAD DE SELECCIÓN EJEMPLO: -DIRECTA -MINIMA CUANTIA -MENOR CUANTIA | G4: VALOR TOTAL ESTIMADO, EN PESOS COLOMBIANOS | H4: NOMBRE DEL CARGO RESPONSABLE (SUPERVISOR DEL CONTRATO) | I4: TELÉFONO DEL RESPONSABLE | J4: CORREO ELECTRÓNICO DEL RESPONSABLE (SUPERVISOR DEL CONTRATO) | K4: ID | L4: Dependencia (Decreto 902) inferida por el correo o, en su defecto, por el campo ENCARGADO — validar | M4: Valor numérico normalizado por la OAPDI ($) | N4: Modalidad normalizada por la OAPDI | O4: Alerta de calidad del dato (OAPDI)
A5: PN26-001 | B5: 84131602 | C5: Talento humano - Seguridad y salud en el trabajo | D5: Prestar el servicio de área protegida para la atención prehospitalaria, atención médica de urgencias y emergencias, y el traslado asistencial de pacientes que lo requieran, dirigido a funcionarios, contratistas, estudiantes y visitantes, en las diferentes sedes de la Escuela Tecnológica Instituto Técnico Central – ETITC | E5: 11 | F5: MINIMA CUANTIA | G5: 25800 | H5: profesional universitario 2044-11 | J5: seguridadysalud@itc.edu.co | K5: 1 | L5: 133 · GIT Gestión de Talento Humano | M5: 25800 | N5: Mínima cuantía | O5: =IF(LEN(IF(OR(NOT(ISNUMBER(B5)),LEN(B5)<>8),"UNSPSC vacío, en texto, con varios códigos o sin 8 dígitos; ","")&IF(AND(ISNUMBER(B5),LEN(B5)=8),IF(MOD(B5,10000)=0,"UNSPSC a nivel de segmento o familia; ",""),"")&IF(NOT(ISNUMBER(E5)),"Duración vacía o en texto; ","")&IF(NOT(ISNUMBER(G5)),"Valor vacío o en texto; ","")&IF(ISNUMBER(M5),IF(M5<1000000,"Valor inferior a $1.000.000: verificar; ",""),"Valor no interpretable; ")&IF(N5="[PENDIENTE DE VERIFICAR]","Modalidad no identificable; ","")&IF(OR(ISERROR(SEARCH("@itc.edu.co",J5)),SUMPRODUCT(--ISNUMBER(SEARCH({"á","é","í","ó","ú","ñ"},J5)))>0),"Correo vacío o no institucional válido; ","")&IF(LEN(TRIM(D5))=0,"Sin objeto contractual; ","")&IF(AND(ISNUMBER(M5),N5="Mínima cuantía"),IF(M5>39850000,"Mínima cuantía con valor superior al tope citado en el instructivo 2026 ($39.850.000): verificar modalidad; ",""),"")&IF(AND(ISNUMBER(M5),OR(ISNUMBER(SEARCH("prestación de servicios",D5)),ISNUMBER(SEARCH("prestar servicios",D5)),ISNUMBER(SEARCH("prestar los servicios",D5)))),IF(M5>=500000000,"Prestación de servicios por $500 millones o más: posible error de digitación; ",""),""))=0,"Sin observaciones",IF(OR(NOT(ISNUMBER(B5)),LEN(B5)<>8),"UNSPSC vacío, en texto, con varios códigos o sin 8 dígitos; ","")&IF(AND(ISNUMBER(B5),LEN(B5)=8),IF(MOD(B5,10000)=0,"UNSPSC a nivel de segmento o familia; ",""),"")&IF(NOT(ISNUMBER(E5)),"Duración vacía o en texto; ","")&IF(NOT(ISNUMBER(G5)),"Valor vacío o en texto; ","")&IF(ISNUMBER(M5),IF(M5<1000000,"Valor inferior a $1.000.000: verificar; ",""),"Valor no interpretable; ")&IF(N5="[PENDIENTE DE VERIFICAR]","Modalidad no identificable; ","")&IF(OR(ISERROR(SEARCH("@itc.edu.co",J5)),SUMPRODUCT(--ISNUMBER(SEARCH({"á","é","í","ó","ú","ñ"},J5)))>0),"Correo vacío o no institucional válido; ","")&IF(LEN(TRIM(D5))=0,"Sin objeto contractual; ","")&IF(AND(ISNUMBER(M5),N5="Mínima cuantía"),IF(M5>39850000,"Mínima cuantía con valor superior al tope citado en el instructivo 2026 ($39.850.000): verificar modalidad; ",""),"")&IF(AND(ISNUMBER(M5),OR(ISNUMBER(SEARCH("prestación de servicios",D5)),ISNUMBER(SEARCH("prestar servicios",D5)),ISNUMBER(SEARCH("prestar los servicios",D5)))),IF(M5>=500000000,"Prestación de servicios por $500 millones o más: posible error de digitación; ",""),"")) -> Valor inferior a $1.000.000: verificar;
A6: PN26-002 | B6: 80101505 | C6: Talento humano - Seguridad y salud en el trabajo | D6: Ejecución del Programa de Vigilancia Epidemiológica de Riesgo Psicosocial en la Escuela Tecnológica Instituto Técnico Central, que incluya la planeación, la implementación, el seguimiento y la evaluación de las medidas de intervención organizacional, grupal e individual, orientadas a la prevención, mitigación y control de los factores de riesgo psicosocial identificados en la batería del 2025, conforme a la normatividad vigente. | E6: 10 | F6: MINIMA CUANTIA | G6: 25000000 | H6: profesional universitario 2044-11 | J6: seguridadysalud@itc.edu.co | K6: 2 | L6: 133 · GIT Gestión de Talento Humano | M6: 25000000 | N6: Mínima cuantía | O6: =IF(LEN(IF(OR(NOT(ISNUMBER(B6)),LEN(B6)<>8),"UNSPSC vacío, en texto, con varios códigos o sin 8 dígitos; ","")&IF(AND(ISNUMBER(B6),LEN(B6)=8),IF(MOD(B6,10000)=0,"UNSPSC a nivel de segmento o familia; ",""),"")&IF(NOT(ISNUMBER(E6)),"Duración vacía o en texto; ","")&IF(NOT(ISNUMBER(G6)),"Valor vacío o en texto; ","")&IF(ISNUMBER(M6),IF(M6<1000000,"Valor inferior a $1.000.000: verificar; ",""),"Valor no interpretable; ")&IF(N6="[PENDIENTE DE VERIFICAR]","Modalidad no identificable; ","")&IF(OR(ISERROR(SEARCH("@itc.edu.co",J6)),SUMPRODUCT(--ISNUMBER(SEARCH({"á","é","í","ó","ú","ñ"},J6)))>0),"Correo vacío o no institucional válido; ","")&IF(LEN(TRIM(D6))=0,"Sin objeto contractual; ","")&IF(AND(ISNUMBER(M6),N6="Mínima cuantía"),IF(M6>39850000,"Mínima cuantía con valor superior al tope citado en el instructivo 2026 ($39.850.000): verificar modalidad; ",""),"")&IF(AND(ISNUMBER(M6),OR(ISNUMBER(SEARCH("prestación de servicios",D6)),ISNUMBER(SEARCH("prestar servicios",D6)),ISNUMBER(SEARCH("prestar los servicios",D6)))),IF(M6>=500000000,"Prestación de servicios por $500 millones o más: posible error de digitación; ",""),""))=0,"Sin observaciones",IF(OR(NOT(ISNUMBER(B6)),LEN(B6)<>8),"UNSPSC vacío, en texto, con varios códigos o sin 8 dígitos; ","")&IF(AND(ISNUMBER(B6),LEN(B6)=8),IF(MOD(B6,10000)=0,"UNSPSC a nivel de segmento o familia; ",""),"")&IF(NOT(ISNUMBER(E6)),"Duración vacía o en texto; ","")&IF(NOT(ISNUMBER(G6)),"Valor vacío o en texto; ","")&IF(ISNUMBER(M6),IF(M6<1000000,"Valor inferior a $1.000.000: verificar; ",""),"Valor no interpretable; ")&IF(N6="[PENDIENTE DE VERIFICAR]","Modalidad no identificable; ","")&IF(OR(ISERROR(SEARCH("@itc.edu.co",J6)),SUMPRODUCT(--ISNUMBER(SEARCH({"á","é","í","ó","ú","ñ"},J6)))>0),"Correo vacío o no institucional válido; ","")&IF(LEN(TRIM(D6))=0,"Sin objeto contractual; ","")&IF(AND(ISNUMBER(M6),N6="Mínima cuantía"),IF(M6>39850000,"Mínima cuantía con valor superior al tope citado en el instructivo 2026 ($39.850.000): verificar modalidad; ",""),"")&IF(AND(ISNUMBER(M6),OR(ISNUMBER(SEARCH("prestación de servicios",D6)),ISNUMBER(SEARCH("prestar servicios",D6)),ISNUMBER(SEARCH("prestar los servicios",D6)))),IF(M6>=500000000,"Prestación de servicios por $500 millones o más: posible error de digitación; ",""),"")) -> Sin observaciones
A7: PN26-003 | B7: 76122406 | C7: Talento humano - Seguridad y salud en el trabajo | D7: Adquirir elementos de protección personal y contratar la certificación de los elementos de protección para trabajo en alturas, destinados al personal de la Escuela Tecnológica Instituto Técnico Central – ETITC, de conformidad con la normatividad vigente. | E7: 7 | F7: SUBASTA | G7: 100000000 | H7: profesional universitario 2044-11 | J7: seguridadysalud@itc.edu.co | K7: 3 | L7: 133 · GIT Gestión de Talento Humano | M7: 100000000 | N7: Selección abreviada – subasta inversa | O7: =IF(LEN(IF(OR(NOT(ISNUMBER(B7)),LEN(B7)<>8),"UNSPSC vacío, en texto, con varios códigos o sin 8 dígitos; ","")&IF(AND(ISNUMBER(B7),LEN(B7)=8),IF(MOD(B7,10000)=0,"UNSPSC a nivel de segmento o familia; ",""),"")&IF(NOT(ISNUMBER(E7)),"Duración vacía o en texto; ","")&IF(NOT(ISNUMBER(G7)),"Valor vacío o en texto; ","")&IF(ISNUMBER(M7),IF(M7<1000000,"Valor inferior a $1.000.000: verificar; ",""),"Valor no interpretable; ")&IF(N7="[PENDIENTE DE VERIFICAR]","Modalidad no identificable; ","")&IF(OR(ISERROR(SEARCH("@itc.edu.co",J7)),SUMPRODUCT(--ISNUMBER(SEARCH({"á","é","í","ó","ú","ñ"},J7)))>0),"Correo vacío o no institucional válido; ","")&IF(LEN(TRIM(D7))=0,"Sin objeto contractual; ","")&IF(AND(ISNUMBER(M7),N7="Mínima cuantía"),IF(M7>39850000,"Mínima cuantía con valor superior al tope citado en el instructivo 2026 ($39.850.000): verificar modalidad; ",""),"")&IF(AND(ISNUMBER(M7),OR(ISNUMBER(SEARCH("prestación de servicios",D7)),ISNUMBER(SEARCH("prestar servicios",D7)),ISNUMBER(SEARCH("prestar los servicios",D7)))),IF(M7>=500000000,"Prestación de servicios por $500 millones o más: posible error de digitación; ",""),""))=0,"Sin observaciones",IF(OR(NOT(ISNUMBER(B7)),LEN(B7)<>8),"UNSPSC vacío, en texto, con varios códigos o sin 8 dígitos; ","")&IF(AND(ISNUMBER(B7),LEN(B7)=8),IF(MOD(B7,10000)=0,"UNSPSC a nivel de segmento o familia; ",""),"")&IF(NOT(ISNUMBER(E7)),"Duración vacía o en texto; ","")&IF(NOT(ISNUMBER(G7)),"Valor vacío o en texto; ","")&IF(ISNUMBER(M7),IF(M7<1000000,"Valor inferior a $1.000.000: verificar; ",""),"Valor no interpretable; ")&IF(N7="[PENDIENTE DE VERIFICAR]","Modalidad no identificable; ","")&IF(OR(ISERROR(SEARCH("@itc.edu.co",J7)),SUMPRODUCT(--ISNUMBER(SEARCH({"á","é","í","ó","ú","ñ"},J7)))>0),"Correo vacío o no institucional válido; ","")&IF(LEN(TRIM(D7))=0,"Sin objeto contractual; ","")&IF(AND(ISNUMBER(M7),N7="Mínima cuantía"),IF(M7>39850000,"Mínima cuantía con valor superior al tope citado en el instructivo 2026 ($39.850.000): verificar modalidad; ",""),"")&IF(AND(ISNUMBER(M7),OR(ISNUMBER(SEARCH("prestación de servicios",D7)),ISNUMBER(SEARCH("prestar servicios",D7)),ISNUMBER(SEARCH("prestar los servicios",D7)))),IF(M7>=500000000,"Prestación de servicios por $500 millones o más: posible error de digitación; ",""),"")) -> Sin observaciones
