Workbook
Name L_VALID: 'Acciones_2027'!$X$2:$X$5
Name PN_AREAS: 'Catalogos_PDN'!$Q$5:$Q$51
Name PN_ESTVF: 'Catalogos_PDN'!$AF$5:$AF$8
Name PN_FUENTE: 'Catalogos_PDN'!$AC$5:$AC$12
Name PN_GASTO: 'Catalogos_PDN'!$AD$5:$AD$6
Name PN_MESES: 'Catalogos_PDN'!$Z$5:$Z$16
Name PN_METAS: 'Catalogos_PDN'!$I$5:$I$49
Name PN_MOD: 'Catalogos_PDN'!$AB$5:$AB$11
Name PN_PRIOR: 'Catalogos_PDN'!$AH$5:$AH$7
Name PN_REG2026: 'Necesidades_2026'!$A$5:$A$428
Name PN_SINO: 'Catalogos_PDN'!$AE$5:$AE$6
Name PN_TIPO: 'Catalogos_PDN'!$AG$5:$AG$15
Name PN_UNIDAD: 'Catalogos_PDN'!$AA$5:$AA$7
Name PN_FECHA: 'Catalogos_PDN'!$AN$8
Name PN_SMMLV: 'Catalogos_PDN'!$AN$7
Name PN_TOPE_MENOR: 'Catalogos_PDN'!$AN$5
Name PN_TOPE_MINIMA: 'Catalogos_PDN'!$AN$6

Sheet Instructivo_PlanAcción
A1: Plantilla Plan de Acción 2027, instructivo unificado
A2: Escuela Tecnológica Instituto Técnico Central, Oficina Asesora de Planeación. Libro único de consulta y formulación del Plan de Acción y del Plan de Necesidades 2027. Las celdas amarillas son las únicas que se diligencian; el resto del libro está protegido.
A4: 1. Para qué sirve este libro
A5: Este libro reúne en un solo archivo todo lo que una dependencia o un área funcional necesita para formular su aporte a la vigencia 2027. Aquí encuentra la propuesta del Plan de Acción que preparó la Oficina Asesora de Planeación, las acciones y actividades sugeridas para cada meta del Plan de Desarrollo Institucional (PDI) 2025 a 2032, el espacio para formular sus propias acciones, la hoja de importación que luego se carga en el SUIE y el formato del Plan de Necesidades.
A6: El libro se descarga desde el aplicativo de la Jornada de Planeación. Una vez diligenciado, el área carga su formulación en el SUIE, porque ese cargue es el insumo con el que cada área trabajará durante la jornada del 18, 19 y 20 de noviembre de 2026. Sin ese insumo el área no podrá avanzar en los talleres.
A8: 2. La ruta en cinco pasos
A9: Paso | B9: Qué hace el área | D9: Dónde
A10: 1 | B10: Ubica su área y revisa las metas que le corresponden, lo que se espera de ella en 2027 y sus compromisos pendientes de 2026. | D10: Buscador_Formulación PAA 2027
A11: 2 | B11: Lee cada meta en el Plan de Acción propuesto: qué cambia frente a 2026, las acciones sugeridas, las actividades que las componen y cómo se genera el impacto. | D11: Plan_Acción_2027 y Acciones_2027
A12: 3 | B12: Formula sus acciones, una por fila, en las columnas amarillas de la meta que le fue asignada. | D12: Formulación_Ejes_2027
A13: 4 | B13: Copia cada acción formulada en la hoja de importación, que es la que se carga en el SUIE. | D13: Importación_FormulaciónPAA2027
A14: 5 | B14: Registra los bienes, obras y servicios que cada acción requiere contratar. | D14: PlandeNecesidades
A16: Ir al Buscador para empezar
A18: 3. Cómo está organizado el Plan de Acción
A19: El PDI 2025 a 2032 se organiza en seis ejes estratégicos, veinticuatro líneas de acción y cuarenta y cinco metas estratégicas con horizonte 2032. Cada meta tiene un código de cuatro niveles que se lee de izquierda a derecha: eje, línea, objetivo estratégico y meta. Así, la meta 1.1.1.1 es la primera meta del primer objetivo de la línea 1.1 (Ampliación de cobertura) del eje 1 (Formación y pedagogía de calidad).
A20: El Plan de Acción es la forma como la Escuela convierte el PDI en trabajo de un año. Para cada meta se fija una meta institucional 2027, se definen las acciones que la harán posible y se nombran las áreas responsables. En 2027 la estructura conserva los seis ejes del PDI y se organiza así:
A21: Eje estratégico | B21: Metas | C21: Acciones propuestas | D21: Actividades propuestas
A22: 1. Formación y pedagogía de calidad | B22: 8 | C22: 13 | D22: 32
A23: 2. Investigación y producción técnico científica | B23: 7 | C23: 8 | D23: 18
A24: 3. Extensión y proyección institucional | B24: 8 | C24: 9 | D24: 25
A25: 4. Transformación institucional | B25: 12 | C25: 16 | D25: 38
A26: 5. Ampliación y modernización de la infraestructura | B26: 6 | C26: 8 | D26: 21
A27: 6. Cuidado por el bienestar y la vida | B27: 4 | C27: 8 | D27: 24
A28: Total | B28: 45 | C28: 62 | D28: 158
A31: 4. Qué cambió de 2026 a 2027
A32: La propuesta 2027 revisó una por una las metas del aplicativo 2026 contra el texto del PDI, la Matriz Plurianual de Inversiones y los informes de gestión. El resultado de esa revisión se resume en la columna «Ajuste 2027» de la hoja Plan_Acción_2027, con la explicación en la columna «Qué cambia frente a 2026».
A33: Tipo de ajuste | B33: Metas | D33: Qué significa
A34: Se mantiene | B34: 19 | D34: El enunciado y el sentido de la meta no cambian; puede ajustarse su indicador o su meta anual.
A35: Se corrige | B35: 15 | D35: Se corrige un error del aplicativo 2026: un código mal formado, un enunciado distinto al del PDI o una meta duplicada.
A36: Se reincorpora | B36: 6 | D36: La meta existe en el PDI pero no estaba en el aplicativo 2026 o no tuvo productos; vuelve al plan.
A37: Se reformula | B37: 3 | D37: La meta se cumplió como hito y en 2027 pasa a mantener o consolidar lo logrado.
A38: Se reorienta | B38: 2 | D38: La meta se cumple por un camino distinto al previsto, sin cambiar el texto del PDI hasta su revisión.
A40: Además de esos ajustes, la versión 2027 introduce tres cambios de fondo. Primero, las 158 tareas que antes se presentaban como acciones se agruparon en 62 acciones, cada una con varias actividades que la componen, porque una acción es un resultado que se logra con un conjunto de actividades y no una tarea suelta. Segundo, cada meta explica de forma explícita cómo se genera su impacto, siguiendo la Guía Metodológica para la Evaluación de Impacto Institucional. Tercero, se reincorporaron líneas que en 2026 no tuvieron productos, como la 5.3 de sedes de terceros y la 6.1 de condiciones para el bienestar, esta última con los componentes de cultura ambiental y gestión energética que decidió el Comité Institucional de Gestión y Desempeño.
A42: 5. Acción, actividad y producto: la diferencia que más importa
A43: La confusión más frecuente en la formulación es presentar una tarea como si fuera una acción. La regla es sencilla: la acción dice qué resultado va a lograr el área; las actividades dicen cómo lo va a lograr; los productos son la evidencia que queda de cada actividad.
A44: Concepto | B44: Qué es | C44: Cómo se redacta | D44: Ejemplo
A45: Acción | B45: Un resultado de mediano alcance que aporta directamente a la meta del PDI y que se logra con varias actividades a lo largo del año. | C45: Verbo en infinitivo, objeto y propósito. Debe poder responder a la pregunta: ¿qué cambia en la Escuela cuando esto se cumple? | D45: Mejorar los resultados de las pruebas Saber PRO y TyT a partir del análisis por programa y competencia, con estrategias de preparación cuyo efecto se evalúa.
A46: Actividad | B46: Cada uno de los pasos que, sumados, producen la acción. Por sí sola no transforma nada. | C46: Verbo en infinitivo y objeto concreto, con un producto verificable. | D46: Aplicar simulacros de las pruebas Saber PRO en los programas tecnológicos.
A47: Producto | B47: El bien o servicio que queda como evidencia de la actividad. | C47: Sustantivo verificable. | D47: Plan de preparación y simulacros aplicados.
A48: Tarea operativa | B48: Algo que el área hace de manera rutinaria. No se formula como acción. | C48: No se formula. | D48: Enviar correos, asistir a reuniones, elaborar un acta.
...

Sheet Instructivo_PlanNecesidades
A1: Instructivo de formulación del Plan de Necesidades 2027
A2: Escuela Tecnológica Instituto Técnico Central, Oficina Asesora de Planeación. Complemento del Plan de Acción 2027: aquí el área dice qué necesita contratar para cumplir las acciones que formuló.
A3: Ir a la hoja PlandeNecesidades para formular
A5: 1. Propósito
A6: Con este formato cada dependencia y área funcional registra los bienes, obras y servicios que necesita contratar en 2027 para ejecutar las acciones de su Plan de Acción. En el Plan de Acción el área dice qué va a hacer; en el Plan de Necesidades dice qué necesita adquirir para hacerlo. Cada necesidad se vincula a una acción del Plan de Acción 2027 y, por medio de ella, a una meta del PDI, de modo que ningún recurso se programe sin una meta que lo justifique. La Oficina Asesora de Planeación consolida las necesidades y las entrega como insumo del Plan Anual de Adquisiciones que la Escuela publica en SECOP II.
A7: Para no confundir siglas, en este libro PAA significa Plan de Acción Anual. El Plan Anual de Adquisiciones se escribe siempre completo.
A9: 2. Marco normativo
A10: Ley 80 de 1993 y Ley 1150 de 2007, que regulan la contratación pública y sus modalidades de selección. Ley 1474 de 2011, artículo 74, que obliga a publicar a más tardar el 31 de enero de cada año el plan de acción, el presupuesto y el plan general de compras. Decreto 1082 de 2015, artículos 2.2.1.1.1.4.1 a 2.2.1.1.1.4.4, que establece que el Plan Anual de Adquisiciones lista los bienes, obras y servicios identificados con el Clasificador de Bienes y Servicios de las Naciones Unidas (UNSPSC), con su valor estimado, fuente de recursos, modalidad de selección y fecha aproximada de inicio, y que se publica en la página web y en SECOP. Decreto 111 de 1996, según el cual ninguna necesidad se contrata sin certificado de disponibilidad presupuestal.
A12: 3. Lo que dice Colombia Compra Eficiente
A13: Colombia Compra Eficiente es la agencia nacional que define las reglas y herramientas de la compra pública. Su guía para elaborar el Plan Anual de Adquisiciones y su guía de codificación de bienes y servicios coinciden en cuatro mensajes para las entidades. Primero, el Plan Anual de Adquisiciones es un instrumento de planeación que permite a la entidad identificar, registrar, programar y divulgar sus necesidades, y a los proveedores conocer con anticipación lo que la entidad va a comprar. Segundo, cada necesidad debe identificarse con el código del Clasificador de Bienes y Servicios, porque ese código es el mismo que usan el SECOP, los estudios previos, los pliegos y el Registro Único de Proponentes. Tercero, el plan no obliga a la entidad a adquirir lo que registra, pero sí debe actualizarse por lo menos una vez al año y cada vez que cambien las necesidades. Cuarto, la entidad debe codificar con el mayor nivel de detalle posible, de preferencia en el nivel de producto.
A14: La versión del clasificador que Colombia Compra Eficiente tiene implementada es la UNSPSC UNv260801, traducida al español. Cuando un bien o servicio no tiene código en el clasificador, Colombia Compra Eficiente puede definir códigos adicionales a solicitud de la entidad y los publica de manera periódica. Antes de cada vigencia conviene verificar en el sitio oficial cuál es la versión vigente.
A16: 4. Qué es el código UNSPSC
A17: El UNSPSC (Código Estándar de Productos y Servicios de las Naciones Unidas) es un catálogo que asigna a cada bien o servicio un número de ocho dígitos. El número se lee por pares: los dos primeros indican el segmento, los dos siguientes la familia, los dos siguientes la clase y los dos últimos el producto. Mientras más dígitos distintos de cero tenga el código, más preciso es.
A18: Nivel | B18: Dígitos que lo identifican | C18: Ejemplo | D18: ¿Sirve para el Plan de Necesidades?
A19: Segmento | B19: Los dos primeros | C19: 80000000, servicios de gestión, servicios profesionales de empresa y servicios administrativos | D19: No: es demasiado general.
A20: Familia | B20: Los cuatro primeros | C20: 80110000, servicios de recursos humanos | D20: No: sigue siendo general.
A21: Clase | B21: Los seis primeros; termina en 00 | C21: 80111600, servicios de personal temporal | D21: Sí, cuando no existe un producto exacto.
A22: Producto | B22: Los ocho dígitos | C22: 80111601, asistencia de oficina o administrativa temporal | D22: Sí, y es el nivel preferido.
A25: 5. Paso a paso para encontrar el código en el clasificador de Colombia Compra Eficiente
A26: Abrir el clasificador de bienes y servicios de Colombia Compra Eficiente
A27: Paso | B27: Qué hacer
A28: 1 | B28: Abra el clasificador en el enlace anterior: https://operaciones.colombiacompra.gov.co/clasificador-de-bienes-y-servicios
A29: 2 | B29: Escriba en pocas palabras qué necesita, sin artículos ni adjetivos. Por ejemplo: computador portátil, servicios de aseo, mantenimiento de ascensores. Piense en el bien o servicio, no en la acción del Plan de Acción.
A30: 3 | B30: Use el buscador por palabra clave. Si conoce un código parecido, por ejemplo uno que la Escuela usó en 2026, búsquelo por código.
A31: 4 | B31: Si prefiere navegar, baje por los niveles en orden: grupo, segmento, familia, clase y producto. Cada nivel abre las opciones del siguiente.
A32: 5 | B32: Elija el resultado cuya denominación describa mejor el objeto. Al seleccionarlo, el clasificador muestra su segmento, familia, clase y producto con el código y el nombre.
A33: 6 | B33: Prefiera el nivel de producto (ocho dígitos sin ceros al final). Si el objeto agrupa varios productos de la misma clase, use la clase (termina en 00).
A34: 7 | B34: Copie el código y péguelo en la columna M de la hoja PlandeNecesidades como número, sin espacios ni puntos. Si el objeto requiere otros códigos, regístrelos en la columna N separados por punto y coma.
A35: 8 | B35: Revise que la alerta de consistencia de la fila no indique «Código UNSPSC inválido» ni «UNSPSC a nivel de segmento o familia».
A37: En la parte final de la página del clasificador se descargan la guía de codificación y la traducción al español del clasificador completo, útiles cuando se necesita buscar sin conexión.
A38: Error frecuente de 2026 | B38: Cómo evitarlo
A39: Código vacío o escrito como texto | B39: Registre siempre ocho dígitos, como número.
A40: Varios códigos en una misma celda | B40: Un código principal en la columna M y los demás en la columna N.
A41: Código a nivel de segmento o familia | B41: Baje al menos hasta la clase.
A42: Código copiado de otra necesidad sin verificar | B42: Confirme que la denominación del código describa su objeto.
A45: 6. Cómo se relaciona una necesidad con el Plan de Acción
A46: Toda necesidad sirve a una acción. Primero se formula la acción y después se registra lo que ella requiere contratar. La lista de la columna H muestra solo las acciones de la meta elegida en la columna E. Si la necesidad sirve a una acción que el área formuló por su cuenta, elija PROPIA y escriba en la columna I el nombre de la acción tal como quedó en la formulación.
A47: Acción del Plan de Acción | B47: Necesidad bien relacionada | D47: Por qué está bien
A48: AC27.19 Convertir los desarrollos de la Escuela en propiedad intelectual protegida | B48: Prestar servicios profesionales de asesoría en propiedad industrial para la redacción y radicación de dos solicitudes de patente ante la SIC | D48: Sin esa asesoría no se obtiene el producto de la acción: las solicitudes radicadas.
A49: AC27.51 Renovar el parque de computadores de apoyo académico | B49: Adquirir 240 computadores de escritorio para las salas de sistemas | D49: El bien es el producto mismo de la actividad de reposición.
...

Sheet Plan_Acción_2027
A1: ESTRUCTURA DEL PDI 2025 A 2032 | F1: FORMULACIÓN 2027 | Q1: IMPACTO SEGÚN LA GUÍA METODOLÓGICA PARA LA EVALUACIÓN DE IMPACTO INSTITUCIONAL | V1: SEGUIMIENTO
A2: EJE ESTRATÉGICO | B2: OBJETIVO ESTRATÉGICO DEL EJE | C2: LÍNEA DE ACCIÓN | D2: OBJETIVO ESTRATÉGICO | E2: META ESTRATÉGICA (PDI 2032) | F2: AJUSTE 2027 | G2: QUÉ CAMBIA FRENTE A 2026 | H2: INDICADOR DE LA META | I2: LÍNEA BASE | J2: META 2032 | K2: META 2027 | L2: FUENTE DE LA META 2027 | M2: ACCIONES 2027 (RESULTADOS QUE SE BUSCAN) | N2: ACTIVIDADES QUE COMPONEN CADA ACCIÓN Y SU PRODUCTO | O2: ÁREAS RESPONSABLES | P2: PRESUPUESTO 2027 (millones de pesos) | Q2: DIMENSIÓN DE IMPACTO | R2: CATEGORÍA DE IMPACTO (GUÍA METODOLÓGICA) | S2: INDICADOR DE IMPACTO (GUÍA METODOLÓGICA) | T2: CÓMO SE GENERA EL IMPACTO (CADENA DE VALOR) | U2: CÓMO SABREMOS QUE HUBO IMPACTO | V2: N.° DE ACCIONES | W2: N.° DE ACTIVIDADES | X2: RUTA DE ALINEACIÓN Y SEGUIMIENTO | Y2: ALERTAS PARA LA REVISIÓN
A3: 1. Formación y pedagogía de calidad | B3: 1. Consolidar a la ETITC como un referente educativo de excelencia, ampliando su oferta académica y garantizando la calidad en todos sus programas mediante una actualización continua y una estrecha vinculación con el entorno. | C3: 1.1 Ampliación de cobertura | D3: 1.1.1. Ampliar la cobertura de estudiantes en los programas de educación superior, asegurando el acceso equitativo y la calidad académica. | E3: 1.1.1.1. Contar con 11.000 estudiantes vinculados a programas de educación superior al 2032. | F3: Se mantiene | G3: Se mantiene el enunciado. Se agrega el crecimiento neto de primer curso (método MEN) como indicador de gestión y se suman las cohortes territoriales y la oferta híbrida y virtual (ver 1.4.1.1). | H3: N.° de estudiantes matriculados en programas de educación superior (SNIES) | I3: 3.925 estudiantes (2024, MPI, columna «Línea base 2024»); 4.219 matriculados en primer semestre de 2026 (Proyecciones de matrícula) | J3: 11.000 estudiantes | K3: 5.400 estudiantes | L3: MPI (meta 2027) y Proyecciones de matrícula 2020 a 2035 (columna Meta). Los programas nuevos aportan entre 650 (primer semestre de 2027) y 883 (segundo semestre de 2027) estudiantes según la misma proyección. | M3: AC27.01. Fortalecer la medición de la cobertura y de sus efectos, de modo que la Escuela sepa cuántos estudiantes nuevos gana cada año y qué pasa con ellos al egresar. AC27.02. Orientar la admisión 2027 hacia los programas con mayor demanda, con un calendario de admisiones armonizado con los recursos que asigna el Ministerio de Educación. AC27.03. Ampliar la cobertura en los territorios con cohortes nuevas en La Primavera (Vichada) y en Zipaquirá. | N3: AC27.01, actividades: 1. Adoptar el crecimiento neto de primer curso como indicador de meta, junto con nuevos atendidos (A27-001). Producto: ficha del indicador y serie SNIES por programa. 2. Iniciar el estudio de impacto de Egresados (A27-006). Producto: diseño del estudio aprobado. AC27.02, actividades: 1. Armonizar el calendario de admisiones con la asignación de recursos del MEN (A27-002). Producto: calendario de admisiones armonizado. 2. Concentrar cupos en programas con demanda creciente y revisar la oferta de programas en descenso (A27-003). Producto: informe de oferta y demanda por programa 2027. AC27.03, actividades: 1. Ejecutar la cohorte primer semestre de 2027 en La Primavera (Vichada) con 80 cupos adicionales (A27-004). Producto: matrícula de la cohorte en SNIES y acto del Consejo Directivo. 2. Ofertar y matricular en Zipaquirá bajo lugares de desarrollo transitorios (A27-005). Producto: matrícula por lugar de desarrollo en SNIES. | O3: Planeación y Plan de Acción (101) Egresados y Bolsa de Empleo (141) GIT Registro, Control y Admisiones (126) Despacho de la Vicerrectoría Académica (120) Sedes Tintal / Soacha-UPK / Viotá (120) | P3: A27-004: 295,8 (Res. MEN 019862) | Q3: Valor Público | R3: Transformaciones del territorio (condiciones del desarrollo, especialmente de cobertura y pertinencia en la oferta educativa). | S3: Porcentaje de jóvenes de la comunidad beneficiaria que se escolarizaron con la Institución. Proporción de programas académicos pertinentes (alineados con necesidades y vocación del territorio) ofrecidos por la Institución en el territorio. | T3: 1. Lo que hacemos: 3 acciones con 6 actividades (columnas M y N). 2. Lo que entregamos (productos): ficha del indicador y serie SNIES por programa; diseño del estudio aprobado; calendario de admisiones armonizado; informe de oferta y demanda por programa 2027; matrícula de la cohorte en SNIES y acto del Consejo Directivo; matrícula por lugar de desarrollo en SNIES. 3. Lo que cambia pronto (resultado): crece la matrícula de primer curso en Bogotá y en los territorios, y los cupos se concentran en programas con demanda. 4. La transformación que buscamos (impacto): más jóvenes de Bogotá y de regiones con poca oferta pública acceden y permanecen en educación superior pertinente con la vocación productiva de su territorio. 5. Tipo de impacto según la guía: externo. | U3: El porcentaje de jóvenes de las comunidades atendidas que se escolarizan con la Escuela sube frente a la línea base de 2024, y la proporción de programas pertinentes ofrecidos en cada territorio aumenta. Indicador de la guía con que se mide: porcentaje de jóvenes de la comunidad beneficiaria que se escolarizaron con la Institución. Punto de comparación: la línea base de la meta (3.925 estudiantes (2024, MPI, columna «Línea base 2024»); 4.219 matriculados en primer semestre de 2026 (Proyecciones de matrícula)) y, cuando el estudio lo permita, un grupo de referencia que no recibió la intervención. | V3: 3 | W3: 6 | X3: Dónde se ubica: eje 1, Formación y pedagogía de calidad, línea 1.1 Ampliación de cobertura, meta 1.1.1.1 del PDI 2025 a 2032. Qué cambió frente a 2026: se mantiene. Se mantiene el enunciado. Se agrega el crecimiento neto de primer curso (método MEN) como indicador de gestión y se suman las cohortes territoriales y la oferta híbrida y virtual (ver 1.4.1.1). Cómo se mide la meta: N.° de estudiantes matriculados en programas de educación superior (SNIES). Línea base: 3.925 estudiantes (2024, MPI, columna «Línea base 2024»); 4.219 matriculados en primer semestre de 2026 (Proyecciones de matrícula). Meta 2027: 5.400 estudiantes. Cómo se mide el impacto: porcentaje de jóvenes de la comunidad beneficiaria que se escolarizaron con la Institución. El indicador sale de la Guía Metodológica para la Evaluación de Impacto Institucional y se lee frente a la línea base. Qué esperamos obtener: más jóvenes de Bogotá y de regiones con poca oferta pública acceden y permanecen en educación superior pertinente con la vocación productiva de su territorio. Cómo se hace el seguimiento: cada trimestre las áreas reportan en el SUIE el avance de las actividades con su evidencia; la Oficina Asesora de Planeación verifica la pertinencia de los productos, consolida el avance de las acciones y de la meta y lo presenta al Comité Institucional de Gestión y Desempeño. Al cierre de 2027 se compara el indicador de la meta con su línea base. | Y3: El texto del PDI (pág. 39) habla de 12.000 estudiantes; la tabla de metas y la MPI, de 11.000. La proyección de matrícula llega a 9.675 en segundo semestre de 2032, por debajo de la meta.
E4: 1.1.1.2. Lograr que el 30% de los estudiantes del IBTI pasen a la educación superior de la ETITC. | F4: Se mantiene | G4: Se unifica el enunciado (el aplicativo tenía dos textos con y sin tilde). | H4: N.° y % de egresados del IBTI matriculados en programas de la ETITC | I4: 31 estudiantes (2024, MPI, columna «Línea base 2024») | J4: 30% (MPI: 250 estudiantes en 2032) | K4: 40 estudiantes | L4: MPI | M4: AC27.04. Consolidar la ruta de tránsito del IBTI a la educación superior de la ETITC, desde la alineación curricular hasta el acompañamiento de la cohorte que ingresa. | N4: AC27.04, actividades: 1. Alinear los currículos del IBTI con los programas técnicos profesionales por ciclos propedéuticos (A27-007). Producto: currículos alineados (ver 4.2.1.3). 2. Implementar la ruta de admisión y tránsito del IBTI a la educación superior (A27-008). Producto: procedimiento adoptado y estudiantes admitidos. 3. Hacer seguimiento a la cohorte que transita y a su permanencia en el primer año (A27-009). Producto: informe de seguimiento de la cohorte. | O4: Despacho de la Vicerrectoría Académica (120) IBTI (124) GIT Registro, Control y Admisiones (126) | P4: Sin presupuesto registrado en la matriz plurianual | Q4: Valor Público | R4: Transformaciones del territorio (condiciones del desarrollo, especialmente de cobertura y pertinencia en la oferta educativa). Cambios curriculares y mejoramiento de programas | S4: Porcentaje de jóvenes de la comunidad beneficiaria que se escolarizaron con la Institución. Reducción en la tasa de deserción atribuible a la intervención. | T4: 1. Lo que hacemos: 1 acción con 3 actividades (columnas M y N). 2. Lo que entregamos (productos): currículos alineados (ver 4.2.1.3); procedimiento adoptado y estudiantes admitidos; informe de seguimiento de la cohorte. 3. Lo que cambia pronto (resultado): más bachilleres técnicos del IBTI ingresan a los programas técnicos profesionales de la ETITC y terminan su primer año. 4. La transformación que buscamos (impacto): la ruta IBTI y educación superior se vuelve una trayectoria continua que reduce la deserción y mejora las oportunidades de estos jóvenes. 5. Tipo de impacto según la guía: externo e interno. | U4: La tasa de tránsito del IBTI a la ETITC supera los 31 estudiantes de la línea base y la deserción de esa cohorte en primer año es menor que la del resto de estudiantes nuevos. Indicador de la guía con que se mide: porcentaje de jóvenes de la comunidad beneficiaria que se escolarizaron con la Institución. Punto de comparación: la línea base de la meta (31 estudiantes (2024, MPI, columna «Línea base 2024»)) y, cuando el estudio lo permita, un grupo de referencia que no recibió la intervención. | V4: 1 | W4: 3 | X4: Dónde se ubica: eje 1, Formación y pedagogía de calidad, línea 1.1 Ampliación de cobertura, meta 1.1.1.2 del PDI 2025 a 2032. Qué cambió frente a 2026: se mantiene. Se unifica el enunciado (el aplicativo tenía dos textos con y sin tilde). Cómo se mide la meta: N.° y % de egresados del IBTI matriculados en programas de la ETITC. Línea base: 31 estudiantes (2024, MPI, columna «Línea base 2024»). Meta 2027: 40 estudiantes. Cómo se mide el impacto: porcentaje de jóvenes de la comunidad beneficiaria que se escolarizaron con la Institución. El indicador sale de la Guía Metodológica para la Evaluación de Impacto Institucional y se lee frente a la línea base. Qué esperamos obtener: la ruta IBTI y educación superior se vuelve una trayectoria continua que reduce la deserción y mejora las oportunidades de estos jóvenes. Cómo se hace el seguimiento: cada trimestre las áreas reportan en el SUIE el avance de las actividades con su evidencia; la Oficina Asesora de Planeación verifica la pertinencia de los productos, consolida el avance de las acciones y de la meta y lo presenta al Comité Institucional de Gestión y Desempeño. Al cierre de 2027 se compara el indicador de la meta con su línea base. | Y4: El PDI expresa la meta en porcentaje y la MPI en número de estudiantes: reportar ambos.
C5: 1.2 Oferta educativa | D5: 1.2.1. Fortalecer la oferta educativa mediante la creación y consolidación de programas de pregrado y posgrado, así como la ETDH, con modalidades virtuales que respondan a las demandas del entorno actual. | E5: 1.2.1.1. Ofrecer programas de educación superior: 5 pregrados nuevos, 3 especializaciones y 3 maestrías. | F5: Se corrige | G5: Se retira la adición de «2 programas nuevos de doctorado», que no está en el PDI (salvo acto del Consejo Directivo). Se integran los programas de IA comprometidos. | H5: N.° de programas nuevos con registro calificado y ofertados, por nivel | I5: 15 pregrados y 3 posgrados (2024, MPI, columna «Línea base 2024»); en 2025 se recibieron 4 visitas de verificación para 10 programas nuevos en modalidad distancia (RC 2025) | J5: 5 pregrados, 3 especializaciones, 3 maestrías | K5: Pregrado: 3 documentos maestros, 2 programas con registro calificado y 2 ofertados desde el II semestre. Posgrado: 2 especializaciones y 2 maestrías ofertadas en el II semestre. | L5: MPI; Acuerdos 04, 07 y 08 de 2026 y Oficio del 10/03/2026 (programas de IA). | M5: AC27.05. Completar el diseño y la aprobación de la nueva oferta de pregrado, con énfasis en inteligencia artificial y ciencia de datos. AC27.06. Poner en marcha la nueva oferta en el segundo semestre de 2027, incluidos los posgrados y los programas que se desarrollarán en Zipaquirá. | N5: AC27.05, actividades: 1. Reprogramar los productos 2026 vencidos de la meta (38 al 2 de septiembre de 2026) (A27-010). Producto: productos reprogramados. 2. Elaborar los documentos maestros de 3 programas de pregrado (A27-011). Producto: documentos maestros. 3. Diseñar 4 programas nuevos de IA: Tecnología en Análisis y Modelado de Datos con IA, TP en Ciencia de Datos Aplicada a la IA, Especialización en Gestión de Proyectos de IA y Maestría en Ciencia de Datos (A27-012). Producto: planes de estudio y acuerdos. 4. Obtener registro calificado de Ingeniería en IA, Ingeniería Robótica con IA y Especialización en Soluciones de IA (A27-013). Producto: radicados y resoluciones del MEN. AC27.06, actividades: 1. Tramitar la modificación del lugar de desarrollo de los programas de IA si se ofrecerán en Zipaquirá (A27-014). Producto: solicitud ante el MEN. 2. Ofertar 2 especializaciones y 2 maestrías en el II semestre (A27-015). Producto: programas ofertados y matrícula. | O5: Despacho de la Vicerrectoría Académica (120) Facultad de Inteligencia Artificial (Acuerdo 010 de 2025) (123) Aseguramiento de la Calidad, MIPG y Registros Calificados (101) Coordinación de Especializaciones (123) | P5: Sin presupuesto registrado en la matriz plurianual | Q5: Valor Público | R5: Transformaciones del territorio (condiciones del desarrollo, especialmente de cobertura y pertinencia en la oferta educativa). Transformaciones de vidas (condiciones de vida movilidad social) de las personas con las que se interactúa. | S5: Proporción de programas académicos pertinentes (alineados con necesidades y vocación del territorio) ofrecidos por la Institución en el territorio. Índice de empleabilidad en el corto plazo tras finalizar el programa formativo. | T5: 1. Lo que hacemos: 2 acciones con 6 actividades (columnas M y N). 2. Lo que entregamos (productos): productos reprogramados; documentos maestros; planes de estudio y acuerdos; radicados y resoluciones del MEN; solicitud ante el MEN; programas ofertados y matrícula. 3. Lo que cambia pronto (resultado): la Escuela cuenta con documentos maestros, registros calificados y programas nuevos ofertados, en especial en inteligencia artificial y datos. 4. La transformación que buscamos (impacto): la oferta responde a lo que el territorio y el sector productivo demandan, y sus egresados se vinculan rápidamente al empleo. 5. Tipo de impacto según la guía: interno y externo. | U5: Aumenta la proporción de programas pertinentes con la vocación del territorio y, cuando egresen las primeras cohortes, su índice de empleabilidad de corto plazo es igual o superior al promedio institucional. Indicador de la guía con que se mide: proporción de programas académicos pertinentes (alineados con necesidades y vocación del territorio) ofrecidos por la Institución en el territorio. Punto de comparación: la línea base de la meta (15 pregrados y 3 posgrados (2024, MPI, columna «Línea base 2024»); en 2025 se recibieron 4 visitas de verificación para 10 programas nuevos en modalidad distancia (RC 2025)) y, cuando el estudio lo permita, un grupo de referencia que no recibió la intervención. | V5: 2 | W5: 6 | X5: Dónde se ubica: eje 1, Formación y pedagogía de calidad, línea 1.2 Oferta educativa, meta 1.2.1.1 del PDI 2025 a 2032. Qué cambió frente a 2026: se corrige. Se retira la adición de «2 programas nuevos de doctorado», que no está en el PDI (salvo acto del Consejo Directivo). Se integran los programas de IA comprometidos. Cómo se mide la meta: N.° de programas nuevos con registro calificado y ofertados, por nivel. Línea base: 15 pregrados y 3 posgrados (2024, MPI, columna «Línea base 2024»); en 2025 se recibieron 4 visitas de verificación para 10 programas nuevos en modalidad distancia (RC 2025). Meta 2027: Pregrado: 3 documentos maestros, 2 programas con registro calificado y 2 ofertados desde el II semestre. Posgrado: 2 especializaciones y 2 maestrías ofertadas en el II semestre. Cómo se mide el impacto: proporción de programas académicos pertinentes (alineados con necesidades y vocación del territorio) ofrecidos por la Institución en el territorio. El indicador sale de la Guía Metodológica para la Evaluación de Impacto Institucional y se lee frente a la línea base. Qué esperamos obtener: la oferta responde a lo que el territorio y el sector productivo demandan, y sus egresados se vinculan rápidamente al empleo. Cómo se hace el seguimiento: cada trimestre las áreas reportan en el SUIE el avance de las actividades con su evidencia; la Oficina Asesora de Planeación verifica la pertinencia de los productos, consolida el avance de las acciones y de la meta y lo presenta al Comité Institucional de Gestión y Desempeño. Al cierre de 2027 se compara el indicador de la meta con su línea base. | Y5: La MPI incluye 2 doctorados que no están en la tabla de metas del PDI.
C6: 1.3 Calidad de los programas académicos | D6: 1.3.1. Garantizar la alta calidad de todos los programas de la ETITC. | E6: 1.3.1.1. Contar con la acreditación del 100% de los programas de la ETITC que sean acreditables. | F6: Se reformula | G6: Hito cumplido: la ETITC mantiene el 100% de sus programas acreditables acreditados y obtuvo la acreditación institucional en 2026. Para 2027 la meta pasa de «lograr» a «mantener y ampliar»: sostener las acreditaciones vigentes, renovar las que vencen y preparar los programas que cumplan requisitos. | H6: % de programas acreditables con acreditación vigente y N.° de programas acreditados | I6: 12 programas acreditados (2024, MPI, columna «Línea base 2024»); 100% de los programas acreditables acreditados y acreditación institucional obtenida en 2026 (RC 2025) | J6: 100% de los acreditables (MPI: 24 programas) | K6: Sugerida por la OAP: mantener el 100% de los programas acreditables acreditados, 18 programas con acreditación vigente, según la MPI, y radicar a tiempo las renovaciones que vencen en 2027 | L6: Sugerida por la OAP con base en la MPI (18 programas en 2027) y en el logro 2026. | M6: AC27.07. Asegurar la continuidad de las acreditaciones de programa, con un calendario de vencimientos y la radicación oportuna de las renovaciones de 2027. AC27.08. Cerrar el ciclo de mejoramiento de los programas acreditados, al día con los planes de mejoramiento y sin productos pendientes de 2026. | N6: AC27.07, actividades: 1. Construir el calendario de vencimientos de las acreditaciones de programa 2027 a 2029 (A27-016). Producto: calendario de vencimientos. 2. Radicar las renovaciones de acreditación que vencen en 2027 y atender las visitas de pares (A27-017). Producto: informes de autoevaluación radicados. AC27.08, actividades: 1. Hacer seguimiento a los planes de mejoramiento de los programas acreditados (A27-018). Producto: informe semestral de planes de mejoramiento. 2. Cerrar los 11 productos vencidos de acreditación de programas de 2026 (A27-019). Producto: productos reprogramados. | O6: Autoevaluación y Acreditación (101) Aseguramiento de la Calidad, MIPG y Registros Calificados (101) | P6: Sin presupuesto registrado en la matriz plurianual | Q6: Académica | R6: Cambios curriculares y mejoramiento de programas Impacto en las labores sustantivas: docencia y formación, investigación e innovación, extensión y proyección social. | S6: Resultados del valor agregado (diferencia entre el desarrollo de competencias antes de ingresar a la Escuela y lo que demuestra al egresar). Cantidad de procesos académicos y académico administrativos que mejoran. | T6: 1. Lo que hacemos: 2 acciones con 4 actividades (columnas M y N). 2. Lo que entregamos (productos): calendario de vencimientos; informes de autoevaluación radicados; informe semestral de planes de mejoramiento; productos reprogramados. 3. Lo que cambia pronto (resultado): ningún programa pierde su acreditación por vencimiento y los planes de mejoramiento quedan al día. 4. La transformación que buscamos (impacto): la calidad reconocida se traduce en mejores aprendizajes y en procesos académicos que mejoran de manera continua. 5. Tipo de impacto según la guía: interno. | U6: Los resultados de valor agregado de los programas acreditados mejoran frente a la medición anterior y crece el número de procesos académicos que reportan mejoras verificables. Indicador de la guía con que se mide: resultados del valor agregado (diferencia entre el desarrollo de competencias antes de ingresar a la Escuela y lo que demuestra al egresar). Punto de comparación: la línea base de la meta (12 programas acreditados (2024, MPI, columna «Línea base 2024»); 100% de los programas acreditables acreditados y acreditación institucional obtenida en 2026 (RC 2025)) y, cuando el estudio lo permita, un grupo de referencia que no recibió la intervención. | V6: 2 | W6: 4 | X6: Dónde se ubica: eje 1, Formación y pedagogía de calidad, línea 1.3 Calidad de los programas académicos, meta 1.3.1.1 del PDI 2025 a 2032. Qué cambió frente a 2026: se reformula. Hito cumplido: la ETITC mantiene el 100% de sus programas acreditables acreditados y obtuvo la acreditación institucional en 2026. Para 2027 la meta pasa de «lograr» a «mantener y ampliar»: sostener las acreditaciones vigentes, renovar las que vencen y preparar los programas que cumplan requisitos. Cómo se mide la meta: % de programas acreditables con acreditación vigente y N.° de programas acreditados. Línea base: 12 programas acreditados (2024, MPI, columna «Línea base 2024»); 100% de los programas acreditables acreditados y acreditación institucional obtenida en 2026 (RC 2025). Meta 2027: Sugerida por la OAP: mantener el 100% de los programas acreditables acreditados, 18 programas con acreditación vigente, según la MPI, y radicar a tiempo las renovaciones que vencen en 2027. Cómo se mide el impacto: resultados del valor agregado (diferencia entre el desarrollo de competencias antes de ingresar a la Escuela y lo que demuestra al egresar). El indicador sale de la Guía Metodológica para la Evaluación de Impacto Institucional y se lee frente a la línea base. Qué esperamos obtener: la calidad reconocida se traduce en mejores aprendizajes y en procesos académicos que mejoran de manera continua. Cómo se hace el seguimiento: cada trimestre las áreas reportan en el SUIE el avance de las actividades con su evidencia; la Oficina Asesora de Planeación verifica la pertinencia de los productos, consolida el avance de las acciones y de la meta y lo presenta al Comité Institucional de Gestión y Desempeño. Al cierre de 2027 se compara el indicador de la meta con su línea base. | Y6: Sin alertas.
E7: 1.3.1.2. Resultados de las Pruebas SABER por encima de la valoración de la media. | F7: Se corrige | G7: El 2026 decía «promedio 252 en el 2032»; según la MPI, 252 es la línea base de 2024, no la meta. | H7: Puntaje promedio institucional Saber PRO y TyT frente a la media nacional | I7: Promedio 252 (2024, MPI, columna «Línea base 2024») | J7: Por encima de la media nacional | K7: Sugerida por la OAP: promedio institucional de 254 puntos, mejora de 1 punto por año desde 252 en 2024, y por encima de la media nacional del grupo de referencia | L7: Sugerida por la OAP (trayectoria de mejora anual de 1 punto). | M7: AC27.09. Mejorar los resultados de las pruebas Saber PRO y TyT a partir del análisis por programa y competencia, con estrategias de preparación cuyo efecto se evalúa. | N7: AC27.09, actividades: 1. Analizar los resultados 2025 a 2026 por programa y competencia (A27-020). Producto: informe de análisis por programa. 2. Implementar estrategias de preparación para Saber PRO y TyT (talleres de ítems, simulacros) (A27-021). Producto: plan de preparación y simulacros aplicados. 3. Evaluar el efecto de las estrategias en los resultados 2027 (A27-022). Producto: informe de resultados 2027. | O7: Autoevaluación y Acreditación (101) Despacho de la Vicerrectoría Académica (120) | P7: Sin presupuesto registrado en la matriz plurianual | Q7: Académica | R7: Cambios curriculares y mejoramiento de programas Cambios en la formación integral y los aprendizajes del estudiantado. | S7: Resultados del valor agregado (diferencia entre el desarrollo de competencias antes de ingresar a la Escuela y lo que demuestra al egresar). Porcentaje de docentes que transforman la didáctica y la evaluación de los aprendizajes. | T7: 1. Lo que hacemos: 1 acción con 3 actividades (columnas M y N). 2. Lo que entregamos (productos): informe de análisis por programa; plan de preparación y simulacros aplicados; informe de resultados 2027. 3. Lo que cambia pronto (resultado): los estudiantes llegan mejor preparados a las pruebas Saber PRO y TyT y el promedio institucional sube. 4. La transformación que buscamos (impacto): los estudiantes egresan con más competencias de las que traían, y los docentes ajustan su didáctica con base en la evidencia. 5. Tipo de impacto según la guía: interno. | U7: El valor agregado entre el ingreso y la salida crece, el promedio supera los 252 puntos de la línea base y aumenta el porcentaje de docentes que transforma su didáctica y su evaluación. Indicador de la guía con que se mide: resultados del valor agregado (diferencia entre el desarrollo de competencias antes de ingresar a la Escuela y lo que demuestra al egresar). Punto de comparación: la línea base de la meta (Promedio 252 (2024, MPI, columna «Línea base 2024»)) y, cuando el estudio lo permita, un grupo de referencia que no recibió la intervención. | V7: 1 | W7: 3 | X7: Dónde se ubica: eje 1, Formación y pedagogía de calidad, línea 1.3 Calidad de los programas académicos, meta 1.3.1.2 del PDI 2025 a 2032. Qué cambió frente a 2026: se corrige. El 2026 decía «promedio 252 en el 2032»; según la MPI, 252 es la línea base de 2024, no la meta. Cómo se mide la meta: Puntaje promedio institucional Saber PRO y TyT frente a la media nacional. Línea base: Promedio 252 (2024, MPI, columna «Línea base 2024»). Meta 2027: Sugerida por la OAP: promedio institucional de 254 puntos, mejora de 1 punto por año desde 252 en 2024, y por encima de la media nacional del grupo de referencia. Cómo se mide el impacto: resultados del valor agregado (diferencia entre el desarrollo de competencias antes de ingresar a la Escuela y lo que demuestra al egresar). El indicador sale de la Guía Metodológica para la Evaluación de Impacto Institucional y se lee frente a la línea base. Qué esperamos obtener: los estudiantes egresan con más competencias de las que traían, y los docentes ajustan su didáctica con base en la evidencia. Cómo se hace el seguimiento: cada trimestre las áreas reportan en el SUIE el avance de las actividades con su evidencia; la Oficina Asesora de Planeación verifica la pertinencia de los productos, consolida el avance de las acciones y de la meta y lo presenta al Comité Institucional de Gestión y Desempeño. Al cierre de 2027 se compara el indicador de la meta con su línea base. | Y7: Sin alertas.
C8: 1.4 Acreditación internacional | D8: 1.4.1. Fortalecer la oferta educativa de la ETITC mediante la acreditación internacional de sus programas de educación superior, alineados con los estándares del Marco Común Europeo de Referencia. | E8: 1.4.1.1. Contar con 2 programas de acreditación internacional. | F8: Se corrige | G8: El 2026 la llamó «cualificación internacional MEC». El MEC es el Marco Europeo de Cualificaciones: 8 niveles que describen lo que una persona sabe, sabe hacer y con qué autonomía (técnico y tecnológico ≈ nivel 5; profesional universitario ≈ 6; especialización y maestría ≈ 7; doctorado = 8). Referenciar un programa al MEC hace legibles sus títulos en el exterior. Se aplica primero a los programas virtuales e híbridos, que pueden captar estudiantes fuera de Bogotá y del país y aportar a los 5.400 de 2027. | H8: N.° de programas con resultados de aprendizaje referenciados al MEC y con acreditación o reconocimiento internacional | I8: 0 programas (2024, MPI, columna «Línea base 2024»); 3 programas nuevos híbridos (presencial y virtual) diseñados en 2025 y 10 programas en modalidad distancia con visita de verificación (RC 2025) | J8: 2 programas | K8: Sugerida por la OAP: 2 programas, priorizando los híbridos y virtuales de IA, con resultados de aprendizaje referenciados a los 8 niveles del MEC y plan de cualificación internacional aprobado; 1 alianza con una IES o agencia extranjera para su reconocimiento | L8: Sugerida por la OAP. | M8: AC27.10. Referenciar dos programas al Marco Europeo de Cualificaciones para que sus títulos sean legibles en el exterior. AC27.11. Proyectar internacionalmente los programas referenciados mediante oferta virtual y una alianza de reconocimiento mutuo. | N8: AC27.10, actividades: 1. Elaborar el documento técnico de referenciación al MEC y al Marco Nacional de Cualificaciones (8 niveles) y seleccionar los 2 programas (A27-023). Producto: documento técnico aprobado. 2. Reescribir los resultados de aprendizaje de los 2 programas por nivel del MEC (conocimientos, destrezas, autonomía) (A27-024). Producto: matriz de resultados de aprendizaje referenciada. AC27.11, actividades: 1. Diseñar la oferta virtual de los programas referenciados para captar estudiantes de otras regiones (A27-025). Producto: plan de oferta virtual 2027 a 2028. 2. Firmar una alianza con una IES o agencia extranjera para reconocimiento mutuo y movilidad virtual (COIL) (A27-026). Producto: convenio suscrito. | O8: Autoevaluación y Acreditación (101) Unidad B-Learning (120) Internacionalización (ORII) (100) | P8: Sin presupuesto registrado en la matriz plurianual | Q8: Académica | R8: Impacto en las labores sustantivas: docencia y formación, investigación e innovación, extensión y proyección social. Cambios curriculares y mejoramiento de programas | S8: Cantidad de procesos académicos y académico administrativos que mejoran. Resultados del valor agregado (diferencia entre el desarrollo de competencias antes de ingresar a la Escuela y lo que demuestra al egresar). | T8: 1. Lo que hacemos: 2 acciones con 4 actividades (columnas M y N). 2. Lo que entregamos (productos): documento técnico aprobado; matriz de resultados de aprendizaje referenciada; plan de oferta virtual 2027 a 2028; convenio suscrito. 3. Lo que cambia pronto (resultado): dos programas tienen resultados de aprendizaje referenciados internacionalmente y una alianza de reconocimiento firmada. 4. La transformación que buscamos (impacto): los títulos de la ETITC son comparables en el exterior y la oferta virtual atrae estudiantes de otras regiones y países con calidad reconocida. 5. Tipo de impacto según la guía: interno. | U8: Aumentan los procesos académicos mejorados por la referenciación y los estudiantes de esos programas muestran mayor valor agregado en sus competencias. Indicador de la guía con que se mide: cantidad de procesos académicos y académico administrativos que mejoran. Punto de comparación: la línea base de la meta (0 programas (2024, MPI, columna «Línea base 2024»); 3 programas nuevos híbridos (presencial y virtual) diseñados en 2025 y 10 programas en modalidad distancia con visita de verificación (RC 2025)) y, cuando el estudio lo permita, un grupo de referencia que no recibió la intervención. | V8: 2 | W8: 4 | X8: Dónde se ubica: eje 1, Formación y pedagogía de calidad, línea 1.4 Acreditación internacional, meta 1.4.1.1 del PDI 2025 a 2032. Qué cambió frente a 2026: se corrige. El 2026 la llamó «cualificación internacional MEC». El MEC es el Marco Europeo de Cualificaciones: 8 niveles que describen lo que una persona sabe, sabe hacer y con qué autonomía (técnico y tecnológico ≈ nivel 5; profesional universitario ≈ 6; especialización y maestría ≈ 7; doctorado = 8). Referenciar un programa al MEC hace legibles sus títulos en el exterior. Se aplica primero a los programas virtuales e híbridos, que pueden captar estudiantes fuera de Bogotá y del país y aportar a los 5.400 de 2027. Cómo se mide la meta: N.° de programas con resultados de aprendizaje referenciados al MEC y con acreditación o reconocimiento internacional. Línea base: 0 programas (2024, MPI, columna «Línea base 2024»); 3 programas nuevos híbridos (presencial y virtual) diseñados en 2025 y 10 programas en modalidad distancia con visita de verificación (RC 2025). Meta 2027: Sugerida por la OAP: 2 programas, priorizando los híbridos y virtuales de IA, con resultados de aprendizaje referenciados a los 8 niveles del MEC y plan de cualificación internacional aprobado; 1 alianza con una IES o agencia extranjera para su reconocimiento. Cómo se mide el impacto: cantidad de procesos académicos y académico administrativos que mejoran. El indicador sale de la Guía Metodológica para la Evaluación de Impacto Institucional y se lee frente a la línea base. Qué esperamos obtener: los títulos de la ETITC son comparables en el exterior y la oferta virtual atrae estudiantes de otras regiones y países con calidad reconocida. Cómo se hace el seguimiento: cada trimestre las áreas reportan en el SUIE el avance de las actividades con su evidencia; la Oficina Asesora de Planeación verifica la pertinencia de los productos, consolida el avance de las acciones y de la meta y lo presenta al Comité Institucional de Gestión y Desempeño. Al cierre de 2027 se compara el indicador de la meta con su línea base. | Y8: El PDI menciona el «Marco Común Europeo de Referencia», que es el de lenguas (MCER), y el 2026 el MEC (cualificaciones): conviene precisarlo en la próxima revisión del PDI.
C9: 1.5 Fortalecimiento del cuerpo docente | D9: 1.5.1. Garantizar que la ETITC cuente con un cuerpo docente de alta calidad mediante la implementación de un plan integral de desarrollo profesoral, orientado a la excelencia académica y al fortalecimiento de sus capacidades. | E9: 1.5.1.1. Se mantienen 12 doctores en formación. | F9: Se corrige | G9: Vuelve al concepto de formación docente del PDI. El 2026 la reemplazó por «24 docentes con doctorado» con código mal formado (1.5.1. 4). | H9: N.° de docentes en formación doctoral | I9: 0 (2024, MPI, columna «Línea base 2024»); 3 docentes iniciaron doctorado en 2026 por la convocatoria posgradual 2025 (RC 2025) | J9: 12 doctores en formación (MPI: 10) | K9: 2 docentes nuevos en formación doctoral (acumulado sugerido: 5) | L9: MPI (2 nuevos en 2027); acumulado calculado por la OAP. | M9: AC27.12. Sostener la formación doctoral de los docentes mediante un plan profesoral actualizado, una convocatoria anual y los apoyos de estudio. | N9: AC27.12, actividades: 1. Actualizar el plan integral de desarrollo profesoral (A27-027). Producto: plan aprobado. 2. Abrir la convocatoria de formación posgradual 2027 (doctorado) (A27-028). Producto: convocatoria y docentes seleccionados. 3. Otorgar los apoyos para formación doctoral disciplinar (A27-029). Producto: comisiones de estudio o apoyos otorgados. | O9: GIT Talento Humano (133) Despacho de la Vicerrectoría Académica (120) | P9: A27-029: 640 (MPI) | Q9: Académica | R9: Cambios curriculares y mejoramiento de programas Cambios en la formación integral y los aprendizajes del estudiantado. | S9: Porcentaje de docentes que transforman o innovan sus prácticas tras su participación en actividades institucionales y de desarrollo docente. Porcentaje de docentes que transforman la didáctica y la evaluación de los aprendizajes. | T9: 1. Lo que hacemos: 1 acción con 3 actividades (columnas M y N). 2. Lo que entregamos (productos): plan aprobado; convocatoria y docentes seleccionados; comisiones de estudio o apoyos otorgados. 3. Lo que cambia pronto (resultado): más docentes inician y sostienen su formación doctoral con apoyo institucional. 4. La transformación que buscamos (impacto): los docentes con formación doctoral transforman sus prácticas y fortalecen la investigación y la docencia de sus programas. 5. Tipo de impacto según la guía: interno. | U9: Crece el porcentaje de docentes que innovan sus prácticas después de su formación, verificable en planes de curso, proyectos y productos de investigación. Indicador de la guía con que se mide: porcentaje de docentes que transforman o innovan sus prácticas tras su participación en actividades institucionales y de desarrollo docente. Punto de comparación: la línea base de la meta (0 (2024, MPI, columna «Línea base 2024»); 3 docentes iniciaron doctorado en 2026 por la convocatoria posgradual 2025 (RC 2025)) y, cuando el estudio lo permita, un grupo de referencia que no recibió la intervención. | V9: 1 | W9: 3 | X9: Dónde se ubica: eje 1, Formación y pedagogía de calidad, línea 1.5 Fortalecimiento del cuerpo docente, meta 1.5.1.1 del PDI 2025 a 2032. Qué cambió frente a 2026: se corrige. Vuelve al concepto de formación docente del PDI. El 2026 la reemplazó por «24 docentes con doctorado» con código mal formado (1.5.1. 4). Cómo se mide la meta: N.° de docentes en formación doctoral. Línea base: 0 (2024, MPI, columna «Línea base 2024»); 3 docentes iniciaron doctorado en 2026 por la convocatoria posgradual 2025 (RC 2025). Meta 2027: 2 docentes nuevos en formación doctoral (acumulado sugerido: 5). Cómo se mide el impacto: porcentaje de docentes que transforman o innovan sus prácticas tras su participación en actividades institucionales y de desarrollo docente. El indicador sale de la Guía Metodológica para la Evaluación de Impacto Institucional y se lee frente a la línea base. Qué esperamos obtener: los docentes con formación doctoral transforman sus prácticas y fortalecen la investigación y la docencia de sus programas. Cómo se hace el seguimiento: cada trimestre las áreas reportan en el SUIE el avance de las actividades con su evidencia; la Oficina Asesora de Planeación verifica la pertinencia de los productos, consolida el avance de las acciones y de la meta y lo presenta al Comité Institucional de Gestión y Desempeño. Al cierre de 2027 se compara el indicador de la meta con su línea base. | Y9: La hoja PROY dice 12 doctores; la tabla en imagen del PDI y la MPI dicen 10.
E10: 1.5.1.2. 80% en formación docentes de planta. | F10: Se corrige | G10: Se recogen aquí las metas de maestrías (48) y formación continuada (276) que el 2026 registró con códigos mal formados. La formalización laboral sale de esta línea. | H10: % de docentes de planta en formación avanzada o continuada | I10: 0 (2024, MPI, columna «Línea base 2024»); 4 docentes iniciaron maestría en 2026 por la convocatoria posgradual 2025 (RC 2025) | J10: 80% | K10: 6 docentes de planta en maestría y 40 docentes en formación continuada | L10: MPI | M10: AC27.13. Elevar la formación avanzada y continuada de los docentes de planta con base en las necesidades reales de cada facultad. | N10: AC27.13, actividades: 1. Identificar las necesidades de formación por facultad (A27-030). Producto: diagnóstico de necesidades. 2. Financiar la formación de docentes de planta en maestrías disciplinares (A27-031). Producto: docentes beneficiados. 3. Ofrecer cursos de formación continuada a docentes (A27-032). Producto: docentes certificados. | O10: Despacho de la Vicerrectoría Académica (120) GIT Talento Humano (133) | P10: A27-031: 240 (MPI) A27-032: 100 (MPI) | Q10: Académica | R10: Cambios curriculares y mejoramiento de programas Cambios en la formación integral y los aprendizajes del estudiantado. | S10: Porcentaje de docentes que transforman o innovan sus prácticas tras su participación en actividades institucionales y de desarrollo docente. Porcentaje de docentes que transforman la didáctica y la evaluación de los aprendizajes. | T10: 1. Lo que hacemos: 1 acción con 3 actividades (columnas M y N). 2. Lo que entregamos (productos): diagnóstico de necesidades; docentes beneficiados; docentes certificados. 3. Lo que cambia pronto (resultado): más docentes de planta cursan maestrías y formación continuada pertinente con las necesidades de su facultad. 4. La transformación que buscamos (impacto): la formación docente se refleja en cambios reales en la didáctica y en la evaluación de los aprendizajes. 5. Tipo de impacto según la guía: interno. | U10: Aumenta el porcentaje de docentes que transforman su didáctica y su evaluación, contrastado con los registros de seguimiento académico antes y después de la formación. Indicador de la guía con que se mide: porcentaje de docentes que transforman o innovan sus prácticas tras su participación en actividades institucionales y de desarrollo docente. Punto de comparación: la línea base de la meta (0 (2024, MPI, columna «Línea base 2024»); 4 docentes iniciaron maestría en 2026 por la convocatoria posgradual 2025 (RC 2025)) y, cuando el estudio lo permita, un grupo de referencia que no recibió la intervención. | V10: 1 | W10: 3 | X10: Dónde se ubica: eje 1, Formación y pedagogía de calidad, línea 1.5 Fortalecimiento del cuerpo docente, meta 1.5.1.2 del PDI 2025 a 2032. Qué cambió frente a 2026: se corrige. Se recogen aquí las metas de maestrías (48) y formación continuada (276) que el 2026 registró con códigos mal formados. La formalización laboral sale de esta línea. Cómo se mide la meta: % de docentes de planta en formación avanzada o continuada. Línea base: 0 (2024, MPI, columna «Línea base 2024»); 4 docentes iniciaron maestría en 2026 por la convocatoria posgradual 2025 (RC 2025). Meta 2027: 6 docentes de planta en maestría y 40 docentes en formación continuada. Cómo se mide el impacto: porcentaje de docentes que transforman o innovan sus prácticas tras su participación en actividades institucionales y de desarrollo docente. El indicador sale de la Guía Metodológica para la Evaluación de Impacto Institucional y se lee frente a la línea base. Qué esperamos obtener: la formación docente se refleja en cambios reales en la didáctica y en la evaluación de los aprendizajes. Cómo se hace el seguimiento: cada trimestre las áreas reportan en el SUIE el avance de las actividades con su evidencia; la Oficina Asesora de Planeación verifica la pertinencia de los productos, consolida el avance de las acciones y de la meta y lo presenta al Comité Institucional de Gestión y Desempeño. Al cierre de 2027 se compara el indicador de la meta con su línea base. | Y10: Sin alertas.
